Workbook

Sheet M&A
C2: Downside | D2: Base | E2: Upside
B3: Nominalised EBITDA (assumed) | C3: 6 | D3: 8 | E3: 9.5 | H3: Morgan | I3: Powersystems | J3: Synergies | K3: Pro Forma
B4: EV / Multiple | C4: 7 | D4: 8 | E4: 9 | G4: Revenue | H4: ='Morgan Sindall'!E5 -> 4546.2 | I4: ='Powersystems '!F8 -> 63.549206 | J4: =D25/12.7% -> 36 | K4: =H4+I4+J4 -> 4645.7492
B5: Purchase EV | C5: =C3*C4 -> 42 | D5: =D3*D4 -> 64 | E5: =E3*E4 -> 85.5 | G5: EBITDA | H5: ='Morgan Sindall'!E11+'Morgan Sindall'!E13 -> 195.6 | I5: 0 | J5: =D6 -> 10.572 | K5: =H5+I5+J5 -> 206.172
B6: Annual synergy EBITDA | C6: =C24+C25 -> 5.5 | D6: ='Cost Synergy'!C10+'Revenue Synergy'!C7 -> 10.572 | E6: =E24+E25 -> 17.1 | G6: D&A | H6: ='Morgan Sindall'!E13 -> 33.6 | I6: 0 | J6: 0 | K6: =H6+I6+J6 -> 33.6
B7: Transaction fees | C7: 2 | D7: 2 | E7: 2 | G7: EBIT | H7: =H5-H6 -> 162 | I7: ='Powersystems '!F12 -> 7.533085 | J7: =J5-J6 -> 10.572 | K7: =H7+I7+J7 -> 180.10509
B8: Lost cash interest rate | C8: 0.03 | D8: 0.03 | E8: 0.03 | G8: Net interest | H8: ='Morgan Sindall'!E16+'Morgan Sindall'!E17 -> 9.9 | I8: ='Powersystems '!F13+'Powersystems '!F14 -> 0.103645 | J8: =-D16*3% -> -2.3035172 | K8: =H8+I8+J8 -> 7.7001278
B9: Tax rate | C9: 0.234 | D9: 0.234 | E9: 0.234 | G9: PBT | H9: ='Morgan Sindall'!E19 -> 171.9 | I9: ='Powersystems '!F15 -> 7.63673 | J9: =J7+J8 -> 8.2684828 | K9: =K7+K8 -> 187.80521
G10: Tax | H10: ='Morgan Sindall'!E20 -> -40.2 | I10: ='Powersystems '!F16 -> -1.970719 | J10: =-J9*'Morgan Sindall'!E21 -> -1.9336417 | K10: =H10+I10+J10 -> -44.104361
B11: Enterprise Value | C11: =C5 -> 42 | D11: =D5 -> 64 | E11: =E5 -> 85.5 | G11: Net Income | H11: ='Morgan Sindall'!E22 -> 131.7 | I11: ='Powersystems '!F17 -> 5.666011 | J11: =J9+J10 -> 6.3348411 | K11: =K9+K10 -> 143.70085
B12: (+) Cash | C12: ='Powersystems '!$F$28 -> 10.783905 | D12: ='Powersystems '!$F$28 -> 10.783905 | E12: ='Powersystems '!$F$28 -> 10.783905
B13: (-) Debt | C13: 0 | D13: 0 | E13: 0
B14: Equity Value | C14: =C11+C12-C13 -> 52.783905 | D14: =D11+D12-D13 -> 74.783905 | E14: =E11+E12-E13 -> 96.283905
B16: Total Uses | C16: =C14+C7 -> 54.783905 | D16: =D14+D7 -> 76.783905 | E16: =E14+E7 -> 98.283905
B18: Morgan Sindall Cash | C18: =C16 -> 54.783905 | D18: =D16 -> 76.783905 | E18: =E16 -> 98.283905
B19: New Debt | C19: 0 | D19: 0 | E19: 0
B20: New Shares | C20: 0 | D20: 0 | E20: 0
B21: Total Sources | C21: =SUM(C18:C20) -> 54.783905 | D21: =SUM(D18:D20) -> 76.783905 | E21: =SUM(E18:E20) -> 98.283905
B23: Powersystems standalone EBITDA | C23: =C3 -> 6 | D23: =D3 -> 8 | E23: =E3 -> 9.5
B24: Cost synergy EBITDA | C24: 3.5 | D24: ='Cost Synergy'!C10 -> 6 | E24: 9.5
B25: Revenue synergy EBITDA | C25: 2 | D25: ='Revenue Synergy'!C7 -> 4.572 | E25: 7.6
B26: Total EBITDA contribution | C26: =SUM(C23:C25) -> 11.5 | D26: =SUM(D23:D25) -> 18.572 | E26: =SUM(E23:E25) -> 26.6
B28: Synergy-adjsuted multiple | C28: =C5/C26 -> 3.6521739 | D28: =D5/D26 -> 3.4460478 | E28: =E5/E26 -> 3.2142857
B30: Morgan Sindall Net Cash | C30: ='Morgan Sindall'!F78-'Morgan Sindall'!F87 -> 531.2 | D30: ='Morgan Sindall'!F78-'Morgan Sindall'!F87 -> 531.2 | E30: ='Morgan Sindall'!F78-'Morgan Sindall'!F87 -> 531.2
B31: Cash considerations + fees | C31: =C21 -> 54.783905 | D31: =D21 -> 76.783905 | E31: =E21 -> 98.283905
B32: Post-deal Net Cash | C32: =C30-C31 -> 476.4161 | D32: =D30-D31 -> 454.4161 | E32: =E30-E31 -> 432.9161
B34: Shares outstanding | C34: 48.5 | D34: 48.5 | E34: 48.5
B35: Standalone EPS | C35: =H11/C34 -> 2.7154639 | D35: =H11/D34 -> 2.7154639 | E35: =H11/E34 -> 2.7154639
B37: Purchase EV | C37: =C5 -> 42 | D37: =D5 -> 64 | E37: =E5 -> 85.5
B38: Total Uses | C38: =C16 -> 54.783905 | D38: =D16 -> 76.783905 | E38: =E16 -> 98.283905
B39: Synergy EBIT | C39: =C24+C25 -> 5.5 | D39: =D24+D25 -> 10.572 | E39: =E24+E25 -> 17.1
B40: Lost interest | C40: =-C38*C8 -> -1.6435172 | D40: =-D38*D8 -> -2.3035172 | E40: =-E38*E8 -> -2.9485171
B41: Synergy PBT | C41: =C39+C40 -> 3.8564828 | D41: =D39+D40 -> 8.2684828 | E41: =E39+E40 -> 14.151483
B42: Synergy tax | C42: =-C41*C9 -> -0.90241699 | D42: =-D41*D9 -> -1.934825 | E42: =-E41*E9 -> -3.311447
B43: Synergy net income | C43: =C41+C42 -> 2.9540659 | D43: =D41+D42 -> 6.3336579 | E43: =E41+E42 -> 10.840036
B44: Pro Forma net income | C44: =$H$11+$I$11+C43 -> 140.32008 | D44: =$H$11+$I$11+D43 -> 143.69967 | E44: =$H$11+$I$11+E43 -> 148.20605
B45: Pro Forma EPS | C45: =C44/$D$34 -> 2.8931975 | D45: =D44/$D$34 -> 2.9628798 | E45: =E44/$D$34 -> 3.0557948
B46: EPS Accretion | C46: =C45/$D$35-1 -> 0.065452368 | D46: =D45/$D$35-1 -> 0.091113659 | E46: =E45/$D$35-1 -> 0.12533065

Sheet Cost Synergy
B2: Average Morgan energy contract | C2: 100
B3: Relevant subcontracted work | C3: 0.2
B4: Subcontractor spend per contract | C4: =C3*C2 -> 20
B5: Subcontractor EBITDA margin | C5: 0.1
B6: Subcontractor EBITDA pool | C6: =C5*C4 -> 2
B7: % Powersystems could internalise | C7: 0.6
B8: Incremental EBITDA per contract | C8: =C7*C6 -> 1.2
B9: Average relevant contracts per year | C9: 5
B10: Annual synergy EBITDA | C10: =C8*C9 -> 6

Sheet Revenue Synergy
B2: Average electrical package | C2: 15
B3: EBITDA Margin | C3: 0.127
B4: Powersystems/competitors self-delivery | C4: 0.8
B5: Incremental EBITDA per contract | C5: =(C3*C2)*C4 -> 1.524
B6: Relevant contracts per year | C6: 3
B7: Annual synergy EBITDA | C7: =C5*C6 -> 4.572

Sheet Powersystems 
B2: Revenue | C2: =C8 -> 47.130143 | D2: =D8 -> 38.991623 | E2: =E8 -> 36.051835 | F2: =F8 -> 63.549206
B3: EBIT | C3: =C12 -> 3.51556 | D3: =D12 -> 2.743319 | E3: =E12 -> 2.429594 | F3: =F12 -> 7.533085
B4: Margin | C4: =C3/C2 -> 0.074592602 | D4: =D3/D2 -> 0.070356625 | E4: =E3/E2 -> 0.067391688 | F4: =F3/F2 -> 0.1185394
C6: 2021 | D6: 2022 | E6: 2023 | F6: 2024
B7: INCOME STATEMENT
B8: Revenue | C8: 47.130143 | D8: 38.991623 | E8: 36.051835 | F8: 63.549206
B9: COGS | C9: -38.026003 | D9: -29.340651 | E9: -25.708964 | F9: -44.048874
B10: Gross Profit | C10: =(C8+C9) -> 9.10414 | D10: =(D8+D9) -> 9.650972 | E10: =(E8+E9) -> 10.342871 | F10: =(F8+F9) -> 19.500332
B11: Admin expense | C11: -5.58858 | D11: -6.907653 | E11: -7.913277 | F11: -11.967247
B12: Operating Profit | C12: =(C10+C11) -> 3.51556 | D12: =(D10+D11) -> 2.743319 | E12: =(E10+E11) -> 2.429594 | F12: =(F10+F11) -> 7.533085
B13: Interest Income | C13: 0.008224 | D13: 0.013325 | E13: 0.142487 | F13: 0.217699
B14: Interest Expense | C14: -0.042801 | D14: -0.04082 | E14: -0.048706 | F14: -0.114054
B15: Profit before Tax | C15: =(C12+C13+C14) -> 3.480983 | D15: =(D12+D13+D14) -> 2.715824 | E15: =(E12+E13+E14) -> 2.523375 | F15: =(F12+F13+F14) -> 7.63673
B16: Tax | C16: -0.759686 | D16: -0.544355 | E16: -0.345718 | F16: -1.970719
B17: Profit | C17: =(C15+C16) -> 2.721297 | D17: =(D15+D16) -> 2.171469 | E17: =(E15+E16) -> 2.177657 | F17: =(F15+F16) -> 5.666011
B19: BALANCE SHEET
B20: Fixed assets
B21: Tangible assets | C21: 3.137909 | D21: 3.155318 | E21: 3.126009 | F21: 3.576041
B22: Investments | C22: 1e-06 | D22: 1e-06 | E22: 2e-06 | F22: 2e-06
B23: Total fixed assets | C23: 3.13791 | D23: 3.155319 | E23: 3.126011 | F23: 3.576043
B25: Current assets
B26: Stocks | C26: 6.101188 | D26: 3.94083 | E26: 5.781749 | F26: 5.765142
B27: Debtors | C27: 14.379764 | D27: 9.017443 | E27: 10.135546 | F27: 11.78623
B28: Cash at bank and in hand | C28: 5.077363 | D28: 7.886805 | E28: 11.807362 | F28: 10.783905
B29: Total current assets | C29: 25.558315 | D29: 20.845078 | E29: 27.724657 | F29: 28.335277
B30: Creditors: amounts falling due within one year | C30: -17.055037 | D30: -12.568818 | E30: -20.806286 | F30: -18.139139
B31: Net current assets | C31: 8.503278 | D31: 8.27626 | E31: 6.918371 | F31: 10.196138
B32: Total assets less current liabilities | C32: 11.641188 | D32: 11.431579 | E32: 10.044382 | F32: 13.772181
B34: Provisions for liabilities
B35: Provisions | C35: -1.09191 | D35: -0.77 | E35: -0.037169 | F35: -0.020513
B36: Deferred tax liability | C36: -0.317077 | D36: -0.371624 | E36: -0.41947 | F36: -0.569339
B37: Total provisions / deferred tax | C37: -1.408987 | D37: -1.141624 | E37: -0.456639 | F37: -0.589852
B38: Net assets | C38: 10.232201 | D38: 10.289955 | E38: 9.587743 | F38: 13.182329
B40: Capital and reserves
B41: Called up share capital | C41: 0.005 | D41: 0.005 | E41: 0.005641 | F41: 0.005641
B42: Share premium account | C42: 0 | D42: 0 | E42: 0.544209 | F42: 0.544209
B43: Share option reserve | C43: 0.514872 | D43: 0.514872 | E43: 0.280806 | F43: 0.280806
B44: Profit and loss reserves | C44: 9.712329 | D44: 9.770083 | E44: 8.757087 | F44: 12.351673
B45: Total equity | C45: 10.232201 | D45: 10.289955 | E45: 9.587743 | F45: 13.182329
B47: CASH FLOW STATEMENT
...

Sheet Morgan Sindall
D2: 2023A | E2: 2024A | F2: 2025A
B4: Income Statement
B5: Revenue | D5: 4117.7 | E5: 4546.2 | F5: 5018.6
B6: % growth | E6: =E5/D5-1 -> 0.10406295 | F6: =F5/E5-1 -> 0.10391096
B7: Cost of sales | D7: -3670.1 | E7: -4016.3 | F7: -4406.6
B8: Gross profit | D8: 447.6 | E8: 529.9 | F8: 612
B9: Gross margin | D9: =D8/D5 -> 0.10870146 | E9: =E8/E5 -> 0.11655888 | F9: =F8/F5 -> 0.12194636
B10: Administrative & other operating items | D10: =D11-D8 -> -307 | E10: =E11-E8 -> -367.9 | F10: =F11-F8 -> -387.1
B11: Operating profit (EBIT) | D11: 140.6 | E11: 162 | F11: 224.9
B12: Operating margin | D12: =D11/D5 -> 0.034145275 | E12: =E11/E5 -> 0.035634156 | F12: =F11/F5 -> 0.044813295
B13: D&A | D13: 29.7 | E13: 33.6 | F13: 36.2
B14: EBITDA | D14: =D11+D13 -> 170.3 | E14: =E11+E13 -> 195.6 | F14: =F11+F13 -> 261.1
B15: EBITDA margin | D15: =D14/D5 -> 0.04135804 | E15: =E14/E5 -> 0.043024944 | F15: =F14/F5 -> 0.052026462
B16: Finance income | D16: 10.8 | E16: 18.2 | F16: 15.6
B17: Finance expense | D17: -7.5 | E17: -8.3 | F17: -8.7
B18: Net finance income | D18: =SUM(D16:D17) -> 3.3 | E18: =SUM(E16:E17) -> 9.9 | F18: =SUM(F16:F17) -> 6.9
B19: Profit before tax | D19: 143.9 | E19: 171.9 | F19: 231.8
B20: Tax | D20: -26.2 | E20: -40.2 | F20: -56.9
B21: Effective tax rate | D21: =-D20/D19 -> 0.18207088 | E21: =-E20/E19 -> 0.23385689 | F21: =-F20/F19 -> 0.24547023
B22: Net income | D22: 117.7 | E22: 131.7 | F22: 174.9
B25: Cash Flow Statement
B26: Operating profit | D26: 140.6 | E26: 162 | F26: 224.9
B27: D&A | D27: 29.7 | E27: 33.6 | F27: 36.2
B28: JV profit adjustment | D28: -14.1 | E28: -4.6 | F28: -0.3
B29: Share-based payments | D29: 6.6 | E29: 10.5 | F29: 10.8
B30: Change in provisions & other non-cash | D30: 15.2 | E30: 5 | F30: -15
B31: Operating cash before working capital | D31: 178 | E31: 206.5 | F31: 256.6
B32: Change in inventories | D32: -10.8 | E32: -131.3 | F32: -127.3
B33: Change in contract assets | D33: 24 | E33: 46 | F33: -11.2
B34: Change in receivables | D34: -107.8 | E34: 7.8 | F34: -100.1
B35: Change in contract liabilities | D35: 21.6 | E35: 14.6 | F35: 8.3
B36: Change in trade payables | D36: 116.2 | E36: 29.1 | F36: 209.3
B37: Total working capital movement | D37: 43.2 | E37: -33.8 | F37: -21
... B40: Net cash from operating activities | D40: 196 | E40: 128.8 | F40: 187.3
B41: Investing activities
B42: Interest received | D42: 10 | E42: 18 | F42: 15.9
B43: Dividends from joint ventures | D43: 1.6 | E43: 4.2 | F43: 4.7
B44: Proceeds on disposal of PP&E | D44: 2 | E44: 1.9 | F44: 0.5
B45: PP&E capex | D45: -14.3 | E45: -18.2 | F45: -16
B46: Intangible capex | D46: -0.3 | E46: 0 | F46: -0.6
...

Sheet Assumptions
B3: Powersystems
B6: Purchase EV
B7: Cash
B8: Debt
B9: Equity purchase price
B10: Transaction fees
B11: Financing
B12: Tax Rate
