Workbook

Sheet DCF
D2: US$mm | F2: 2023 | G2: 2024 | H2: 2025 | I2: 2026 | J2: 2027 | K2: 2028 | L2: 2029 | M2: 2030 | N2: Term
B4: OPERATING PERFORMANCE
B5: Revenue | F5: ='Historical 3-Statement'!D16 -> 30652 | G5: ='Historical 3-Statement'!E16 -> 27290 | H5: ='Historical 3-Statement'!F16 -> 18546 | I5: =Scenarios!D14 -> 18259.94 | J5: =Scenarios!E14 -> 19072.596 | K5: =Scenarios!F14 -> 19566.824 | L5: =Scenarios!G14 -> 20128.42 | M5: =Scenarios!H14 -> 20707.197
B6: % Growth | F6: -0.127 | G6: =G5/F5-1 -> -0.10968289 | H6: =H5/G5-1 -> -0.32041041 | I6: =I5/H5-1 -> -0.01542435 | J6: =J5/I5-1 -> 0.044504848 | K6: =K5/J5-1 -> 0.025912979 | L6: =L5/K5-1 -> 0.028701446 | M6: =M5/L5-1 -> 0.028754217
B7: Underlying EBITDA | F7: ='Full Historical 3-Statement'!D8 -> 9958 | G7: ='Full Historical 3-Statement'!E8 -> 8460 | H7: ='Full Historical 3-Statement'!F8 -> 6417 | I7: =Scenarios!D16 -> 8216.973 | J7: =Scenarios!E16 -> 8773.3941 | K7: =Scenarios!F16 -> 9000.7389 | L7: =Scenarios!G16 -> 9259.0731 | M7: =Scenarios!H16 -> 9525.3105
B8: EBITDA Margin | F8: =F7/F5 -> 0.32487277 | G8: =G7/G5 -> 0.31000366 | H8: =H7/H5 -> 0.34600453 | I8: =I7/I5 -> 0.45 | J8: =J7/J5 -> 0.46 | K8: =K7/K5 -> 0.46 | L8: =L7/L5 -> 0.46 | M8: =M7/M5 -> 0.46
B9: Depreciation & Amortisation | F9: ='Full Historical 3-Statement'!D9 -> 2790 | G9: ='Full Historical 3-Statement'!E9 -> 3175 | H9: ='Full Historical 3-Statement'!F9 -> 2382 | I9: =Scenarios!D19 -> 2282.4925 | J9: =Scenarios!E19 -> 2288.7115 | K9: =Scenarios!F19 -> 2250.1847 | L9: =Scenarios!G19 -> 2214.1262 | M9: =Scenarios!H19 -> 2277.7916
B10: D&A / Revenue | F10: =F9/F5 -> 0.091021793 | G10: =G9/G5 -> 0.11634298 | H10: =H9/H5 -> 0.1284374 | I10: =I9/I5 -> 0.125 | J10: =J9/J5 -> 0.12 | K10: =K9/K5 -> 0.115 | L10: =L9/L5 -> 0.11 | M10: =M9/M5 -> 0.11
B11: Underlying EBIT | F11: ='Full Historical 3-Statement'!D10 -> 7168 | G11: ='Full Historical 3-Statement'!E10 -> 5285 | H11: ='Full Historical 3-Statement'!F10 -> 4035 | I11: =I7-I9 -> 5934.4805 | J11: =J7-J9 -> 6484.6826 | K11: =K7-K9 -> 6750.5542 | L11: =L7-L9 -> 7044.9469 | M11: =M7-M9 -> 7247.5188
B13: TAX / NOPAT
B14: Current Tax Expense | F14: =-'Full Historical 3-Statement'!D27 -> 2251 | G14: =-'Full Historical 3-Statement'!E27 -> 1864 | H14: =-'Full Historical 3-Statement'!F27 -> 1587 | I14: =I11*I15 -> 2373.7922 | J14: =J11*J15 -> 2593.873 | K14: =K11*K15 -> 2700.2217 | L14: =L11*L15 -> 2817.9788 | M14: =M11*M15 -> 2899.0075
B15: Tax Rate | F15: =F14/F11 -> 0.3140346 | G15: =G14/G11 -> 0.35269631 | H15: =H14/H11 -> 0.39330855 | I15: =Scenarios!D22 -> 0.4 | J15: =Scenarios!E22 -> 0.4 | K15: =Scenarios!F22 -> 0.4 | L15: =Scenarios!G22 -> 0.4 | M15: =Scenarios!H22 -> 0.4
B16: NOPAT | F16: =F11-F14 -> 4917 | G16: =G11-G14 -> 3421 | H16: =H11-H14 -> 2448 | I16: =I11-I14 -> 3560.6883 | J16: =J11-J14 -> 3890.8096 | K16: =K11-K14 -> 4050.3325 | L16: =L11-L14 -> 4226.9682 | M16: =M11-M14 -> 4348.5113
B18: REINVESTMENT / WORKING CAPITAL
B19: Capital Expenditure | F19: =-'Full Historical 3-Statement'!D11 -> 5734 | G19: =-'Full Historical 3-Statement'!E11 -> 5490 | H19: =-'Full Historical 3-Statement'!F11 -> 3322 | I19: =Scenarios!D24 -> 3100 | J19: =Scenarios!E24 -> 2900 | K19: =Scenarios!F24 -> 2600 | L19: =Scenarios!G24 -> 2400 | M19: =Scenarios!H24 -> 2200
B20: CapEx / Revenue | F20: =F19/F5 -> 0.18706773 | G20: =G19/G5 -> 0.20117259 | H20: =H19/H5 -> 0.17912218 | I20: =I19/I5 -> 0.16977055 | J20: =J19/J5 -> 0.15205062 | K20: =K19/K5 -> 0.13287798 | L20: =L19/L5 -> 0.1192344 | M20: =M19/M5 -> 0.10624326
B21: Inventory | F21: ='Full Historical 3-Statement'!D105 -> 6387 | G21: ='Full Historical 3-Statement'!E105 -> 5247 | H21: ='Full Historical 3-Statement'!F105 -> 3013 | I21: =Scenarios!D27 -> 2901.5795 | J21: =Scenarios!E27 -> 2978.4602 | K21: =Scenarios!F27 -> 3055.641 | L21: =Scenarios!G27 -> 3143.3423 | M21: =Scenarios!H27 -> 3233.7266
B22: Trade Receivables | F22: ='Full Historical 3-Statement'!D106 -> 4516 | G22: ='Full Historical 3-Statement'!E106 -> 3228 | H22: ='Full Historical 3-Statement'!F106 -> 3748 | I22: =Scenarios!D29 -> 3702.0152 | J22: =Scenarios!E29 -> 3814.5192 | K22: =Scenarios!F29 -> 3913.3647 | L22: =Scenarios!G29 -> 4025.684 | M22: =Scenarios!H29 -> 4141.4393
B23: Trade Payables | F23: =-'Full Historical 3-Statement'!D116 -> 6511 | G23: =-'Full Historical 3-Statement'!E116 -> 6092 | H23: =-'Full Historical 3-Statement'!F116 -> 4879 | I23: =Scenarios!D31 -> 5046.0857 | J23: =Scenarios!E31 -> 5147.4926 | K23: =Scenarios!F31 -> 5301.9174 | L23: =Scenarios!G31 -> 5460.9749 | M23: =Scenarios!H31 -> 5624.8042
B24: Operating Net Working Capital | E24: ='Full Historical 3-Statement'!C105+'Full Historical 3-Statement'!C106+'Full Historical 3-Statement'!C116 -> 3701 | F24: =F21+F22-F23 -> 4392 | G24: =G21+G22-G23 -> 2383 | H24: =H21+H22-H23 -> 1882 | I24: =I21+I22-I23 -> 1557.509 | J24: =J21+J22-J23 -> 1645.4867 | K24: =K21+K22-K23 -> 1667.0883 | L24: =L21+L22-L23 -> 1708.0513 | M24: =M21+M22-M23 -> 1750.3618
B25: NWC / Revenue | F25: =F24/F5 -> 0.14328592 | G25: =G24/G5 -> 0.087321363 | H25: =H24/H5 -> 0.10147741 | I25: =I24/I5 -> 0.085296504 | J25: =J24/J5 -> 0.086274923 | K25: =K24/K5 -> 0.08519974 | L25: =L24/L5 -> 0.084857695 | M25: =M24/M5 -> 0.084529153
B27: UNLEVERED FREE CASH FLOW
B28: Change in Operation NWC | F28: =F24-E24 -> 691 | G28: =G24-F24 -> -2009 | H28: =H24-G24 -> -501 | I28: =I24-H24 -> -324.49096 | J28: =J24-I24 -> 87.97769 | K28: =K24-J24 -> 21.601556 | L28: =L24-K24 -> 40.963017 | M28: =M24-L24 -> 42.310486
B29: Unlevered FCF | F29: =F16+F9-F19-F28 -> 1282 | G29: =G16+G9-G19-G28 -> 3115 | H29: =H16+H9-H19-H28 -> 2009 | I29: =I16+I9-I19-I28 -> 3067.6718 | J29: =J16+J9-J19-J28 -> 3191.5434 | K29: =K16+K9-K19-K28 -> 3678.9157 | L29: =L16+L9-L19-L28 -> 4000.1313 | M29: =M16+M9-M19-M28 -> 4383.9925 | N29: =M29*(1+Assumptions!E3) -> 4471.6723
B31: UNDISCOUNTED CASH FLOW
B32: Discrete Forecast | I32: =I29 -> 3067.6718 | J32: =J29 -> 3191.5434 | K32: =K29 -> 3678.9157 | L32: =L29 -> 4000.1313 | M32: =M29 -> 4383.9925 | N32: =N29 -> 4471.6723
B33: Terminal Value | N33: =N29/(Assumptions!E4-Assumptions!E3) -> 60803.734
B35: ENTERPRISE VALUE
B36: Present Value of Discrete | D36: =NPV(Assumptions!E4,DCF!I32,DCF!J32,DCF!K32,DCF!L32,DCF!M32) -> 13888.107
B37: Present Value of Terminal | D37: =N33/(1+Assumptions!E4)^5 -> 38882.258
B38: EV | D38: =SUM(D36:D37) -> 52770.364
B40: EQUITY VALUE
B41: EV | D41: =D38 -> 52770.364
B42: Net Debt | D42: =-('Full Historical 3-Statement'!F117+'Full Historical 3-Statement'!F125)-'Full Historical 3-Statement'!F110 -> 9045
B43: Equity Value | D43: =D41-D42 -> 43725.364
B44: Shares Outstanding | D44: =Assumptions!E19 -> 1131
B45: Intrinsic Value Per Share | D45: =D43/D44 -> 38.6608
B46: Live Case | D46: 1

Sheet Assumptions
B2: ASSUMPTIONS
B3: Growth Rate | E3: 0.02
B4: Discount Rate | E4: =(E21*E10)+(E28*E15) -> 0.093542725
B6: COST OF EQUITY
B7: Risk-free Rate (UK 10-Year) | E7: 0.05
B8: Beta | E8: 0.97
B9: Market Risk Premium | E9: 0.06
B10: CAPM | E10: =E7+(E8*E9) -> 0.1082
B12: AFTER-TAX COST OF DEBT
B13: Interest Rate on Debt | E13: =E25 -> 0.055681158
B14: Tax Rate | E14: =DCF!H15 -> 0.39330855
B15: Cost of Debt | E15: =E13*(1-E14) -> 0.033781282
B17: MARKET VALUE OF EQUITY AND DEBT
B18: Share Price | E18: =(4134/100)*1.35 -> 55.809
B19: Shares Outstanding | E19: 1131
B20: Market Value of Equity | E20: =E18*E19 -> 63119.979
B21: % Weight | E21: =E20/(E20+E27) -> 0.80304317
B23: Interest Expense | E23: =-'Full Historical 3-Statement'!F23 -> 862
B24: Total Debt | E24: =(-'Full Historical 3-Statement'!F125-'Full Historical 3-Statement'!F117) -> 15481
B25: Current Cost of Debt | E25: =E23/E24 -> 0.055681158
B26: Average Maturity | E26: 8
B27: Market Value of Debt | E27: =-PV(E25,E26,E23,E24) -> 15481
B28: % Weight | E28: =E27/(E20+E27) -> 0.19695683

Sheet Scenarios
B2: LIVE CASE | J2: Cases
C3: 2025A | D3: 2026E | E3: 2027E | F3: 2028E | G3: 2029E | H3: 2030E | J3: 1
B4: Copper | C4: 8122 | D4: =C4*(1+D5) -> 10233.72 | E4: =D4*(1+E5) -> 10745.406 | F4: =E4*(1+F5) -> 11282.676 | G4: =F4*(1+G5) -> 11677.57 | H4: =G4*(1+H5) -> 12086.285 | J4: 2
B5: Copper Growth | D5: =CHOOSE(DCF!$D$46,Scenarios!D37,Scenarios!D69,Scenarios!D102) -> 0.26 | E5: =CHOOSE(DCF!$D$46,Scenarios!E37,Scenarios!E69,Scenarios!E102) -> 0.05 | F5: =CHOOSE(DCF!$D$46,Scenarios!F37,Scenarios!F69,Scenarios!F102) -> 0.05 | G5: =CHOOSE(DCF!$D$46,Scenarios!G37,Scenarios!G69,Scenarios!G102) -> 0.035 | H5: =CHOOSE(DCF!$D$46,Scenarios!H37,Scenarios!H69,Scenarios!H102) -> 0.035 | J5: 3
B6: Premium Iron Ore | C6: 6651 | D6: =C6*(1+D7) -> 6717.51 | E6: =D6*(1+E7) -> 6986.2104 | F6: =E6*(1+F7) -> 6916.3483 | G6: =F6*(1+G7) -> 7054.6753 | H6: =G6*(1+H7) -> 7195.7688
B7: Premium Iron Ore Growth | D7: =CHOOSE(DCF!$D$46,Scenarios!D39,Scenarios!D71,Scenarios!D104) -> 0.01 | E7: =CHOOSE(DCF!$D$46,Scenarios!E39,Scenarios!E71,Scenarios!E104) -> 0.04 | F7: =CHOOSE(DCF!$D$46,Scenarios!F39,Scenarios!F71,Scenarios!F104) -> -0.01 | G7: =CHOOSE(DCF!$D$46,Scenarios!G39,Scenarios!G71,Scenarios!G104) -> 0.02 | H7: =CHOOSE(DCF!$D$46,Scenarios!H39,Scenarios!H71,Scenarios!H104) -> 0.02
B8: Manganese | C8: 472 | D8: =C8*(1+D9) -> 708 | E8: =D8*(1+E9) -> 729.24 | F8: =E8*(1+F9) -> 743.8248 | G8: =F8*(1+G9) -> 758.7013 | H8: =G8*(1+H9) -> 773.87532
B9: Manganese Growth | D9: =CHOOSE(DCF!$D$46,Scenarios!D41,Scenarios!D73,Scenarios!D106) -> 0.5 | E9: =CHOOSE(DCF!$D$46,Scenarios!E41,Scenarios!E73,Scenarios!E106) -> 0.03 | F9: =CHOOSE(DCF!$D$46,Scenarios!F41,Scenarios!F73,Scenarios!F106) -> 0.02 | G9: =CHOOSE(DCF!$D$46,Scenarios!G41,Scenarios!G73,Scenarios!G106) -> 0.02 | H9: =CHOOSE(DCF!$D$46,Scenarios!H41,Scenarios!H73,Scenarios!H106) -> 0.02
B10: Crop Nutrients | C10: 195 | D10: =C10*(1+D11) -> 196.95 | E10: =D10*(1+E11) -> 199.90425 | F10: =E10*(1+F11) -> 203.90233 | G10: =F10*(1+G11) -> 208.99989 | H10: =G10*(1+H11) -> 214.22489
B11: Crop Nutrients Growth | D11: =CHOOSE(DCF!$D$46,Scenarios!D43,Scenarios!D75,Scenarios!D108) -> 0.01 | E11: =CHOOSE(DCF!$D$46,Scenarios!E43,Scenarios!E75,Scenarios!E108) -> 0.015 | F11: =CHOOSE(DCF!$D$46,Scenarios!F43,Scenarios!F75,Scenarios!F108) -> 0.02 | G11: =CHOOSE(DCF!$D$46,Scenarios!G43,Scenarios!G75,Scenarios!G108) -> 0.025 | H11: =CHOOSE(DCF!$D$46,Scenarios!H43,Scenarios!H75,Scenarios!H108) -> 0.025
B12: Other | C12: 392 | D12: =C12*(1+D13) -> 403.76 | E12: =D12*(1+E13) -> 411.8352 | F12: =E12*(1+F13) -> 420.0719 | G12: =F12*(1+G13) -> 428.47334 | H12: =G12*(1+H13) -> 437.04281
B13: Other Growth | D13: =CHOOSE(DCF!$D$46,Scenarios!D45,Scenarios!D77,Scenarios!D110) -> 0.03 | E13: =CHOOSE(DCF!$D$46,Scenarios!E45,Scenarios!E77,Scenarios!E110) -> 0.02 | F13: =CHOOSE(DCF!$D$46,Scenarios!F45,Scenarios!F77,Scenarios!F110) -> 0.02 | G13: =CHOOSE(DCF!$D$46,Scenarios!G45,Scenarios!G77,Scenarios!G110) -> 0.02 | H13: =CHOOSE(DCF!$D$46,Scenarios!H45,Scenarios!H77,Scenarios!H110) -> 0.02
B14: Revenue | C14: =C4+C6+C8+C10+C12+3493-792 -> 18533 | D14: =D4+D6+D8+D10+D12 -> 18259.94 | E14: =E4+E6+E8+E10+E12 -> 19072.596 | F14: =F4+F6+F8+F10+F12 -> 19566.824 | G14: =G4+G6+G8+G10+G12 -> 20128.42 | H14: =H4+H6+H8+H10+H12 -> 20707.197
B16: Underlying EBITDA | C16: ='Full Historical 3-Statement'!F8 -> 6417 | D16: =D14*D17 -> 8216.973 | E16: =E14*E17 -> 8773.3941 | F16: =F14*F17 -> 9000.7389 | G16: =G14*G17 -> 9259.0731 | H16: =H14*H17 -> 9525.3105
B17: Underlying EBITDA / Revenue | C17: =C16/C14 -> 0.34624723 | D17: =CHOOSE(DCF!$D$46,Scenarios!D49,Scenarios!D81,Scenarios!D114) -> 0.45 | E17: =CHOOSE(DCF!$D$46,Scenarios!E49,Scenarios!E81,Scenarios!E114) -> 0.46 | F17: =CHOOSE(DCF!$D$46,Scenarios!F49,Scenarios!F81,Scenarios!F114) -> 0.46 | G17: =CHOOSE(DCF!$D$46,Scenarios!G49,Scenarios!G81,Scenarios!G114) -> 0.46 | H17: =CHOOSE(DCF!$D$46,Scenarios!H49,Scenarios!H81,Scenarios!H114) -> 0.46
B19: Depreciation & Amortisation | C19: ='Full Historical 3-Statement'!F9 -> 2382 | D19: =D20*D14 -> 2282.4925 | E19: =E20*E14 -> 2288.7115 | F19: =F20*F14 -> 2250.1847 | G19: =G20*G14 -> 2214.1262 | H19: =H20*H14 -> 2277.7916
B20: D&A / Revenue | C20: =C19/C14 -> 0.12852749 | D20: =CHOOSE(DCF!$D$46,Scenarios!D52,Scenarios!D84,Scenarios!D117) -> 0.125 | E20: =CHOOSE(DCF!$D$46,Scenarios!E52,Scenarios!E84,Scenarios!E117) -> 0.12 | F20: =CHOOSE(DCF!$D$46,Scenarios!F52,Scenarios!F84,Scenarios!F117) -> 0.115 | G20: =CHOOSE(DCF!$D$46,Scenarios!G52,Scenarios!G84,Scenarios!G117) -> 0.11 | H20: =CHOOSE(DCF!$D$46,Scenarios!H52,Scenarios!H84,Scenarios!H117) -> 0.11
B22: Tax Rate | C22: =DCF!H15 -> 0.39330855 | D22: =CHOOSE(DCF!$D$46,Scenarios!D54,Scenarios!D86,Scenarios!D119) -> 0.4 | E22: =CHOOSE(DCF!$D$46,Scenarios!E54,Scenarios!E86,Scenarios!E119) -> 0.4 | F22: =CHOOSE(DCF!$D$46,Scenarios!F54,Scenarios!F86,Scenarios!F119) -> 0.4 | G22: =CHOOSE(DCF!$D$46,Scenarios!G54,Scenarios!G86,Scenarios!G119) -> 0.4 | H22: =CHOOSE(DCF!$D$46,Scenarios!H54,Scenarios!H86,Scenarios!H119) -> 0.4
B24: CapEx | C24: =-'Full Historical 3-Statement'!F11 -> 3322 | D24: =CHOOSE(DCF!$D$46,Scenarios!D56,Scenarios!D88,Scenarios!D121) -> 3100 | E24: =CHOOSE(DCF!$D$46,Scenarios!E56,Scenarios!E88,Scenarios!E121) -> 2900 | F24: =CHOOSE(DCF!$D$46,Scenarios!F56,Scenarios!F88,Scenarios!F121) -> 2600 | G24: =CHOOSE(DCF!$D$46,Scenarios!G56,Scenarios!G88,Scenarios!G121) -> 2400 | H24: =CHOOSE(DCF!$D$46,Scenarios!H56,Scenarios!H88,Scenarios!H121) -> 2200
B25: CapEx Growth | D25: =D24/C24-1 -> -0.066827213 | E25: =E24/D24-1 -> -0.064516129 | F25: =F24/E24-1 -> -0.10344828 | G25: =G24/F24-1 -> -0.076923077 | H25: =H24/G24-1 -> -0.083333333
B27: Inventory | C27: ='Full Historical 3-Statement'!F105 -> 3013 | D27: =D28*D14/365 -> 2901.5795 | E27: =E28*E14/365 -> 2978.4602 | F27: =F28*F14/365 -> 3055.641 | G27: =G28*G14/365 -> 3143.3423 | H27: =H28*H14/365 -> 3233.7266
B28: Inventory Days | C28: =C27/C14*365 -> 59.339826 | D28: =CHOOSE(DCF!$D$46,Scenarios!D60,Scenarios!D92,Scenarios!D125) -> 58 | E28: =CHOOSE(DCF!$D$46,Scenarios!E60,Scenarios!E92,Scenarios!E125) -> 57 | F28: =CHOOSE(DCF!$D$46,Scenarios!F60,Scenarios!F92,Scenarios!F125) -> 57 | G28: =CHOOSE(DCF!$D$46,Scenarios!G60,Scenarios!G92,Scenarios!G125) -> 57 | H28: =CHOOSE(DCF!$D$46,Scenarios!H60,Scenarios!H92,Scenarios!H125) -> 57
B29: Trade Receivables | C29: ='Full Historical 3-Statement'!F106 -> 3748 | D29: =D30*D14/365 -> 3702.0152 | E29: =E30*E14/365 -> 3814.5192 | F29: =F30*F14/365 -> 3913.3647 | G29: =G30*G14/365 -> 4025.684 | H29: =H30*H14/365 -> 4141.4393
B30: Trade Receivables | C30: =C29/C14*365 -> 73.815356 | D30: =CHOOSE(DCF!$D$46,Scenarios!D62,Scenarios!D94,Scenarios!D127) -> 74 | E30: =CHOOSE(DCF!$D$46,Scenarios!E62,Scenarios!E94,Scenarios!E127) -> 73 | F30: =CHOOSE(DCF!$D$46,Scenarios!F62,Scenarios!F94,Scenarios!F127) -> 73 | G30: =CHOOSE(DCF!$D$46,Scenarios!G62,Scenarios!G94,Scenarios!G127) -> 73 | H30: =CHOOSE(DCF!$D$46,Scenarios!H62,Scenarios!H94,Scenarios!H127) -> 73
B31: Trade Payables | C31: =-'Full Historical 3-Statement'!F116 -> 4879 | D31: =D32*((-'Full Historical 3-Statement'!$F$17*1.03)/365) -> 5046.0857 | E31: =E32*((-'Full Historical 3-Statement'!$F$17*1.03^2)/365) -> 5147.4926 | F31: =F32*((-'Full Historical 3-Statement'!$F$17*1.03^3)/365) -> 5301.9174 | G31: =G32*((-'Full Historical 3-Statement'!$F$17*1.03^4)/365) -> 5460.9749 | H31: =H32*((-'Full Historical 3-Statement'!$F$17*1.03^5)/365) -> 5624.8042
B32: Trade Payables | C32: =C31/-'Full Historical 3-Statement'!F17*365 -> 103.57305 | D32: =CHOOSE(DCF!$D$46,Scenarios!D64,Scenarios!D96,Scenarios!D129) -> 104 | E32: =CHOOSE(DCF!$D$46,Scenarios!E64,Scenarios!E96,Scenarios!E129) -> 103 | F32: =CHOOSE(DCF!$D$46,Scenarios!F64,Scenarios!F96,Scenarios!F129) -> 103 | G32: =CHOOSE(DCF!$D$46,Scenarios!G64,Scenarios!G96,Scenarios!G129) -> 103 | H32: =CHOOSE(DCF!$D$46,Scenarios!H64,Scenarios!H96,Scenarios!H129) -> 103
B34: BASE CASE
C35: 2025A | D35: 2026E | E35: 2027E | F35: 2028E | G35: 2029E | H35: 2030E
B36: Copper | C36: 8122 | D36: =C36*(1+D37) -> 10233.72 | E36: =D36*(1+E37) -> 10745.406 | F36: =E36*(1+F37) -> 11282.676 | G36: =F36*(1+G37) -> 11677.57 | H36: =G36*(1+H37) -> 12086.285
B37: Copper Growth | D37: 0.26 | E37: 0.05 | F37: 0.05 | G37: 0.035 | H37: 0.035
B38: Premium Iron Ore | C38: 6651 | D38: =C38*(1+D39) -> 6717.51 | E38: =D38*(1+E39) -> 6986.2104 | F38: =E38*(1+F39) -> 6916.3483 | G38: =F38*(1+G39) -> 7054.6753 | H38: =G38*(1+H39) -> 7195.7688
B39: Premium Iron Ore Growth | D39: 0.01 | E39: 0.04 | F39: -0.01 | G39: 0.02 | H39: 0.02
B40: Manganese | C40: 472 | D40: =C40*(1+D41) -> 708 | E40: =D40*(1+E41) -> 729.24 | F40: =E40*(1+F41) -> 743.8248 | G40: =F40*(1+G41) -> 758.7013 | H40: =G40*(1+H41) -> 773.87532
B41: Manganese Growth | D41: 0.5 | E41: 0.03 | F41: 0.02 | G41: 0.02 | H41: 0.02
B42: Crop Nutrients | C42: 195 | D42: =C42*(1+D43) -> 196.95 | E42: =D42*(1+E43) -> 199.90425 | F42: =E42*(1+F43) -> 203.90233 | G42: =F42*(1+G43) -> 208.99989 | H42: =G42*(1+H43) -> 214.22489
B43: Crop Nutrients Growth | D43: 0.01 | E43: 0.015 | F43: 0.02 | G43: 0.025 | H43: 0.025
B44: Other | C44: 392 | D44: =C44*(1+D45) -> 403.76 | E44: =D44*(1+E45) -> 411.8352 | F44: =E44*(1+F45) -> 420.0719 | G44: =F44*(1+G45) -> 428.47334 | H44: =G44*(1+H45) -> 437.04281
B45: Other Growth | D45: 0.03 | E45: 0.02 | F45: 0.02 | G45: 0.02 | H45: 0.02
B46: Revenue | C46: 18533 | D46: =D36+D38+D40+D42+D44 -> 18259.94 | E46: =E36+E38+E40+E42+E44 -> 19072.596 | F46: =F36+F38+F40+F42+F44 -> 19566.824 | G46: =G36+G38+G40+G42+G44 -> 20128.42 | H46: =H36+H38+H40+H42+H44 -> 20707.197
B48: Underlying EBITDA | C48: 6417 | D48: =D46*D49 -> 8216.973 | E48: =E46*E49 -> 8773.3941 | F48: =F46*F49 -> 9000.7389 | G48: =G46*G49 -> 9259.0731 | H48: =H46*H49 -> 9525.3105
...

Sheet Rationale
B3: Assumption | C3: Rationale
B4: Copper | C4: Anglo expects copper production to grow over the next three years from 695kt in 2025 to 790-850kt in 2028. In 2026 alone, the Los Bronces second plant has restarted which will add incremental production, while Collahausi is expected to get better-grade ore later in the year. Future production growth is expected to come from Chiledue to high-grade ore and plant debottlenecking at the end of 2027. Peru to remain stable. Copper price is expected to growth roughly 20% in 2026, as reported by the World Bank, and usage to grow 2% per year supported by electricity networks, urbanisation, manufacturing and data centres, creating a very strong pricing environment. In 2027, we can expect a price normalisation depsite the increase in production. There is a supply gap remaining for Copper therefore 2028 onwards forecast we can expect an attractive backdrop still but not continuously elevated price increases every year
B5: Premium Iron Ore | C5: Management expects production in Kumba to slightly increase through to 2028 and Minas-Rio to drop from 2026 to 2028; however, sales are not expected to be impacted, beacuase Kumba plans to draw down finished-product inventory while production is lower. The World Bank forecasts the average iron ore price will decrease from the $97/dmt in 2026 to $95/dmt in 2027, due to China property downturn. Continous production growth from large exporters such as Australia and Brazil put pressure on the price.
B6: Manganese | C6: South32 and South Africa Manganese expect production to stay flat in 2026 and 2027. The market remained relatively well supplied and overall demand growth was modest in 2026. S&P expects manganese demand to increase substantially over the long term because manganese is increasingly used in battery chemistries.
B7: Crop Nutrients | C7: Woodsmith mining is still being developed, but could be a transformational asset once commerically ready. Majority of the revenue from this line is being generated by The Cibra Group, a Brazilian fertiliser distributor. Anglo has piloted sales of Woodsmith across the EU, NA, China and Brazil to prove demand for it, establish pricing and build a future market before mining commences. No Board approval date has been published yet.
B8: Underlying EBITDA | C8: Copper being Anglos highest margin core business, resulting in an EBITDA margin to naturally rise helped by the very strong copper pricing. De Beers sell off remove the negative contribution the company has had on EBITDA. Anglo should have a structurally higher EBITDA margin. Additionally, Anglo management delivered a $1.8bn run-rate cost saving program ending in 2025, H1 benefits from those savings.
B9: D&A | C9: With the sale of De Beers, D&A / Revenue will increase slightly due to the contribution of $276m it was contributing. With Copper revenue expected to grow driven by price increase, D&A / Revenue will fall.
B10: CapEx | C10: Management guideline

Sheet Historical 3-Statement
A1: Anglo American plc — Condensed Historical 3-Statement
A2: 2021A–2025A | US$ million | 20 core lines. All condensed lines now trace to the Full Historical 3-Statement sheet; 2025 operating metrics are continuing operations.
A13: US$mm | B13: 2021 | C13: 2022 | D13: 2023 | E13: 2024 | F13: 2025
A15: INCOME STATEMENT
A16: Revenue | B16: ='Full Historical 3-Statement'!B7 -> 41554 | C16: ='Full Historical 3-Statement'!C7 -> 35118 | D16: ='Full Historical 3-Statement'!D7 -> 30652 | E16: ='Full Historical 3-Statement'!E7 -> 27290 | F16: ='Full Historical 3-Statement'!F7 -> 18546
A17: Underlying EBITDA | B17: ='Full Historical 3-Statement'!B8 -> 20634 | C17: ='Full Historical 3-Statement'!C8 -> 14495 | D17: ='Full Historical 3-Statement'!D8 -> 9958 | E17: ='Full Historical 3-Statement'!E8 -> 8460 | F17: ='Full Historical 3-Statement'!F8 -> 6417
A18: Depreciation & Amortisation | B18: ='Full Historical 3-Statement'!B9 -> 2844 | C18: ='Full Historical 3-Statement'!C9 -> 2532 | D18: ='Full Historical 3-Statement'!D9 -> 2790 | E18: ='Full Historical 3-Statement'!E9 -> 3175 | F18: ='Full Historical 3-Statement'!F9 -> 2382
A19: Underlying EBIT | B19: ='Full Historical 3-Statement'!B10 -> 17790 | C19: ='Full Historical 3-Statement'!C10 -> 11963 | D19: ='Full Historical 3-Statement'!D10 -> 7168 | E19: ='Full Historical 3-Statement'!E10 -> 5285 | F19: ='Full Historical 3-Statement'!F10 -> 4035
A20: Finance, Special Items, Tax, Discontinued Ops & NCI | B20: ='Full Historical 3-Statement'!B32-'Full Historical 3-Statement'!B10 -> -9228 | C20: ='Full Historical 3-Statement'!C32-'Full Historical 3-Statement'!C10 -> -7449 | D20: ='Full Historical 3-Statement'!D32-'Full Historical 3-Statement'!D10 -> -6885 | E20: ='Full Historical 3-Statement'!E32-'Full Historical 3-Statement'!E10 -> -8353 | F20: ='Full Historical 3-Statement'!F32-'Full Historical 3-Statement'!F10 -> -7776
A21: Net Income Attributable to Shareholders | B21: ='Full Historical 3-Statement'!B32 -> 8562 | C21: ='Full Historical 3-Statement'!C32 -> 4514 | D21: ='Full Historical 3-Statement'!D32 -> 283 | E21: ='Full Historical 3-Statement'!E32 -> -3068 | F21: ='Full Historical 3-Statement'!F32 -> -3741
A24: CASH FLOW STATEMENT
A25: Net Cash from Operating Activities | B25: ='Full Historical 3-Statement'!B55 -> 16723 | C25: ='Full Historical 3-Statement'!C55 -> 9765 | D25: ='Full Historical 3-Statement'!D55 -> 6496 | E25: ='Full Historical 3-Statement'!E55 -> 8103 | F25: ='Full Historical 3-Statement'!F55 -> 5511
A26: Capital Expenditure | B26: ='Full Historical 3-Statement'!B11 -> -5193 | C26: ='Full Historical 3-Statement'!C11 -> -5738 | D26: ='Full Historical 3-Statement'!D11 -> -5734 | E26: ='Full Historical 3-Statement'!E11 -> -5490 | F26: ='Full Historical 3-Statement'!F11 -> -3322
A27: Other Investing Activities | B27: ='Full Historical 3-Statement'!B68-'Full Historical 3-Statement'!B11 -> -365 | C27: ='Full Historical 3-Statement'!C68-'Full Historical 3-Statement'!C11 -> -79 | D27: ='Full Historical 3-Statement'!D68-'Full Historical 3-Statement'!D11 -> 174 | E27: ='Full Historical 3-Statement'!E68-'Full Historical 3-Statement'!E11 -> 355 | F27: ='Full Historical 3-Statement'!F68-'Full Historical 3-Statement'!F11 -> 1414
A28: Net Cash from Financing Activities | B28: ='Full Historical 3-Statement'!B82 -> -9356 | C28: ='Full Historical 3-Statement'!C82 -> -4368 | D28: ='Full Historical 3-Statement'!D82 -> -3223 | E28: ='Full Historical 3-Statement'!E82 -> -840 | F28: ='Full Historical 3-Statement'!F82 -> -5491
A29: FX / Other Cash Movement | B29: ='Full Historical 3-Statement'!B86 -> -260 | C29: ='Full Historical 3-Statement'!C86 -> -237 | D29: ='Full Historical 3-Statement'!D86 -> -39 | E29: ='Full Historical 3-Statement'!E86 -> -68 | F29: ='Full Historical 3-Statement'!F86 -> 172
A30: Ending Cash & Cash Equivalents (CFS) | B30: ='Full Historical 3-Statement'!B87 -> 9057 | C30: ='Full Historical 3-Statement'!C87 -> 8400 | D30: ='Full Historical 3-Statement'!D87 -> 6074 | E30: ='Full Historical 3-Statement'!E87 -> 8134 | F30: ='Full Historical 3-Statement'!F87 -> 6418
A33: BALANCE SHEET
A34: Cash & Cash Equivalents | B34: ='Full Historical 3-Statement'!B110 -> 9066 | C34: ='Full Historical 3-Statement'!C110 -> 8412 | D34: ='Full Historical 3-Statement'!D110 -> 6088 | E34: ='Full Historical 3-Statement'!E110 -> 8167 | F34: ='Full Historical 3-Statement'!F110 -> 6436
A35: Property, Plant & Equipment | B35: ='Full Historical 3-Statement'!B93 -> 39501 | C35: ='Full Historical 3-Statement'!C93 -> 41125 | D35: ='Full Historical 3-Statement'!D93 -> 43949 | E35: ='Full Historical 3-Statement'!E93 -> 40844 | F35: ='Full Historical 3-Statement'!F93 -> 34253
A36: Other Assets | B36: ='Full Historical 3-Statement'!B113-'Full Historical 3-Statement'!B110-'Full Historical 3-Statement'!B93 -> 17418 | C36: ='Full Historical 3-Statement'!C113-'Full Historical 3-Statement'!C110-'Full Historical 3-Statement'!C93 -> 17870 | D36: ='Full Historical 3-Statement'!D113-'Full Historical 3-Statement'!D110-'Full Historical 3-Statement'!D93 -> 16507 | E36: ='Full Historical 3-Statement'!E113-'Full Historical 3-Statement'!E110-'Full Historical 3-Statement'!E93 -> 15855 | F36: ='Full Historical 3-Statement'!F113-'Full Historical 3-Statement'!F110-'Full Historical 3-Statement'!F93 -> 15305
A37: Total Assets | B37: ='Full Historical 3-Statement'!B113 -> 65985 | C37: ='Full Historical 3-Statement'!C113 -> 67407 | D37: ='Full Historical 3-Statement'!D113 -> 66544 | E37: ='Full Historical 3-Statement'!E113 -> 64866 | F37: ='Full Historical 3-Statement'!F113 -> 55994
A38: Gross Debt | B38: =-('Full Historical 3-Statement'!B117+'Full Historical 3-Statement'!B125) -> 12856 | C38: =-('Full Historical 3-Statement'!C117+'Full Historical 3-Statement'!C125) -> 14365 | D38: =-('Full Historical 3-Statement'!D117+'Full Historical 3-Statement'!D125) -> 16912 | E38: =-('Full Historical 3-Statement'!E117+'Full Historical 3-Statement'!E125) -> 18210 | F38: =-('Full Historical 3-Statement'!F117+'Full Historical 3-Statement'!F125) -> 15481
A39: Other Liabilities | B39: =-'Full Historical 3-Statement'!B133-B38 -> 18359 | C39: =-'Full Historical 3-Statement'!C133-C38 -> 19089 | D39: =-'Full Historical 3-Statement'!D133-D38 -> 18015 | E39: =-'Full Historical 3-Statement'!E133-E38 -> 18123 | F39: =-'Full Historical 3-Statement'!F133-F38 -> 16396
A40: Total Equity | B40: ='Full Historical 3-Statement'!B144 -> 34770 | C40: ='Full Historical 3-Statement'!C144 -> 33953 | D40: ='Full Historical 3-Statement'!D144 -> 31617 | E40: ='Full Historical 3-Statement'!E144 -> 28533 | F40: ='Full Historical 3-Statement'!F144 -> 24117
A41: Balance Check | B41: =B37-B38-B39-B40 -> 0 | C41: =C37-C38-C39-C40 -> 0 | D41: =D37-D38-D39-D40 -> 0 | E41: =E37-E38-E39-E40 -> 0 | F41: =F37-F38-F39-F40 -> 0
A44: Audit trail: the condensed sheet contains no historical hardcodes. Its selected operating, cash-flow and balance-sheet lines are linked to the Full Historical 3-Statement. The catch-all below Underlying EBIT aggregates all items required to reconcile to reported shareholder net income.

Sheet Full Historical 3-Statement
A1: Anglo American plc — Full Historical 3-Statement
A2: 2021A–2025A | US$ million. 2025 operating P&L / APM metrics use continuing operations, with discontinued operations shown separately; cash flow and balance sheet remain total Group. 2022 balance sheet uses the IAS 12-restated comparative.
A4: US$mm | B4: 2021 | C4: 2022 | D4: 2023 | E4: 2024 | F4: 2025 | H4: Period | I4: Primary Source | J4: Basis / Note
H5: 2021A–2022A | I5: https://www.angloamerican.com/~/media/Files/A/Anglo-American-Group-v5/PLC/investors/annual-reporting/2022/aa-annual-report-full-2022.pdf | J5: 2022 Annual Report; 2022 balance-sheet DTL / equity updated for IAS 12 restatement.
A6: SUPPLEMENTAL OPERATING KPIs / APMs | H6: 2022A restatement | I6: https://www.annualreports.com/HostedData/AnnualReportArchive/a/LSE_AAL_2023.pdf | J6: 2023 Annual Report comparative; used for restated 2022 DTL and equity.
A7: Revenue | B7: ='Source Data'!B5 -> 41554 | C7: ='Source Data'!C5 -> 35118 | D7: ='Source Data'!D5 -> 30652 | E7: ='Source Data'!E5 -> 27290 | F7: ='Source Data'!F5 -> 18546 | H7: 2023A–2024A | I7: https://www.angloamerican.com/~/media/Files/A/Anglo-American-Group-v9/PLC/investors/annual-reporting/2024/aa-annual-report-full-2024.pdf | J7: 2024 Annual Report.
A8: Underlying EBITDA | B8: ='Source Data'!B6 -> 20634 | C8: ='Source Data'!C6 -> 14495 | D8: ='Source Data'!D6 -> 9958 | E8: ='Source Data'!E6 -> 8460 | F8: ='Source Data'!F6 -> 6417 | H8: 2025A | I8: https://www.angloamerican.com/~/media/Files/A/Anglo-American-Group-v9/PLC/investors/annual-reporting/2025/aa-annual-report-full-2025.pdf | J8: 2025 Annual Report; operating P&L/APMs continuing operations; discontinued operations shown separately.
A9: Depreciation & Amortisation | B9: =B8-B10 -> 2844 | C9: =C8-C10 -> 2532 | D9: =D8-D10 -> 2790 | E9: =E8-E10 -> 3175 | F9: =F8-F10 -> 2382
A10: Underlying EBIT | B10: ='Source Data'!B7 -> 17790 | C10: ='Source Data'!C7 -> 11963 | D10: ='Source Data'!D7 -> 7168 | E10: ='Source Data'!E7 -> 5285 | F10: ='Source Data'!F7 -> 4035
A11: Capital Expenditure (APM) | B11: ='Source Data'!B11 -> -5193 | C11: ='Source Data'!C11 -> -5738 | D11: ='Source Data'!D11 -> -5734 | E11: ='Source Data'!E11 -> -5490 | F11: ='Source Data'!F11 -> -3322
A12: Net Debt | B12: 3842 | C12: 6918 | D12: 10615 | E12: 10623 | F12: 8571
A15: INCOME STATEMENT
A16: Revenue | B16: 41554 | C16: 35118 | D16: 30652 | E16: 27290 | F16: 18546
A17: Operating Costs | B17: -23962 | C17: -25875 | D17: -26748 | E17: -27518 | F17: -17194
A18: Operating Profit / (Loss) | B18: =B16+B17 -> 17592 | C18: =C16+C17 -> 9243 | D18: =D16+D17 -> 3904 | E18: =E16+E17 -> -228 | F18: =F16+F17 -> 1352
A19: Non-Operating Special Items | B19: -207 | C19: -77 | D19: -100 | E19: -79 | F19: -59
A20: Net Income from Associates & Joint Ventures | B20: 634 | C20: 641 | D20: 378 | E20: 134 | F20: 82
A21: Profit before Net Finance Costs and Tax | B21: =SUM(B18:B20) -> 18019 | C21: =SUM(C18:C20) -> 9807 | D21: =SUM(D18:D20) -> 4182 | E21: =SUM(E18:E20) -> -173 | F21: =SUM(F18:F20) -> 1375
A22: Investment Income | B22: 139 | C22: 214 | D22: 427 | E22: 426 | F22: 392
A23: Interest Expense | B23: -550 | C23: -515 | D23: -990 | E23: -1172 | F23: -862
A24: Other Net Financing Gains / (Losses) | B24: 21 | C24: -26 | D24: -24 | E24: -5 | F24: -22
A25: Net Finance Costs | B25: =SUM(B22:B24) -> -390 | C25: =SUM(C22:C24) -> -327 | D25: =SUM(D22:D24) -> -587 | E25: =SUM(E22:E24) -> -751 | F25: =SUM(F22:F24) -> -492
A26: Profit / (Loss) before Tax | B26: =B21+B25 -> 17629 | C26: =C21+C25 -> 9480 | D26: =D21+D25 -> 3595 | E26: =E21+E25 -> -924 | F26: =F21+F25 -> 883
A27: Income Tax | B27: -5930 | C27: -3456 | D27: -2251 | E27: -1864 | F27: -1587
A28: Profit / (Loss) before Discontinued Operations | B28: =B26+B27 -> 11699 | C28: =C26+C27 -> 6024 | D28: =D26+D27 -> 1344 | E28: =E26+E27 -> -2788 | F28: =F26+F27 -> -704
A29: Discontinued Operations | B29: 0 | C29: 0 | D29: 0 | E29: 0 | F29: -2466
A30: Profit / (Loss) for the Financial Year | B30: =B28+B29 -> 11699 | C30: =C28+C29 -> 6024 | D30: =D28+D29 -> 1344 | E30: =E28+E29 -> -2788 | F30: =F28+F29 -> -3170
A31: Non-Controlling Interests | B31: 3137 | C31: 1510 | D31: 1061 | E31: 280 | F31: 571
A32: Net Income Attributable to Shareholders | B32: =B30-B31 -> 8562 | C32: =C30-C31 -> 4514 | D32: =D30-D31 -> 283 | E32: =E30-E31 -> -3068 | F32: =F30-F31 -> -3741
A35: CASH FLOW STATEMENT
A36: Profit / (Loss) before Tax | B36: =B26 -> 17629 | C36: =C26 -> 9480 | D36: =D26 -> 3595 | E36: =E26 -> -924 | F36: =F26 -> 883
A37: Net Finance Costs | B37: =-B25 -> 390 | C37: =-C25 -> 327 | D37: =-D25 -> 587 | E37: =-E25 -> 751 | F37: =-F25 -> 492
A38: Net Income from Associates & Joint Ventures | B38: =-B20 -> -634 | C38: =-C20 -> -641 | D38: =-D20 -> -378 | E38: =-E20 -> -134 | F38: =-F20 -> -82
A39: Non-Operating Special Items | B39: =-B19 -> 207 | C39: =-C19 -> 77 | D39: =-D19 -> 100 | E39: =-E19 -> 79 | F39: =-F19 -> 59
A40: Operating Profit / (Loss) | B40: =SUM(B36:B39) -> 17592 | C40: =SUM(C36:C39) -> 9243 | D40: =SUM(D36:D39) -> 3904 | E40: =SUM(E36:E39) -> -228 | F40: =SUM(F36:F39) -> 1352
A41: Revenue & Operating Special Items | B41: -499 | C41: 1681 | D41: 2652 | E41: 5240 | F41: 2548
A42: Cash Element of Special Items | B42: -18 | C42: -12 | D42: -89 | E42: -331 | F42: -273
A43: Depreciation & Amortisation | B43: 2715 | C43: 2446 | D43: 2685 | E43: 3072 | F43: 2301
A44: Share-Based Payment Expense | B44: 189 | C44: 215 | D44: 175 | E44: 189 | F44: 129
A45: Provisions / Retirement Benefits | B45: -303 | C45: 250 | D45: 25 | E45: -204 | F45: 181
...

Sheet Source Data
A1: Anglo American plc — Historical Source Data
A2: US$ million. 2025 operating P&L / capex metrics reflect continuing operations after Steelmaking Coal, Nickel and PGMs were classified as discontinued operations; earlier years are as reported.
A4: Source Metric | B4: 2021 | C4: 2022 | D4: 2023 | E4: 2024 | F4: 2025 | G4: Source / Note | H4: URL
A5: Revenue | B5: 41554 | C5: 35118 | D5: 30652 | E5: 27290 | F5: 18546 | G5: FY2021–FY2024 as reported; FY2025 continuing operations. | H5: https://www.angloamerican.com/media/press-releases/2026/20-02-2026
A6: Underlying EBITDA | B6: 20634 | C6: 14495 | D6: 9958 | E6: 8460 | F6: 6417 | G6: Company APM; FY2025 continuing operations. | H6: https://www.angloamerican.com/~/media/Files/A/Anglo-American-Group-v9/PLC/investors/annual-reporting/2025/aa-annual-report-full-2025.pdf
A7: Underlying EBIT | B7: 17790 | C7: 11963 | D7: 7168 | E7: 5285 | F7: 4035 | G7: 2024 = EBITDA less reported D&A; FY2025 continuing operations. | H7: https://www.angloamerican.com/~/media/Files/A/Anglo-American-Group-v9/PLC/investors/annual-reporting/2024/aa-annual-report-full-2024.pdf
A8: Net Finance Costs | B8: -390 | C8: -327 | D8: -587 | E8: -751 | F8: -492 | G8: Reported net finance costs incl. financing special items / remeasurements where applicable. | H8: https://www.angloamerican.com/~/media/Files/A/Anglo-American-Group-v9/PLC/investors/annual-reporting/2025/aa-annual-report-full-2025.pdf
A9: Net Income Attributable to Shareholders | B9: 8562 | C9: 4514 | D9: 283 | E9: -3068 | F9: -3741 | G9: Profit/(loss) attributable to equity shareholders of Anglo American plc. | H9: https://www.angloamerican.com/~/media/Files/A/Anglo-American-Group-v9/PLC/investors/annual-reporting/2025/aa-annual-report-full-2025.pdf
A10: Net Cash from Operating Activities | B10: 16723 | C10: 9765 | D10: 6496 | E10: 8103 | F10: 5511 | G10: Total Group consolidated cash flow statement. | H10: https://www.angloamerican.com/~/media/Files/A/Anglo-American-Group-v9/PLC/investors/annual-reporting/2025/aa-annual-report-full-2025.pdf
A11: Capital Expenditure | B11: -5193 | C11: -5738 | D11: -5734 | E11: -5490 | F11: -3322 | G11: Company capex APM; FY2025 continuing operations. | H11: https://www.angloamerican.com/~/media/Files/A/Anglo-American-Group-v9/PLC/investors/annual-reporting/2025/aa-annual-report-full-2025.pdf
A12: Net Cash Used in Investing Activities | B12: -5558 | C12: -5817 | D12: -5560 | E12: -5135 | F12: -1908 | G12: Total Group consolidated cash flow statement. | H12: https://www.angloamerican.com/~/media/Files/A/Anglo-American-Group-v9/PLC/investors/annual-reporting/2025/aa-annual-report-full-2025.pdf
A13: Net Cash Used in Financing Activities | B13: -9356 | C13: -4368 | D13: -3223 | E13: -840 | F13: -5491 | G13: Total Group consolidated cash flow statement. | H13: https://www.angloamerican.com/~/media/Files/A/Anglo-American-Group-v9/PLC/investors/annual-reporting/2025/aa-annual-report-full-2025.pdf
A14: FX / Other Cash Movement | B14: -260 | C14: -237 | D14: -39 | E14: -68 | F14: 172 | G14: Effect of changes in foreign exchange rates on cash. | H14: https://www.angloamerican.com/~/media/Files/A/Anglo-American-Group-v9/PLC/investors/annual-reporting/2025/aa-annual-report-full-2025.pdf
A15: Opening Cash (CFS) | B15: 7508 | C15: 9057 | D15: 8400 | E15: 6074 | F15: 8134 | G15: Cash and cash equivalents at start of year per consolidated cash flow statement. | H15: https://www.angloamerican.com/~/media/Files/A/Anglo-American-Group-v5/PLC/investors/annual-reporting/2022/aa-annual-report-full-2021.pdf
... A20: Total Equity | B20: 34770 | C20: 33953 | D20: 31617 | E20: 28533 | F20: 24117 | G20: Consolidated total equity; 2022 uses latest restated comparative. | H20: https://www.angloamerican.com/~/media/Files/A/Anglo-American-Group-v9/PLC/investors/annual-reporting/2025/aa-annual-report-full-2025.pdf
