Workbook

Sheet Full Historical Statements
B1: NIKE, Inc. — Full Historical Three-Statement Model
B2: USD $mm, except per share data; historical periods sourced from NIKE 10-Ks.
B4: Assumptions | E4: 2021 | F4: 2022 | G4: 2023 | H4: 2024 | I4: 2025 | J4: 2026 | K4: 2027 | L4: 2028 | M4: 2029 | N4: 2030
B5: Revenue Growth (%) | F5: =F22/E22-1 -> 0.048767345 | G5: =G22/F22-1 -> 0.096488975 | H5: =H22/G22-1 -> 0.0028310912 | I5: =I22/H22-1 -> -0.098380125 | J5: 0.01 | K5: 0.07 | L5: 0.08 | M5: 0.09 | N5: 0.09
B6: COGs (% of Revenue) | E6: =E23/E22 -> 0.55179846 | F6: =F23/F22 -> 0.54016271 | G6: =G23/G22 -> 0.56475389 | H6: =H23/H22 -> 0.55439819 | I6: =I23/I22 -> 0.57265326 | J6: 0.58 | K6: 0.56 | L6: 0.54 | M6: 0.52 | N6: 0.52
B7: Demand creation (Growth Rate) | F7: =F25/E25-1 -> 0.23635196 | G7: =G25/F25-1 -> 0.054545455 | H7: =H25/G25-1 -> 0.055418719 | I7: =I25/H25-1 -> 0.09428238 | J7: 0.1 | K7: 0.12 | L7: 0.12 | M7: 0.14 | N7: 0.14
B8: S&A (% of Revenue) | E8: =E27/E22 -> 0.2924469 | F8: =F27/F22 -> 0.31693428 | G8: =G27/G22 -> 0.31975711 | H8: =H27/H22 -> 0.32272887 | I8: =I27/I22 -> 0.34740547 | J8: 0.35 | K8: 0.36 | L8: 0.36 | M8: 0.36 | N8: 0.36
B9: D&A (% of PPE) | E9: =E27/E22 -> 0.2924469 | F9: =F81/F47 -> 0.1496556 | G9: =G81/G47 -> 0.13835859 | H9: =H81/H47 -> 0.1592 | I9: =I81/I47 -> 0.16052196 | J9: =AVERAGE(G9:I9) -> 0.15269352 | K9: =AVERAGE(H9:J9) -> 0.15747182 | L9: =AVERAGE(I9:K9) -> 0.15689576 | M9: =AVERAGE(J9:L9) -> 0.15568703 | N9: =AVERAGE(K9:M9) -> 0.15668487
B10: Interest (% of Debt) | E10: =E29/E63 -> 0.027833847 | F10: =F29/F63 -> 0.022982063 | G10: =G29/G63 -> -0.00067211829 | H10: =H29/H63 -> -0.020372011 | I10: =I29/I63 -> -0.013440523 | J10: 0.02 | K10: 0.02 | L10: 0.02 | M10: 0.02 | N10: 0.02
B11: Tax Rate | E11: =E32/E31 -> 0.14021919 | F11: =F32/F31 -> 0.090963765 | G11: =G32/G31 -> 0.18238994 | H11: =H32/H31 -> 0.14925373 | I11: =I32/I31 -> 0.17142857 | J11: 0.15 | K11: 0.15 | L11: 0.15 | M11: 0.15 | N11: 0.15
B12: Accounts Receivable (Days) | E12: =E43/E22*365 -> 36.575396 | F12: =F43/F22*365 -> 36.468743 | G12: =G43/G22*365 -> 29.439737 | H12: =H43/H22*365 -> 31.460126 | I12: =I43/I22*365 -> 37.178626 | J12: 31 | K12: 31 | L12: 31 | M12: 31 | N12: 31
B13: Inventory (Days) | E13: =E44/E23*365 -> 101.79484 | F13: =F44/F23*365 -> 121.80651 | G13: =G44/G23*365 -> 106.67969 | H13: =H44/H23*365 -> 96.380509 | I13: =I44/I23*365 -> 103.07647 | J13: 95 | K13: 93 | L13: 90 | M13: 90 | N13: 90
B14: Accounts Payable (Days) | E14: =E58/E23*365 -> 42.119954 | F14: =F58/F23*365 -> 48.57794 | G14: =G58/G23*365 -> 36.115125 | H14: =H58/H23*365 -> 36.544864 | I14: =I58/I23*365 -> 47.88397 | J14: 40 | K14: 40 | L14: 40 | M14: 40 | N14: 40
B15: CAPEX (3% of Revenue) | E15: =E94 -> -695 | F15: =F94 -> -758 | G15: =G94 -> -969 | H15: =H94 -> -812 | I15: =I94 -> -430 | J15: =-J22*3% -> -1403.1627 | K15: =-K22*3% -> -1501.3841 | L15: =-L22*3% -> -1621.4948 | M15: =-M22*3% -> -1767.4293 | N15: =-N22*3% -> -1926.498
B16: Days | E16: 365 | F16: 365 | G16: 365 | H16: 365 | I16: 365 | J16: 365 | K16: 365 | L16: 365 | M16: 365 | N16: 365
B19: Fiscal Year Ended May 31 | E19: 2021 | F19: 2022 | G19: 2023 | H19: 2024 | I19: 2025 | J19: 2026 | K19: 2027 | L19: 2028 | M19: 2029 | N19: 2030
B21: Income Statement | C21: Income Statement | D21: Income Statement | E21: Income Statement | F21: Income Statement | G21: Income Statement | H21: Income Statement | I21: Income Statement | J21: Income Statement | K21: Income Statement | L21: Income Statement | M21: Income Statement | N21: Income Statement
B22: Revenues | E22: 44538 | F22: 46710 | G22: 51217 | H22: 51362 | I22: 46309 | J22: =I22*(1+J5) -> 46772.09 | K22: =J22*(1+K5) -> 50046.136 | L22: =K22*(1+L5) -> 54049.827 | M22: =L22*(1+M5) -> 58914.312 | N22: =M22*(1+N5) -> 64216.6
B23: Cost of sales | E23: 24576 | F23: 25231 | G23: 28925 | H23: 28475 | I23: 26519 | J23: =J22*J6 -> 27127.812 | K23: =K22*K6 -> 28025.836 | L23: =L22*L6 -> 29186.907 | M23: =M22*M6 -> 30635.442 | N23: =N22*N6 -> 33392.632
B24: Gross profit | E24: 19962 | F24: 21479 | G24: 22292 | H24: 22887 | I24: 19790 | J24: =J22-J23 -> 19644.278 | K24: =K22-K23 -> 22020.3 | L24: =L22-L23 -> 24862.921 | M24: =M22-M23 -> 28278.87 | N24: =N22-N23 -> 30823.968
B25: Demand creation expense | E25: 3114 | F25: 3850 | G25: 4060 | H25: 4285 | I25: 4689 | J25: =I25*(1+J7) -> 5157.9 | K25: =J25*(1+K7) -> 5776.848 | L25: =K25*(1+L7) -> 6470.0698 | M25: =L25*(1+M7) -> 7375.8795 | N25: =M25*(1+N7) -> 8408.5027
B26: Operating overhead expense | E26: 9911 | F26: 10954 | G26: 12317 | H26: 12291 | I26: 11399 | J26: =J27-J25 -> 11212.332 | K26: =K27-K25 -> 12239.761 | L26: =L27-L25 -> 12987.868 | M26: =M27-M25 -> 13833.273 | N26: =N27-N25 -> 14709.473
B27: Total selling and administrative expense | E27: 13025 | F27: 14804 | G27: 16377 | H27: 16576 | I27: 16088 | J27: =J22*J8 -> 16370.231 | K27: =K22*K8 -> 18016.609 | L27: =L22*L8 -> 19457.938 | M27: =M22*M8 -> 21209.152 | N27: =N22*N8 -> 23117.976
B28: Income from operations | E28: =E24-E27 -> 6937 | F28: =F24-F27 -> 6675 | G28: =G24-G27 -> 5915 | H28: =H24-H27 -> 6311 | I28: =I24-I27 -> 3702 | J28: =J24-J27 -> 3274.0463 | K28: =K24-K27 -> 4003.6909 | L28: =L24-L27 -> 5404.9827 | ... N28: =N24-N27 -> 7705.992
B29: Interest expense (income), net | E29: 262 | F29: 205 | G29: -6 | H29: -161 | I29: -107 | J29: =J130*J10 -> 140.16 | K29: =K130*K10 -> 140.14 | L29: =L130*L10 -> 140.14 | M29: =M130*M10 -> 130.14 | N29: =N130*N10 -> 130.36
B30: Other (income) expense, net | E30: 14 | F30: -181 | G30: -280 | H30: -228 | I30: -76 | J30: -76 | K30: -76 | L30: -76 | M30: -76 | N30: -76
B31: Income before income taxes | E31: 6661 | F31: 6651 | G31: 6201 | H31: 6700 | I31: 3885 | J31: =J28-J29-J30 -> 3209.8863 | K31: =K28-K29-K30 -> 3939.5509 | L31: =L28-L29-L30 -> 5340.8427 | M31: =M28-M29-M30 -> 7015.5774 | N31: =N28-N29-N30 -> 7651.632
B32: Income tax expense | E32: 934 | F32: 605 | G32: 1131 | H32: 1000 | I32: 666 | J32: =J31*J11 -> 481.48295 | K32: =K31*K11 -> 590.93264 | L32: =L31*L11 -> 801.12641 | M32: =M31*M11 -> 1052.3366 | N32: =N31*N11 -> 1147.7448
B33: Net income | E33: 5727 | F33: 6046 | G33: 5070 | H33: 5700 | I33: 3219 | J33: =J31-J32 -> 2728.4034 | K33: =K31-K32 -> 3348.6183 | L33: =L31-L32 -> 4539.7163 | M33: =M31-M32 -> 5963.2408 | N33: =N31-N32 -> 6503.8872
B34: Basic EPS | E34: 3.64 | F34: 3.83 | G34: 3.27 | H34: 3.76 | I34: 2.17
B35: Diluted EPS | E35: 3.56 | F35: 3.75 | G35: 3.23 | H35: 3.73 | I35: 2.16
B36: Basic weighted average shares | E36: 1573 | F36: 1578.8 | G36: 1551.6 | H36: 1517.6 | I36: 1484.9
B37: Diluted weighted average shares | E37: 1609.4 | F37: 1610.8 | G37: 1569.8 | H37: 1529.7 | I37: 1487.6
B40: Balance Sheet — Assets | C40: Balance Sheet — Assets | D40: Balance Sheet — Assets | E40: Balance Sheet — Assets | F40: Balance Sheet — Assets | G40: Balance Sheet — Assets | H40: Balance Sheet — Assets | I40: Balance Sheet — Assets | J40: Balance Sheet — Assets | K40: Balance Sheet — Assets | L40: Balance Sheet — Assets | M40: Balance Sheet — Assets | N40: Balance Sheet — Assets
B41: Cash and equivalents | E41: 9889 | F41: 8574 | G41: 7441 | H41: 9860 | I41: 7464 | J41: =J107 -> 7380.033 | K41: =K107 -> 9028.7919 | L41: =L107 -> 9830.929 | M41: =M107 -> 11740.446 | N41: =N107 -> 13586.53
B42: Short-term investments | E42: 3587 | F42: 4423 | G42: 3234 | H42: 1722 | I42: 1687 | J42: =AVERAGE(G42:I42) -> 2214.3333 | K42: =AVERAGE(H42:J42) -> 1874.4444 | L42: =AVERAGE(I42:K42) -> 1925.2593 | M42: =AVERAGE(J42:L42) -> 2004.679 | N42: =AVERAGE(K42:M42) -> 1934.7942
B43: Accounts receivable, net | E43: 4463 | F43: 4667 | G43: 4131 | H43: 4427 | I43: 4717 | J43: =J22*J12/J16 -> 3972.4241 | K43: =K22*K12/K16 -> 4250.4938 | L43: =L22*L12/L16 -> 4590.5333 | M43: =M22*M12/M16 -> 5003.6813 | N43: =N22*N12/N16 -> 5454.0126
B44: Inventories | E44: 6854 | F44: 8420 | G44: 8454 | H44: 7519 | I44: 7489 | J44: =J23*J13/J16 -> 7060.6634 | K44: =K23*K13/K16 -> 7140.8295 | L44: =L23*L13/L16 -> 7196.7715 | M44: =M23*M13/M16 -> 7553.9446 | N44: =N23*N13/N16 -> 8233.7996
B45: Prepaid expenses and other current assets | E45: 1498 | F45: 2129 | G45: 1942 | H45: 1854 | I45: 2005 | J45: =AVERAGE(G45:I45) -> 1933.6667 | K45: =AVERAGE(H45:J45) -> 1930.8889 | L45: =AVERAGE(I45:K45) -> 1956.5185 | M45: =AVERAGE(J45:L45) -> 1940.358 | N45: =AVERAGE(K45:M45) -> 1942.5885
B46: Total current assets | E46: 26291 | F46: 28213 | G46: 25202 | H46: 25382 | I46: 23362 | J46: =SUM(J41:J45) -> 22561.121 | K46: =SUM(K41:K45) -> 24225.449 | L46: =SUM(L41:L45) -> 25500.012 | M46: =SUM(M41:M45) -> 28243.109 | N46: =SUM(N41:N45) -> 31151.725
...

Sheet Simplified Model
B1: NIKE, Inc. — Simplified Three-Statement Model | P1: Model Check | Q1: Target
B2: USD $mm; historical data linked to Full Historical Statements. Forecast columns are intentionally blank for you to complete. | P2: Historical BS check | Q2: 0
P3: Historical cash check | Q3: 0
B4: Fiscal Year Ended May 31 | E4: 2021 | F4: 2022 | G4: 2023 | H4: 2024 | I4: 2025 | J4: 2026 | K4: 2027 | L4: 2028 | M4: 2029 | N4: 2030
J5: Forecast | K5: Forecast | L5: Forecast | M5: Forecast | N5: Forecast
B6: Income Statement | C6: Income Statement | D6: Income Statement | E6: Income Statement | F6: Income Statement | G6: Income Statement | H6: Income Statement | I6: Income Statement | J6: Income Statement | K6: Income Statement | L6: Income Statement | M6: Income Statement | N6: Income Statement
B7: Revenue | E7: ='Full Historical Statements'!E22 -> 44538 | F7: ='Full Historical Statements'!F22 -> 46710 | G7: ='Full Historical Statements'!G22 -> 51217 | H7: ='Full Historical Statements'!H22 -> 51362 | I7: ='Full Historical Statements'!I22 -> 46309 | J7: ='Full Historical Statements'!J22 -> 46772.09 | K7: ='Full Historical Statements'!K22 -> 50046.136 | L7: ='Full Historical Statements'!L22 -> 54049.827 | ... N7: ='Full Historical Statements'!N22 -> 64216.6
B8: Cost of sales | E8: ='Full Historical Statements'!E23 -> 24576 | F8: ='Full Historical Statements'!F23 -> 25231 | G8: ='Full Historical Statements'!G23 -> 28925 | H8: ='Full Historical Statements'!H23 -> 28475 | I8: ='Full Historical Statements'!I23 -> 26519 | J8: ='Full Historical Statements'!J23 -> 27127.812 | K8: ='Full Historical Statements'!K23 -> 28025.836 | L8: ='Full Historical Statements'!L23 -> 29186.907 | ... N8: ='Full Historical Statements'!N23 -> 33392.632
B9: Gross profit | E9: ='Full Historical Statements'!E24 -> 19962 | F9: ='Full Historical Statements'!F24 -> 21479 | G9: ='Full Historical Statements'!G24 -> 22292 | H9: ='Full Historical Statements'!H24 -> 22887 | I9: ='Full Historical Statements'!I24 -> 19790 | J9: ='Full Historical Statements'!J24 -> 19644.278 | K9: ='Full Historical Statements'!K24 -> 22020.3 | L9: ='Full Historical Statements'!L24 -> 24862.921 | ... N9: ='Full Historical Statements'!N24 -> 30823.968
B10: Selling and administrative expense | E10: ='Full Historical Statements'!E27 -> 13025 | F10: ='Full Historical Statements'!F27 -> 14804 | G10: ='Full Historical Statements'!G27 -> 16377 | H10: ='Full Historical Statements'!H27 -> 16576 | I10: ='Full Historical Statements'!I27 -> 16088 | J10: ='Full Historical Statements'!J27 -> 16370.231 | K10: ='Full Historical Statements'!K27 -> 18016.609 | L10: ='Full Historical Statements'!L27 -> 19457.938 | ... N10: ='Full Historical Statements'!N27 -> 23117.976
B11: Income from operations | E11: ='Full Historical Statements'!E28 -> 6937 | F11: ='Full Historical Statements'!F28 -> 6675 | G11: ='Full Historical Statements'!G28 -> 5915 | H11: ='Full Historical Statements'!H28 -> 6311 | I11: ='Full Historical Statements'!I28 -> 3702 | J11: ='Full Historical Statements'!J28 -> 3274.0463 | K11: ='Full Historical Statements'!K28 -> 4003.6909 | L11: ='Full Historical Statements'!L28 -> 5404.9827 | ... N11: ='Full Historical Statements'!N28 -> 7705.992
B12: Interest expense (income), net | E12: ='Full Historical Statements'!E29 -> 262 | F12: ='Full Historical Statements'!F29 -> 205 | G12: ='Full Historical Statements'!G29 -> -6 | H12: ='Full Historical Statements'!H29 -> -161 | I12: ='Full Historical Statements'!I29 -> -107 | J12: ='Full Historical Statements'!J29 -> 140.16 | K12: ='Full Historical Statements'!K29 -> 140.14 | L12: ='Full Historical Statements'!L29 -> 140.14 | ... N12: ='Full Historical Statements'!N29 -> 130.36
B13: Other (income) expense, net | E13: ='Full Historical Statements'!E30 -> 14 | F13: ='Full Historical Statements'!F30 -> -181 | G13: ='Full Historical Statements'!G30 -> -280 | H13: ='Full Historical Statements'!H30 -> -228 | I13: ='Full Historical Statements'!I30 -> -76 | J13: ='Full Historical Statements'!J30 -> -76 | K13: ='Full Historical Statements'!K30 -> -76 | L13: ='Full Historical Statements'!L30 -> -76 | ... N13: ='Full Historical Statements'!N30 -> -76
B14: Income before income taxes | E14: ='Full Historical Statements'!E31 -> 6661 | F14: ='Full Historical Statements'!F31 -> 6651 | G14: ='Full Historical Statements'!G31 -> 6201 | H14: ='Full Historical Statements'!H31 -> 6700 | I14: ='Full Historical Statements'!I31 -> 3885 | J14: ='Full Historical Statements'!J31 -> 3209.8863 | K14: ='Full Historical Statements'!K31 -> 3939.5509 | L14: ='Full Historical Statements'!L31 -> 5340.8427 | ... N14: ='Full Historical Statements'!N31 -> 7651.632
B15: Income tax expense | E15: ='Full Historical Statements'!E32 -> 934 | F15: ='Full Historical Statements'!F32 -> 605 | G15: ='Full Historical Statements'!G32 -> 1131 | H15: ='Full Historical Statements'!H32 -> 1000 | I15: ='Full Historical Statements'!I32 -> 666 | J15: ='Full Historical Statements'!J32 -> 481.48295 | K15: ='Full Historical Statements'!K32 -> 590.93264 | L15: ='Full Historical Statements'!L32 -> 801.12641 | ... N15: ='Full Historical Statements'!N32 -> 1147.7448
B16: Net income | E16: ='Full Historical Statements'!E80 -> 5727 | F16: ='Full Historical Statements'!F80 -> 6046 | G16: ='Full Historical Statements'!G80 -> 5070 | H16: ='Full Historical Statements'!H80 -> 5700 | I16: ='Full Historical Statements'!I80 -> 3219 | J16: ='Full Historical Statements'!J33 -> 2728.4034 | K16: ='Full Historical Statements'!K33 -> 3348.6183 | L16: ='Full Historical Statements'!L33 -> 4539.7163 | M16: ='Full Historical Statements'!M33 -> 5963.2408 | N16: ='Full Historical Statements'!N33 -> 6503.8872
B19: Balance Sheet — Assets | C19: Balance Sheet — Assets | D19: Balance Sheet — Assets | E19: Balance Sheet — Assets | F19: Balance Sheet — Assets | G19: Balance Sheet — Assets | H19: Balance Sheet — Assets | I19: Balance Sheet — Assets | J19: Balance Sheet — Assets | K19: Balance Sheet — Assets | L19: Balance Sheet — Assets | M19: Balance Sheet — Assets | N19: Balance Sheet — Assets
B20: Cash and equivalents | E20: ='Full Historical Statements'!E41 -> 9889 | F20: ='Full Historical Statements'!F41 -> 8574 | G20: ='Full Historical Statements'!G41 -> 7441 | H20: ='Full Historical Statements'!H41 -> 9860 | I20: ='Full Historical Statements'!I41 -> 7464 | J20: ='Full Historical Statements'!J41 -> 7380.033 | K20: ='Full Historical Statements'!K41 -> 9028.7919 | L20: ='Full Historical Statements'!L41 -> 9830.929 | ... N20: ='Full Historical Statements'!N41 -> 13586.53
B21: Short-term investments | E21: ='Full Historical Statements'!E42 -> 3587 | F21: ='Full Historical Statements'!F42 -> 4423 | G21: ='Full Historical Statements'!G42 -> 3234 | H21: ='Full Historical Statements'!H42 -> 1722 | I21: ='Full Historical Statements'!I42 -> 1687 | J21: ='Full Historical Statements'!J42 -> 2214.3333 | K21: ='Full Historical Statements'!K42 -> 1874.4444 | L21: ='Full Historical Statements'!L42 -> 1925.2593 | ... N21: ='Full Historical Statements'!N42 -> 1934.7942
B22: Accounts receivable, net | E22: ='Full Historical Statements'!E43 -> 4463 | F22: ='Full Historical Statements'!F43 -> 4667 | G22: ='Full Historical Statements'!G43 -> 4131 | H22: ='Full Historical Statements'!H43 -> 4427 | I22: ='Full Historical Statements'!I43 -> 4717 | J22: ='Full Historical Statements'!J43 -> 3972.4241 | K22: ='Full Historical Statements'!K43 -> 4250.4938 | L22: ='Full Historical Statements'!L43 -> 4590.5333 | ... N22: ='Full Historical Statements'!N43 -> 5454.0126
B23: Inventories | E23: ='Full Historical Statements'!E44 -> 6854 | F23: ='Full Historical Statements'!F44 -> 8420 | G23: ='Full Historical Statements'!G44 -> 8454 | H23: ='Full Historical Statements'!H44 -> 7519 | I23: ='Full Historical Statements'!I44 -> 7489 | J23: ='Full Historical Statements'!J44 -> 7060.6634 | K23: ='Full Historical Statements'!K44 -> 7140.8295 | L23: ='Full Historical Statements'!L44 -> 7196.7715 | ... N23: ='Full Historical Statements'!N44 -> 8233.7996
B24: Other current assets | E24: ='Full Historical Statements'!E45 -> 1498 | F24: ='Full Historical Statements'!F45 -> 2129 | G24: ='Full Historical Statements'!G45 -> 1942 | H24: ='Full Historical Statements'!H45 -> 1854 | I24: ='Full Historical Statements'!I45 -> 2005 | J24: ='Full Historical Statements'!J45 -> 1933.6667 | K24: ='Full Historical Statements'!K45 -> 1930.8889 | L24: ='Full Historical Statements'!L45 -> 1956.5185 | ... N24: ='Full Historical Statements'!N45 -> 1942.5885
B25: Total current assets | E25: =SUM(E20:E24) -> 26291 | F25: =SUM(F20:F24) -> 28213 | G25: =SUM(G20:G24) -> 25202 | H25: =SUM(H20:H24) -> 25382 | I25: =SUM(I20:I24) -> 23362 | J25: ='Full Historical Statements'!J46 -> 22561.121 | K25: ='Full Historical Statements'!K46 -> 24225.449 | L25: ='Full Historical Statements'!L46 -> 25500.012 | M25: ='Full Historical Statements'!M46 -> 28243.109 | N25: ='Full Historical Statements'!N46 -> 31151.725
B26: Property, plant and equipment, net | E26: ='Full Historical Statements'!E47 -> 4904 | F26: ='Full Historical Statements'!F47 -> 4791 | G26: ='Full Historical Statements'!G47 -> 5081 | H26: ='Full Historical Statements'!H47 -> 5000 | I26: ='Full Historical Statements'!I47 -> 4828 | J26: ='Full Historical Statements'!J47 -> 4456.8553 | K26: ='Full Historical Statements'!K47 -> 5256.4102 | L26: ='Full Historical Statements'!L47 -> 6053.1965 | ... N26: ='Full Historical Statements'!N47 -> 7727.0064
B27: Operating lease right-of-use assets, net | E27: ='Full Historical Statements'!E48 -> 3113 | F27: ='Full Historical Statements'!F48 -> 2926 | G27: ='Full Historical Statements'!G48 -> 2923 | H27: ='Full Historical Statements'!H48 -> 2718 | I27: ='Full Historical Statements'!I48 -> 2712 | J27: ='Full Historical Statements'!J48 -> 2784.3333 | K27: ='Full Historical Statements'!K48 -> 2738.1111 | L27: ='Full Historical Statements'!L48 -> 2744.8148 | ... N27: ='Full Historical Statements'!N48 -> 2746.2263
B28: Intangible assets and goodwill | E28: ='Full Historical Statements'!E49+'Full Historical Statements'!E50 -> 511 | F28: ='Full Historical Statements'!F49+'Full Historical Statements'!F50 -> 570 | G28: ='Full Historical Statements'!G49+'Full Historical Statements'!G50 -> 555 | H28: ='Full Historical Statements'!H49+'Full Historical Statements'!H50 -> 499 | I28: ='Full Historical Statements'!I49+'Full Historical Statements'!I50 -> 499 | J28: ='Full Historical Statements'!J49 -> 300 | K28: ='Full Historical Statements'!K49 -> 300 | L28: ='Full Historical Statements'!L49 -> 300 | M28: ='Full Historical Statements'!M49 -> 300 | N28: ='Full Historical Statements'!N49 -> 300
B29: Other non-current assets | E29: ='Full Historical Statements'!E51 -> 2921 | F29: ='Full Historical Statements'!F51 -> 3821 | G29: ='Full Historical Statements'!G51 -> 3770 | H29: ='Full Historical Statements'!H51 -> 4511 | I29: ='Full Historical Statements'!I51 -> 5178 | J29: ='Full Historical Statements'!J50+'Full Historical Statements'!J51 -> 4826.3333 | K29: ='Full Historical Statements'!K50+'Full Historical Statements'!K51 -> 4965.1111 | L29: ='Full Historical Statements'!L50+'Full Historical Statements'!L51 -> 5036.4815 | M29: ='Full Historical Statements'!M50+'Full Historical Statements'!M51 -> 4909.3086 | N29: ='Full Historical Statements'!N50+'Full Historical Statements'!N51 -> 4970.3004
B30: Total assets | E30: =SUM(E25:E29) -> 37740 | F30: =SUM(F25:F29) -> 40321 | G30: =SUM(G25:G29) -> 37531 | H30: =SUM(H25:H29) -> 38110 | I30: =SUM(I25:I29) -> 36579 | J30: =SUM(J25:J29) -> 34928.643 | K30: =SUM(K25:K29) -> 37485.081 | L30: =SUM(L25:L29) -> 39634.504 | ... N30: =SUM(N25:N29) -> 46895.258
B33: Balance Sheet — Liabilities | C33: Balance Sheet — Liabilities | D33: Balance Sheet — Liabilities | E33: Balance Sheet — Liabilities | F33: Balance Sheet — Liabilities | G33: Balance Sheet — Liabilities | H33: Balance Sheet — Liabilities | I33: Balance Sheet — Liabilities | J33: Balance Sheet — Liabilities | K33: Balance Sheet — Liabilities | L33: Balance Sheet — Liabilities | M33: Balance Sheet — Liabilities | N33: Balance Sheet — Liabilities
B34: Accounts payable | E34: ='Full Historical Statements'!E58 -> 2836 | F34: ='Full Historical Statements'!F58 -> 3358 | G34: ='Full Historical Statements'!G58 -> 2862 | H34: ='Full Historical Statements'!H58 -> 2851 | I34: ='Full Historical Statements'!I58 -> 3479 | J34: ='Full Historical Statements'!J58 -> 2972.9109 | K34: ='Full Historical Statements'!K58 -> 3071.3245 | L34: ='Full Historical Statements'!L58 -> 3198.5651 | ... N34: ='Full Historical Statements'!N58 -> 3659.4665
B35: Other current liabilities | E35: ='Full Historical Statements'!E56+'Full Historical Statements'!E57+'Full Historical Statements'!E59+'Full Historical Statements'!E60+'Full Historical Statements'!E61 -> 6838 | F35: ='Full Historical Statements'!F56+'Full Historical Statements'!F57+'Full Historical Statements'!F59+'Full Historical Statements'!F60+'Full Historical Statements'!F61 -> 7372 | G35: ='Full Historical Statements'!G56+'Full Historical Statements'!G57+'Full Historical Statements'!G59+'Full Historical Statements'!G60+'Full Historical Statements'!G61 -> 6394 | H35: ='Full Historical Statements'!H56+'Full Historical Statements'!H57+'Full Historical Statements'!H59+'Full Historical Statements'!H60+'Full Historical Statements'!H61 -> 7742 | I35: ='Full Historical Statements'!I56+'Full Historical Statements'!I57+'Full Historical Statements'!I59+'Full Historical Statements'!I60+'Full Historical Statements'!I61 -> 7087 | J35: ='Full Historical Statements'!J56+'Full Historical Statements'!J57+'Full Historical Statements'!J59+'Full Historical Statements'!J60+'Full Historical Statements'!J61 -> 7740.3333 | K35: ='Full Historical Statements'!K56+'Full Historical Statements'!K57+'Full Historical Statements'!K59+'Full Historical Statements'!K60+'Full Historical Statements'!K61 -> 7856.1111 | L35: ='Full Historical Statements'!L56+'Full Historical Statements'!L57+'Full Historical Statements'!L59+'Full Historical Statements'!L60+'Full Historical Statements'!L61 -> 6894.4815 | ... N35: ='Full Historical Statements'!N56+'Full Historical Statements'!N57+'Full Historical Statements'!N59+'Full Historical Statements'!N60+'Full Historical Statements'!N61 -> 8360.3004
B36: Total current liabilities | E36: =SUM(E34:E35) -> 9674 | F36: =SUM(F34:F35) -> 10730 | G36: =SUM(G34:G35) -> 9256 | H36: =SUM(H34:H35) -> 10593 | I36: =SUM(I34:I35) -> 10566 | J36: =SUM(J34:J35) -> 10713.244 | K36: =SUM(K34:K35) -> 10927.436 | L36: =SUM(L34:L35) -> 10093.047 | ... N36: =SUM(N34:N35) -> 12019.767
B37: Long-term debt | E37: ='Full Historical Statements'!E63 -> 9413 | F37: ='Full Historical Statements'!F63 -> 8920 | G37: ='Full Historical Statements'!G63 -> 8927 | H37: ='Full Historical Statements'!H63 -> 7903 | I37: ='Full Historical Statements'!I63 -> 7961 | J37: ='Full Historical Statements'!J63 -> 7008 | K37: ='Full Historical Statements'!K63 -> 7007 | L37: ='Full Historical Statements'!L63 -> 7007 | ... N37: ='Full Historical Statements'!N63 -> 6518
B38: Other non-current liabilities | E38: ='Full Historical Statements'!E64+'Full Historical Statements'!E65 -> 5886 | F38: ='Full Historical Statements'!F64+'Full Historical Statements'!F65 -> 5390 | G38: ='Full Historical Statements'!G64+'Full Historical Statements'!G65 -> 5344 | H38: ='Full Historical Statements'!H64+'Full Historical Statements'!H65 -> 5184 | I38: ='Full Historical Statements'!I64+'Full Historical Statements'!I65 -> 4839 | J38: ='Full Historical Statements'!J64+'Full Historical Statements'!J65 -> 5122.3333 | K38: ='Full Historical Statements'!K64+'Full Historical Statements'!K65 -> 5048.4444 | L38: ='Full Historical Statements'!L64+'Full Historical Statements'!L65 -> 5003.2593 | ... N38: ='Full Historical Statements'!N64+'Full Historical Statements'!N65 -> 5036.572
B39: Total liabilities | E39: =E36+E37+E38 -> 24973 | F39: =F36+F37+F38 -> 25040 | G39: =G36+G37+G38 -> 23527 | H39: =H36+H37+H38 -> 23680 | I39: =I36+I37+I38 -> 23366 | J39: =J36+J37+J38 -> 22843.578 | K39: =K36+K37+K38 -> 22982.88 | L39: =L36+L37+L38 -> 22103.306 | ... N39: =N36+N37+N38 -> 23574.339
B42: Balance Sheet — Shareholders' Equity | C42: Balance Sheet — Shareholders' Equity | D42: Balance Sheet — Shareholders' Equity | E42: Balance Sheet — Shareholders' Equity | F42: Balance Sheet — Shareholders' Equity | G42: Balance Sheet — Shareholders' Equity | H42: Balance Sheet — Shareholders' Equity | I42: Balance Sheet — Shareholders' Equity | J42: Balance Sheet — Shareholders' Equity | K42: Balance Sheet — Shareholders' Equity | L42: Balance Sheet — Shareholders' Equity | M42: Balance Sheet — Shareholders' Equity | N42: Balance Sheet — Shareholders' Equity
B43: Common stock | E43: ='Full Historical Statements'!E70 -> 3 | F43: ='Full Historical Statements'!F70 -> 3 | G43: ='Full Historical Statements'!G70 -> 3 | H43: ='Full Historical Statements'!H70 -> 3 | I43: ='Full Historical Statements'!I70 -> 3 | J43: ='Full Historical Statements'!J70 -> 3 | K43: ='Full Historical Statements'!K70 -> 3 | L43: ='Full Historical Statements'!L70 -> 3 | ... N43: ='Full Historical Statements'!N70 -> 3
B44: Capital in excess of stated value | E44: ='Full Historical Statements'!E71 -> 9965 | F44: ='Full Historical Statements'!F71 -> 11484 | G44: ='Full Historical Statements'!G71 -> 12412 | H44: ='Full Historical Statements'!H71 -> 13409 | I44: ='Full Historical Statements'!I71 -> 14195 | J44: ='Full Historical Statements'!J71 -> 15046.7 | K44: ='Full Historical Statements'!K71 -> 16099.969 | L44: ='Full Historical Statements'!L71 -> 17226.967 | ... N44: ='Full Historical Statements'!N71 -> 20580.179
B45: Accumulated other comprehensive income (loss) | E45: ='Full Historical Statements'!E72 -> -380 | F45: ='Full Historical Statements'!F72 -> 318 | G45: ='Full Historical Statements'!G72 -> 231 | H45: ='Full Historical Statements'!H72 -> 53 | I45: ='Full Historical Statements'!I72 -> -258 | J45: ='Full Historical Statements'!J72 -> -258 | K45: ='Full Historical Statements'!K72 -> -258 | L45: ='Full Historical Statements'!L72 -> -258 | ... N45: ='Full Historical Statements'!N72 -> -258
B46: Retained earnings (deficit) | E46: ='Full Historical Statements'!E73 -> 3179 | F46: ='Full Historical Statements'!F73 -> 3476 | G46: ='Full Historical Statements'!G73 -> 1358 | H46: ='Full Historical Statements'!H73 -> 965 | I46: ='Full Historical Statements'!I73 -> -727 | J46: ='Full Historical Statements'!J73 -> 2001.4034 | K46: ='Full Historical Statements'!K73 -> 5350.0216 | L46: ='Full Historical Statements'!L73 -> 9889.7379 | ... N46: ='Full Historical Statements'!N73 -> 22356.866
...

Sheet DCF
F5: Year -2 | G5: Year -2 | H5: Year 0 | I5: Year 1 | J5: Year 2 | K5: Year 3 | L5: Year 4 | M5: Year 5 | N5: Term
B7: Revenue Growth | G7: =G13/F13-1 -> 0.0028310912 | H7: =H13/G13-1 -> -0.098380125 | I7: =I13/H13-1 -> 0.01 | J7: =J13/I13-1 -> 0.07 | K7: =K13/J13-1 -> 0.08 | L7: =L13/K13-1 -> 0.09 | M7: =M13/L13-1 -> 0.09 | N7: 0.1
B8: COGS | C8: (% of Revenue) | F8: =-F14/F13 -> 0.56475389 | G8: =-G14/G13 -> 0.55439819 | H8: =-H14/H13 -> 0.57265326 | I8: =-I14/I13 -> 0.58 | J8: =-J14/J13 -> 0.56 | K8: =-K14/K13 -> 0.54 | L8: =-L14/L13 -> 0.52 | M8: =-M14/M13 -> 0.52 | N8: 0.01
B9: SG&A | C9: (% of Revenue) | F9: =F17/F13 -> 0.31975711 | G9: =G17/G13 -> 0.32272887 | H9: =H17/H13 -> 0.34740547 | I9: =I17/I13 -> 0.35 | J9: =J17/J13 -> 0.36 | K9: =K17/K13 -> 0.36 | L9: =L17/L13 -> 0.36 | M9: =M17/M13 -> 0.36 | N9: 0.35
B11: Depreciation Growth | G11: =G20/F20-1 -> 0.13229018 | H11: =H20/G20-1 -> -0.02638191 | I11: =I20/H20-1 -> -0.2899259 | J11: =J20/I20-1 -> 0.27534009 | K11: =K20/J20-1 -> 0.17508446 | L11: =L20/K20-1 -> 0.1427119 | M11: =M20/L20-1 -> 0.1435786 | N11: 0.14
B13: Revenue | F13: ='Simplified Model'!G7 -> 51217 | G13: ='Simplified Model'!H7 -> 51362 | H13: ='Simplified Model'!I7 -> 46309 | I13: ='Simplified Model'!J7 -> 46772.09 | J13: ='Simplified Model'!K7 -> 50046.136 | K13: ='Simplified Model'!L7 -> 54049.827 | L13: ='Simplified Model'!M7 -> 58914.312 | M13: ='Simplified Model'!N7 -> 64216.6 | N13: =M13*(1+N7) -> 70638.26
B14: COGS | F14: =-'Simplified Model'!G8 -> -28925 | G14: =-'Simplified Model'!H8 -> -28475 | H14: =-'Simplified Model'!I8 -> -26519 | I14: =-'Simplified Model'!J8 -> -27127.812 | J14: =-'Simplified Model'!K8 -> -28025.836 | K14: =-'Simplified Model'!L8 -> -29186.907 | L14: =-'Simplified Model'!M8 -> -30635.442 | M14: =-'Simplified Model'!N8 -> -33392.632 | N14: =M14*(1+N8) -> -33726.558
B15: Gross Profit | F15: =F13+F14 -> 22292 | G15: =G13+G14 -> 22887 | H15: =H13+H14 -> 19790 | I15: =I13+I14 -> 19644.278 | J15: =J13+J14 -> 22020.3 | K15: =K13+K14 -> 24862.921 | L15: =L13+L14 -> 28278.87 | M15: =M13+M14 -> 30823.968 | N15: =N13+N14 -> 36911.702
B17: SG&A | F17: ='Simplified Model'!G10 -> 16377 | G17: ='Simplified Model'!H10 -> 16576 | H17: ='Simplified Model'!I10 -> 16088 | I17: ='Simplified Model'!J10 -> 16370.231 | J17: ='Simplified Model'!K10 -> 18016.609 | K17: ='Simplified Model'!L10 -> 19457.938 | L17: ='Simplified Model'!M10 -> 21209.152 | M17: ='Simplified Model'!N10 -> 23117.976 | N17: =N13*N9 -> 24723.391
B18: EBITDA | F18: =F21-F20 -> 6618 | G18: =G21-G20 -> 7107 | H18: =H21-H20 -> 4477 | I18: =I21-I20 -> 3824.3537 | J18: =J21-J20 -> 4705.52 | K18: =K21-K20 -> 6229.6912 | L18: =L21-L20 -> 8012.1216 | M18: =M21-M20 -> 8783.7053 | N18: =N21-N20 -> 13416.904
B20: Depreciation | F20: =-'Simplified Model'!G54 -> -703 | G20: =-'Simplified Model'!H54 -> -796 | H20: =-'Simplified Model'!I54 -> -775 | I20: =-'Simplified Model'!J54 -> -550.30743 | J20: =-'Simplified Model'!K54 -> -701.82913 | K20: =-'Simplified Model'!L54 -> -824.7085 | L20: =-'Simplified Model'!M54 -> -942.40422 | M20: =-'Simplified Model'!N54 -> -1077.7133 | N20: =M20*(1+N11) -> -1228.5932
B21: Operating Profit | F21: =F15-F17 -> 5915 | G21: =G15-G17 -> 6311 | H21: =H15-H17 -> 3702 | I21: =I15-I17 -> 3274.0463 | J21: =J15-J17 -> 4003.6909 | K21: =K15-K17 -> 5404.9827 | L21: =L15-L17 -> 7069.7174 | M21: =M15-M17 -> 7705.992 | N21: =N15-N17 -> 12188.311
B23: Tax Rate | F23: ='Full Historical Statements'!G11 -> 0.18238994 | G23: ='Full Historical Statements'!H11 -> 0.14925373 | H23: ='Full Historical Statements'!I11 -> 0.17142857 | I23: ='Full Historical Statements'!J11 -> 0.15 | J23: ='Full Historical Statements'!K11 -> 0.15 | K23: ='Full Historical Statements'!L11 -> 0.15 | L23: ='Full Historical Statements'!M11 -> 0.15 | M23: ='Full Historical Statements'!N11 -> 0.15 | N23: 0.15
B24: Current Tax | F24: ='Simplified Model'!G15 -> 1131 | G24: ='Simplified Model'!H15 -> 1000 | H24: ='Simplified Model'!I15 -> 666 | I24: ='Simplified Model'!J15 -> 481.48295 | J24: ='Simplified Model'!K15 -> 590.93264 | K24: ='Simplified Model'!L15 -> 801.12641 | L24: ='Simplified Model'!M15 -> 1052.3366 | M24: ='Simplified Model'!N15 -> 1147.7448 | N24: =N21*N23 -> 1828.2466
B29: UNLEVERED FREE CASH FLOW
F32: Year -2 | G32: Year -2 | H32: Year 0 | I32: Year 1 | J32: Year 2 | K32: Year 3 | L32: Year 4 | M32: Year 5 | N32: Term
B33: Unlevered Free Cash Flow
B34: EBIT | F34: =F21 -> 5915 | G34: =G21 -> 6311 | H34: =H21 -> 3702 | I34: =I21 -> 3274.0463 | J34: =J21 -> 4003.6909 | K34: =K21 -> 5404.9827 | L34: =L21 -> 7069.7174 | M34: =M21 -> 7705.992 | N34: =N21 -> 12188.311
B35: Current Taxes | F35: =F24 -> 1131 | G35: =G24 -> 1000 | H35: =H24 -> 666 | I35: =I24 -> 481.48295 | J35: =J24 -> 590.93264 | K35: =K24 -> 801.12641 | L35: =L24 -> 1052.3366 | M35: =M24 -> 1147.7448 | N35: =N24 -> 1828.2466
B36: NOPAT | F36: =F34-F35 -> 4784 | G36: =G34-G35 -> 5311 | H36: =H34-H35 -> 3036 | I36: =I34-I35 -> 2792.5634 | J36: =J34-J35 -> 3412.7583 | K36: =K34-K35 -> 4603.8563 | L36: =L34-L35 -> 6017.3808 | M36: =M34-M35 -> 6558.2472 | N36: =N34-N35 -> 10360.064
B37: D&A | F37: =-F20 -> 703 | G37: =-G20 -> 796 | H37: =-H20 -> 775 | I37: =-I20 -> 550.30743 | J37: =-J20 -> 701.82913 | K37: =-K20 -> 824.7085 | L37: =-L20 -> 942.40422 | M37: =-M20 -> 1077.7133 | N37: =-N20 -> 1228.5932
B38: Capital Expenditure | F38: ='Simplified Model'!G58 -> -969 | G38: ='Simplified Model'!H58 -> -812 | H38: ='Simplified Model'!I58 -> -430 | I38: ='Simplified Model'!J58 -> -1403.1627 | J38: ='Simplified Model'!K58 -> -1501.3841 | K38: ='Simplified Model'!L58 -> -1621.4948 | L38: ='Simplified Model'!M58 -> -1767.4293 | M38: ='Simplified Model'!N58 -> -1926.498 | N38: -1800
B39: Cash from Working Capital | F39: ='Simplified Model'!G56 -> -513 | G39: ='Simplified Model'!H56 -> 716 | H39: ='Simplified Model'!I56 -> -787 | I39: ='Simplified Model'!J56 -> -1750.3349 | J39: ='Simplified Model'!K56 -> 453.87159 | K39: ='Simplified Model'!L56 -> 548.8517 | L39: ='Simplified Model'!M56 -> 912.90421 | M39: ='Simplified Model'!N56 -> 1434.5746 | N39: 1500
B40: Unlevered Free Cash Flow | F40: =SUM(F36:F39) -> 4005 | G40: =SUM(G36:G39) -> 6011 | H40: =SUM(H36:H39) -> 2594 | I40: =SUM(I36:I39) -> 189.37321 | J40: =SUM(J36:J39) -> 3067.0749 | K40: =SUM(K36:K39) -> 4355.9217 | L40: =SUM(L36:L39) -> 6105.2599 | M40: =SUM(M36:M39) -> 7144.037 | N40: =SUM(N36:N39) -> 11288.657
B44: DISCOUNTED CASH FLOW SCHEDULE
I46: Year 1 | J46: Year 2 | K46: Year 3 | L46: Year 4 | M46: Year 5 | N46: Term
B48: Unlevered Free Cash Flow | I48: =I40 -> 189.37321 | J48: =J40 -> 3067.0749 | K48: =K40 -> 4355.9217 | L48: =L40 -> 6105.2599 | M48: =M40 -> 7144.037 | N48: =N40 -> 11288.657
B49: EBITDA | N49: =N48+N18 -> 24705.561
B52: UNDISCOUNTED CASH FLOW
B53: Discrete Forecast | I53: =I48 -> 189.37321 | J53: =J48 -> 3067.0749 | K53: =K48 -> 4355.9217 | L53: =L48 -> 6105.2599 | M53: =M48 -> 7144.037 | N53: =N48 -> 11288.657
B54: Terminal Value | I54: 0 | J54: 0 | K54: 0 | L54: 0 | M54: 0 | N54: =N53*D61 -> 135463.89
B55: Total Cash Flow | I55: =SUM(I53:I54) -> 189.37321 | J55: =SUM(J53:J54) -> 3067.0749 | K55: =SUM(K53:K54) -> 4355.9217 | L55: =SUM(L53:L54) -> 6105.2599 | M55: =SUM(M53:M54) -> 7144.037 | N55: =SUM(N53:N54) -> 146752.54
B59: ASSUMPTIONS | G59: ENTERPRISE VALUE | K59: EQUITY VALUE PER SHARE
B60: First Year of Forecast | D60: 2026 | G60: PV of Discrete | I60: =NPV(D62,I53,J53,K53,L53,M53) -> 14802.199 | K60: Equity Value | N60: =I75 -> 87783.543
B61: Terminal Multiple | D61: 12 | G61: PV of Terminal | I61: =NPV(D62,I54:N54) -> 78317.344 | K61: Shares Outstanding | N61: =D80 -> 1480
B62: Discount Rate | D62: =(D82*D69)+(D88*D75) -> 0.095622468 | G62: Enterprise Value | I62: =I60+I61 -> 93119.543 | K62: Equity Value | N62: =N60/N61 -> 59.313205
B65: COST OF EQUITY | G65: NET DEBT
B66: Risk-free rate (US 10y) | D66: 0.0462 | G66: Short-term debt | I66: ='Simplified Model'!I38 -> 4839
B67: Beta | D67: 1.13 | G67: Long-term debt | I67: ='Simplified Model'!I37 -> 7961
B68: Market risk premium | D68: 0.05 | G68: Cash and cash equivalent | I68: ='Simplified Model'!I20 -> 7464
...

Sheet Source Notes
A1: Source Notes
A3: Model sheet | B3: Source | C3: Financial statement coverage | D3: URL
A4: Full Historical Statements | B4: NIKE FY2022 Form 10-K | C4: FY2021 balance sheet; FY2021–FY2022 income statement and cash flow data | D4: https://www.sec.gov/Archives/edgar/data/320187/000032018722000038/nke-20220531.htm
A5: Full Historical Statements | B5: NIKE FY2023 Form 10-K | C5: FY2021–FY2023 income statement and cash flow data; FY2022–FY2023 balance sheets | D5: https://www.sec.gov/Archives/edgar/data/320187/000032018723000039/nke-20230531.htm
A6: Full Historical Statements | B6: NIKE FY2025 Form 10-K | C6: FY2023–FY2025 income statement and cash flow data; FY2024–FY2025 balance sheets | D6: https://www.sec.gov/Archives/edgar/data/320187/000032018725000047/nke-20250531.htm
