Workbook

Sheet Summary
B1: Project Soft: Microsoft Valuation Model | 19th July 2026
B2: Ibrahim Diaby
B5: Valuation Summary | G5: Key Financial Metrics
B7: Current Share Price | E7: =DCF!D78 -> 393.82 | G7: Income Statement
I8: 2025A | J8: 2026E | K8: 2027E | L8: 2028E
B9: Instrinic Share Price | E9: =DCF!N60 -> 716.66094 | G9: Revenue | I9: ='Simplified Model'!G8 -> 281724 | J9: ='Simplified Model'!H8 -> 323982.6 | K9: ='Simplified Model'!I8 -> 372579.99 | L9: ='Simplified Model'!J8 -> 428466.99
G10: Revenue Growth (%) | I10: ='Simplified Model'!G9 -> 0.14932156 | J10: ='Simplified Model'!H9 -> 0.15 | K10: ='Simplified Model'!I9 -> 0.15 | L10: ='Simplified Model'!J9 -> 0.15
B11: Implied Premium | E11: =(E9-E7)/E7 -> 0.81976776 | G11: EBITDA | I11: ='Simplified Model'!G19 -> 128528 | J11: ='Simplified Model'!H19 -> 150651.91 | K11: ='Simplified Model'!I19 -> 172504.54 | L11: ='Simplified Model'!J19 -> 199237.15
G12: EBITDA Margin (%) | I12: ='Simplified Model'!G20 -> 0.45621956 | J12: ='Simplified Model'!H20 -> 0.465 | K12: ='Simplified Model'!I20 -> 0.463 | L12: ='Simplified Model'!J20 -> 0.465
B14: Ratios
E15: 2025
B16: Return on Invested Capital | E16: =Ratios!H22 -> 0.30214782
B18: Return on Equity | E18: =Ratios!H27 -> 0.29647227
B20: EV / Revenue | E20: =Ratios!H31 -> 10.410869
B22: P/E Ratio | E22: =Ratios!H32 -> 28.872434

Sheet Full Historical Statements
B2: Microsoft Corporation - Full Historical Statements
B3: USD in millions, except per-share amounts and share counts
E4: 2021A | F4: 2022A | G4: 2023A | H4: 2024A | I4: 2025A | J4: 2026E | K4: 2027E | L4: 2028E | M4: 2029E | N4: 2030E
B5: ASSUMPTIONS
B6: Revenue Growth (%) | F6: =F33/E33-1 -> 0.17956071 | G6: =G33/F33-1 -> 0.068820296 | H6: =H33/G33-1 -> 0.15669962 | I6: =I33/H33-1 -> 0.14932156 | J6: 0.15 | K6: 0.15 | L6: 0.15 | M6: 0.15 | N6: 0.15
B7: Product Revenue (% of Revenue) | E7: =E31/E33 -> 0.42283804 | F7: =F31/F33 -> 0.36683311 | G7: =G31/G33 -> 0.30530637 | H7: =H31/H33 -> 0.26424801 | I7: =I31/I33 -> 0.22698102 | J7: 0.23 | K7: 0.23 | L7: =AVERAGE(I7:K7) -> 0.22899367 | M7: =AVERAGE(J7:L7) -> 0.22966456 | N7: =AVERAGE(K7:M7) -> 0.22955274
B8: Service Revenue (% of Revenue) | E8: =E32/E33 -> 0.57716196 | F8: =F32/F33 -> 0.63316689 | G8: =G32/G33 -> 0.69469363 | H8: =H32/H33 -> 0.73575199 | I8: =I32/I33 -> 0.77301898 | J8: 0.77 | K8: 0.77 | L8: 0.77 | M8: 0.77 | N8: 0.77
B9: Cost of Goods (% of Revenue) | E9: =SUM(E34:E35)/SUM(E31:E32) -> 0.31074199 | F9: =SUM(F34:F35)/SUM(F31:F32) -> 0.31598326 | G9: =SUM(G34:G35)/SUM(G31:G32) -> 0.31079914 | H9: =SUM(H34:H35)/SUM(H31:H32) -> 0.30235556 | I9: =SUM(I34:I35)/SUM(I31:I32) -> 0.31176258 | J9: 0.31 | K9: 0.32 | L9: 0.33 | M9: 0.32 | N9: 0.3
B10: Product COG | E10: =E34/E33 -> 0.10838965 | F10: =F34/F33 -> 0.096151712 | G10: =G34/G33 -> 0.084014817 | H10: =H34/H33 -> 0.062303669 | I10: =I34/I33 -> 0.04792279 | J10: 0.05 | K10: 0.05 | L10: 0.05 | M10: 0.05 | N10: 0.05
B11: Service COG | E11: =E35/E33 -> 0.20235234 | F11: =F35/F33 -> 0.21983154 | G11: =G35/G33 -> 0.22678432 | H11: =H35/H33 -> 0.24005189 | I11: =I35/I33 -> 0.26383979 | J11: 0.27 | K11: 0.28 | L11: 0.27 | M11: 0.26 | N11: 0.25
B12: Operating Expenses (% of Revenue) | E12: =SUM(E38:E40)/E33 -> 0.27330922 | F12: =SUM(F38:F40)/F33 -> 0.26346396 | G12: =SUM(G38:G40)/G33 -> 0.27147205 | H12: =SUM(H38:H40)/H33 -> 0.25120144 | I12: =SUM(I38:I40)/I33 -> 0.23201786 | J12: =SUM(J38:J40)/J33 -> 0.225 | K12: =SUM(K38:K40)/K33 -> 0.217 | L12: =SUM(L38:L40)/L33 -> 0.205 | ... N12: =SUM(N38:N40)/N33 -> 0.2
B13: Research and Development | E13: =E38/E33 -> 0.12324497 | F13: =F38/F33 -> 0.12362939 | G13: =G38/G33 -> 0.12832975 | H13: =H38/H33 -> 0.12038903 | I13: =I38/I33 -> 0.11531854 | J13: 0.11 | K13: 0.107 | L13: 0.1 | M13: 0.1 | N13: 0.1
B14: Sales and Marketing | E14: =E39/E33 -> 0.11968136 | F14: =F39/F33 -> 0.11007717 | G14: =G39/G33 -> 0.10739683 | H14: =H39/H33 -> 0.099770726 | I14: =I39/I33 -> 0.091060754 | J14: 0.085 | K14: 0.08 | L14: 0.075 | M14: 0.07 | N14: 0.07
B15: G&A | E15: =E40/E33 -> 0.030382895 | F15: =F40/F33 -> 0.029757402 | G15: =G40/G33 -> 0.035745464 | H15: =H40/H33 -> 0.031041685 | I15: =I40/I33 -> 0.025638568 | J15: 0.03 | K15: 0.03 | L15: 0.03 | M15: 0.03 | N15: 0.03
B16: Interest (% of Debt) | E16: =E154/E76 -> 0.046850661 | F16: =F154/F76 -> 0.043863752 | G16: =G154/G76 -> 0.046868302 | H16: =H154/H76 -> 0.068754685 | I16: =I154/I76 -> 0.059399283 | J16: 0.05 | K16: 0.05 | L16: 0.05 | M16: 0.05 | N16: 0.05
B17: Taxes (% of EBT) | E17: =E44/E43 -> 0.13826615 | F17: =F44/F43 -> 0.13113383 | G17: =G44/G43 -> 0.18978625 | H17: =H44/H43 -> 0.18231327 | I17: =I44/I43 -> 0.17629644 | J17: =AVERAGE(G17:I17) -> 0.18279865 | K17: =AVERAGE(H17:J17) -> 0.18046945 | L17: =AVERAGE(I17:K17) -> 0.17985485 | M17: =AVERAGE(J17:L17) -> 0.18104098 | N17: =AVERAGE(K17:M17) -> 0.1804551
B18: Other Income (% of EBT) | E18: =E42/E41 -> 0.016963213 | F18: =F42/F41 -> 0.0039936198 | G18: =G42/G41 -> 0.0089016414 | H18: =H42/H41 -> -0.015041167 | I18: =I42/I41 -> -0.038131769 | J18: 0.02 | K18: 0.02 | L18: 0.02 | M18: 0.02 | N18: 0.02
B19: D&A (% of PPE) | E19: =E93/E60 -> 0.19569622 | F19: =F93/F60 -> 0.19436006 | G19: =G93/G60 -> 0.14492738 | H19: =H93/H60 -> 0.16436932 | I19: =I93/I60 -> 0.16662764 | J19: 0.19 | K19: 0.2 | L19: 0.235 | M19: 0.26 | N19: 0.27
B20: Accounts Receivable (Days) | E20: =E56/E33*E25 -> 82.609675 | F20: =F56/F33*F25 -> 81.481137 | G20: =G56/G33*G25 -> 83.859661 | H20: =H56/H33*H25 -> 84.762934 | I20: =I56/I33*I25 -> 90.568517 | J20: 91 | K20: 90 | L20: 90 | M20: 90 | N20: 90
B21: Inventory (Days) | E21: =E57/(E34+E35)*E25 -> 18.420509 | F21: =F57/(F34+F35)*F25 -> 21.800958 | G21: =G57/(G34+G35)*G25 -> 13.854516 | H21: =H57/(H34+H35)*H25 -> 6.1363575 | I21: =I57/(I34+I35)*I25 -> 3.8980542 | J21: 3 | K21: 2 | L21: 2 | M21: 2 | N21: 2
B22: Accounts Payable (Days) | E22: =E68/(E34+E35)*E25 -> 105.95985 | F22: =F68/(F34+F35)*F25 -> 110.69433 | G22: =G68/(G34+G35)*G25 -> 100.27899 | H22: =H68/(H34+H35)*H25 -> 108.3269 | I22: =I68/(I34+I35)*I25 -> 115.21285 | J22: 115 | K22: 116 | L22: 117 | M22: 117 | N22: 117
B23: CAPEX | E23: =E118 -> -20622 | F23: =F118 -> -23886 | G23: =G118 -> -28107 | H23: =H118 -> -44477 | I23: =I118 -> -64551 | J23: -110000 | K23: -150000 | L23: -140000 | M23: -120000 | N23: -130000
B24: (% of Revenue) | E24: =-E23/E33 -> 0.12268574 | F24: =-F23/F33 -> 0.12047208 | G24: =-G23/G33 -> 0.13263337 | H24: =-H23/H33 -> 0.18144842 | I24: =-I23/I33 -> 0.22912851 | J24: =-J23/J33 -> 0.33952441 | K24: =-K23/K33 -> 0.40259811 | L24: =-L23/L33 -> 0.32674629 | ... N24: =-N23/N33 -> 0.22941949
B25: Days | E25: 365 | F25: 365 | G25: 365 | H25: 365 | I25: 365 | J25: 365 | K25: 365 | L25: 365 | M25: 365 | N25: 365
E28: 2021A | F28: 2022A | G28: 2023A | H28: 2024A | I28: 2025A | J28: 2026E | K28: 2027E | L28: 2028E | M28: 2029E | N28: 2030E
B30: Income Statement
B31: Product revenue | E31: 71074 | F31: 72732 | G31: 64699 | H31: 64773 | I31: 63946 | J31: =J33*J7 -> 74515.998 | K31: =K33*K7 -> 85693.398 | L31: =L33*L7 -> 98116.229 | M31: =M33*M7 -> 113164.23 | N31: =N33*N7 -> 130075.51
B32: Service and other revenue | E32: 97014 | F32: 125538 | G32: 147216 | H32: 180349 | I32: 217778 | J32: =J33*I8 -> 250444.7 | K32: =K33*K8 -> 286886.59 | L32: =L33*L8 -> 329919.58 | M32: =M33*M8 -> 379407.52 | N32: =N33*N8 -> 436318.65
B33: Total revenue | E33: =SUM(E31:E32) -> 168088 | F33: =SUM(F31:F32) -> 198270 | G33: =SUM(G31:G32) -> 211915 | H33: =SUM(H31:H32) -> 245122 | I33: =SUM(I31:I32) -> 281724 | J33: =I33*(1+J6) -> 323982.6 | K33: =J33*(1+K6) -> 372579.99 | L33: =K33*(1+L6) -> 428466.99 | M33: =L33*(1+M6) -> 492737.04 | N33: =M33*(1+N6) -> 566647.59
B34: Product cost of revenue | E34: 18219 | F34: 19064 | G34: 17804 | H34: 15272 | I34: 13501 | J34: =J33*J10 -> 16199.13 | K34: =K33*K10 -> 18628.999 | L34: =L33*L10 -> 21423.349 | M34: =M33*M10 -> 24636.852 | N34: =N33*N10 -> 28332.38
B35: Service and other cost of revenue | E35: 34013 | F35: 43586 | G35: 48059 | H35: 58842 | I35: 74330 | J35: =J33*J11 -> 87475.302 | K35: =K33*K11 -> 104322.4 | L35: =L33*L11 -> 115686.09 | M35: =M33*M11 -> 128111.63 | N35: =N33*N11 -> 141661.9
B36: Total cost of revenue | E36: =SUM(E34:E35) -> 52232 | F36: =SUM(F34:F35) -> 62650 | G36: =SUM(G34:G35) -> 65863 | H36: =SUM(H34:H35) -> 74114 | I36: =SUM(I34:I35) -> 87831 | J36: =J33*J9 -> 100434.61 | K36: =K33*K9 -> 119225.6 | L36: =L33*L9 -> 141394.11 | M36: =M33*M9 -> 157675.85 | N36: =N33*N9 -> 169994.28
B37: Gross margin | E37: =E33-E36 -> 115856 | F37: =F33-F36 -> 135620 | G37: =G33-G36 -> 146052 | H37: =H33-H36 -> 171008 | I37: =I33-I36 -> 193893 | J37: =J33-J36 -> 223547.99 | K37: =K33-K36 -> 253354.39 | L37: =L33-L36 -> 287072.88 | ... N37: =N33-N36 -> 396653.31
B38: Research and development | E38: 20716 | F38: 24512 | G38: 27195 | H38: 29510 | I38: 32488 | J38: =J33*J13 -> 35638.086 | K38: =K33*K13 -> 39866.059 | L38: =L33*L13 -> 42846.699 | M38: =M33*M13 -> 49273.704 | N38: =N33*N13 -> 56664.759
B39: Sales and marketing | E39: 20117 | F39: 21825 | G39: 22759 | H39: 24456 | I39: 25654 | J39: =J33*J14 -> 27538.521 | K39: =K33*K14 -> 29806.399 | L39: =L33*L14 -> 32135.024 | M39: =M33*M14 -> 34491.593 | N39: =N33*N14 -> 39665.331
B40: General and administrative | E40: 5107 | F40: 5900 | G40: 7575 | H40: 7609 | I40: 7223 | J40: =J33*J15 -> 9719.478 | K40: =K33*K15 -> 11177.4 | L40: =L33*L15 -> 12854.01 | M40: =M33*M15 -> 14782.111 | N40: =N33*N15 -> 16999.428
B41: Operating income | E41: =E37-SUM(E38:E40) -> 69916 | F41: =F37-SUM(F38:F40) -> 83383 | G41: =G37-SUM(G38:G40) -> 88523 | H41: =H37-SUM(H38:H40) -> 109433 | I41: =I37-SUM(I38:I40) -> 128528 | J41: =J37-SUM(J38:J40) -> 150651.91 | K41: =K37-SUM(K38:K40) -> 172504.54 | L41: =L37-SUM(L38:L40) -> 199237.15 | ... N41: =N37-SUM(N38:N40) -> 283323.8
B42: Other income / (expense), net | E42: 1186 | F42: 333 | G42: 788 | H42: -1646 | I42: -4901 | J42: =J41*J18 -> 3013.0382 | K42: =K41*K18 -> 3450.0907 | L42: =L41*L18 -> 3984.743 | M42: =M41*M18 -> 4730.2756 | N42: =N41*N18 -> 5666.4759
B43: Income before income taxes | E43: =E41+E42 -> 71102 | F43: =F41+F42 -> 83716 | G43: =G41+G42 -> 89311 | H43: =H41+H42 -> 107787 | I43: =I41+I42 -> 123627 | J43: =J41+J42 -> 153664.95 | K43: =K41+K42 -> 175954.63 | L43: =L41+L42 -> 203221.89 | ... N43: =N41+N42 -> 288990.27
B44: Provision for income taxes | E44: 9831 | F44: 10978 | G44: 16950 | H44: 19651 | I44: 21795 | J44: =J43*J17 -> 28089.745 | K44: =K43*K17 -> 31754.435 | L44: =L43*L17 -> 36550.443 | M44: =M43*M17 -> 43675.061 | N44: =N43*N17 -> 52149.767
...

Sheet Simplified Model
B2: Microsoft Corporation - Simplified Model
B3: USD in millions, except EPS/shares; FY2026-FY2030 forecast area left blank
C5: 2021A | D5: 2022A | E5: 2023A | F5: 2024A | G5: 2025A | H5: 2026F | I5: 2027F | J5: 2028F | K5: 2029F | L5: 2030F
B7: Income Statement
B8: Revenue | C8: ='Full Historical Statements'!E33 -> 168088 | D8: ='Full Historical Statements'!F33 -> 198270 | E8: ='Full Historical Statements'!G33 -> 211915 | F8: ='Full Historical Statements'!H33 -> 245122 | G8: ='Full Historical Statements'!I33 -> 281724 | H8: ='Full Historical Statements'!J33 -> 323982.6 | I8: ='Full Historical Statements'!K33 -> 372579.99 | J8: ='Full Historical Statements'!L33 -> 428466.99 | ... L8: ='Full Historical Statements'!N33 -> 566647.59
B9: Revenue Growth (%) | D9: =IFERROR(D8/C8-1,"") -> 0.17956071 | E9: =IFERROR(E8/D8-1,"") -> 0.068820296 | F9: =IFERROR(F8/E8-1,"") -> 0.15669962 | G9: =IFERROR(G8/F8-1,"") -> 0.14932156 | H9: ='Full Historical Statements'!J6 -> 0.15 | I9: ='Full Historical Statements'!K6 -> 0.15 | J9: ='Full Historical Statements'!L6 -> 0.15 | K9: ='Full Historical Statements'!M6 -> 0.15 | L9: ='Full Historical Statements'!N6 -> 0.15
B10: Cost of Goods | C10: ='Full Historical Statements'!E36 -> 52232 | D10: ='Full Historical Statements'!F36 -> 62650 | E10: ='Full Historical Statements'!G36 -> 65863 | F10: ='Full Historical Statements'!H36 -> 74114 | G10: ='Full Historical Statements'!I36 -> 87831 | H10: ='Full Historical Statements'!J36 -> 100434.61 | I10: ='Full Historical Statements'!K36 -> 119225.6 | J10: ='Full Historical Statements'!L36 -> 141394.11 | ... L10: ='Full Historical Statements'!N36 -> 169994.28
B11: Gross Profit | C11: ='Full Historical Statements'!E37 -> 115856 | D11: ='Full Historical Statements'!F37 -> 135620 | E11: ='Full Historical Statements'!G37 -> 146052 | F11: ='Full Historical Statements'!H37 -> 171008 | G11: ='Full Historical Statements'!I37 -> 193893 | H11: ='Full Historical Statements'!J37 -> 223547.99 | I11: ='Full Historical Statements'!K37 -> 253354.39 | J11: ='Full Historical Statements'!L37 -> 287072.88 | ... L11: ='Full Historical Statements'!N37 -> 396653.31
B12: Gross Margin (%) | C12: =C11/C8 -> 0.68925801 | D12: =D11/D8 -> 0.68401674 | E12: =E11/E8 -> 0.68920086 | F12: =F11/F8 -> 0.69764444 | G12: =G11/G8 -> 0.68823742 | H12: ='Full Historical Statements'!J37/'Full Historical Statements'!J33 -> 0.69 | I12: ='Full Historical Statements'!K37/'Full Historical Statements'!K33 -> 0.68 | J12: ='Full Historical Statements'!L37/'Full Historical Statements'!L33 -> 0.67 | K12: ='Full Historical Statements'!M37/'Full Historical Statements'!M33 -> 0.68 | L12: ='Full Historical Statements'!N37/'Full Historical Statements'!N33 -> 0.7
B13: R&D | C13: ='Full Historical Statements'!E38 -> 20716 | D13: ='Full Historical Statements'!F38 -> 24512 | E13: ='Full Historical Statements'!G38 -> 27195 | F13: ='Full Historical Statements'!H38 -> 29510 | G13: ='Full Historical Statements'!I38 -> 32488 | H13: ='Full Historical Statements'!J38 -> 35638.086 | I13: ='Full Historical Statements'!K38 -> 39866.059 | J13: ='Full Historical Statements'!L38 -> 42846.699 | ... L13: ='Full Historical Statements'!N38 -> 56664.759
B14: R&D (% Revenue) | C14: =C13/C8 -> 0.12324497 | D14: =D13/D8 -> 0.12362939 | E14: =E13/E8 -> 0.12832975 | F14: =F13/F8 -> 0.12038903 | G14: =G13/G8 -> 0.11531854 | H14: ='Full Historical Statements'!J38/'Full Historical Statements'!J33 -> 0.11 | I14: ='Full Historical Statements'!K38/'Full Historical Statements'!K33 -> 0.107 | J14: ='Full Historical Statements'!L38/'Full Historical Statements'!L33 -> 0.1 | K14: ='Full Historical Statements'!M38/'Full Historical Statements'!M33 -> 0.1 | L14: ='Full Historical Statements'!N38/'Full Historical Statements'!N33 -> 0.1
B15: Sales & Marketing | C15: ='Full Historical Statements'!E39 -> 20117 | D15: ='Full Historical Statements'!F39 -> 21825 | E15: ='Full Historical Statements'!G39 -> 22759 | F15: ='Full Historical Statements'!H39 -> 24456 | G15: ='Full Historical Statements'!I39 -> 25654 | H15: ='Full Historical Statements'!J39 -> 27538.521 | I15: ='Full Historical Statements'!K39 -> 29806.399 | J15: ='Full Historical Statements'!L39 -> 32135.024 | ... L15: ='Full Historical Statements'!N39 -> 39665.331
B16: Sales & Marketing (% Revenue) | C16: =C15/C8 -> 0.11968136 | D16: =D15/D8 -> 0.11007717 | E16: =E15/E8 -> 0.10739683 | F16: =F15/F8 -> 0.099770726 | G16: =G15/G8 -> 0.091060754 | H16: ='Full Historical Statements'!J39/'Full Historical Statements'!J33 -> 0.085 | I16: ='Full Historical Statements'!K39/'Full Historical Statements'!K33 -> 0.08 | J16: ='Full Historical Statements'!L39/'Full Historical Statements'!L33 -> 0.075 | K16: ='Full Historical Statements'!M39/'Full Historical Statements'!M33 -> 0.07 | L16: ='Full Historical Statements'!N39/'Full Historical Statements'!N33 -> 0.07
B17: G&A | C17: ='Full Historical Statements'!E40 -> 5107 | D17: ='Full Historical Statements'!F40 -> 5900 | E17: ='Full Historical Statements'!G40 -> 7575 | F17: ='Full Historical Statements'!H40 -> 7609 | G17: ='Full Historical Statements'!I40 -> 7223 | H17: ='Full Historical Statements'!J40 -> 9719.478 | I17: ='Full Historical Statements'!K40 -> 11177.4 | J17: ='Full Historical Statements'!L40 -> 12854.01 | ... L17: ='Full Historical Statements'!N40 -> 16999.428
B18: G&A (% Revenue) | C18: =C17/C8 -> 0.030382895 | D18: =D17/D8 -> 0.029757402 | E18: =E17/E8 -> 0.035745464 | F18: =F17/F8 -> 0.031041685 | G18: =G17/G8 -> 0.025638568 | H18: ='Full Historical Statements'!J40/'Full Historical Statements'!J33 -> 0.03 | I18: ='Full Historical Statements'!K40/'Full Historical Statements'!K33 -> 0.03 | J18: ='Full Historical Statements'!L40/'Full Historical Statements'!L33 -> 0.03 | K18: ='Full Historical Statements'!M40/'Full Historical Statements'!M33 -> 0.03 | L18: ='Full Historical Statements'!N40/'Full Historical Statements'!N33 -> 0.03
B19: Operating income | C19: ='Full Historical Statements'!E41 -> 69916 | D19: ='Full Historical Statements'!F41 -> 83383 | E19: ='Full Historical Statements'!G41 -> 88523 | F19: ='Full Historical Statements'!H41 -> 109433 | G19: ='Full Historical Statements'!I41 -> 128528 | H19: ='Full Historical Statements'!J41 -> 150651.91 | I19: ='Full Historical Statements'!K41 -> 172504.54 | J19: ='Full Historical Statements'!L41 -> 199237.15 | ... L19: ='Full Historical Statements'!N41 -> 283323.8
B20: Operating Margin | C20: =C19/C8 -> 0.41594879 | D20: =D19/D8 -> 0.42055278 | E20: =E19/E8 -> 0.41772881 | F20: =F19/F8 -> 0.446443 | G20: =G19/G8 -> 0.45621956 | H20: ='Full Historical Statements'!J41/'Full Historical Statements'!J33 -> 0.465 | I20: ='Full Historical Statements'!K41/'Full Historical Statements'!K33 -> 0.463 | J20: ='Full Historical Statements'!L41/'Full Historical Statements'!L33 -> 0.465 | K20: ='Full Historical Statements'!M41/'Full Historical Statements'!M33 -> 0.48 | L20: ='Full Historical Statements'!N41/'Full Historical Statements'!N33 -> 0.5
B21: Other income / (expense), net | C21: ='Full Historical Statements'!E42 -> 1186 | D21: ='Full Historical Statements'!F42 -> 333 | E21: ='Full Historical Statements'!G42 -> 788 | F21: ='Full Historical Statements'!H42 -> -1646 | G21: ='Full Historical Statements'!I42 -> -4901 | H21: ='Full Historical Statements'!J42 -> 3013.0382 | I21: ='Full Historical Statements'!K42 -> 3450.0907 | J21: ='Full Historical Statements'!L42 -> 3984.743 | ... L21: ='Full Historical Statements'!N42 -> 5666.4759
B22: Income before income taxes | C22: ='Full Historical Statements'!E43 -> 71102 | D22: ='Full Historical Statements'!F43 -> 83716 | E22: ='Full Historical Statements'!G43 -> 89311 | F22: ='Full Historical Statements'!H43 -> 107787 | G22: ='Full Historical Statements'!I43 -> 123627 | H22: ='Full Historical Statements'!J43 -> 153664.95 | I22: ='Full Historical Statements'!K43 -> 175954.63 | J22: ='Full Historical Statements'!L43 -> 203221.89 | ... L22: ='Full Historical Statements'!N43 -> 288990.27
B23: Provision for income taxes | C23: ='Full Historical Statements'!E44 -> 9831 | D23: ='Full Historical Statements'!F44 -> 10978 | E23: ='Full Historical Statements'!G44 -> 16950 | F23: ='Full Historical Statements'!H44 -> 19651 | G23: ='Full Historical Statements'!I44 -> 21795 | H23: ='Full Historical Statements'!J44 -> 28089.745 | I23: ='Full Historical Statements'!K44 -> 31754.435 | J23: ='Full Historical Statements'!L44 -> 36550.443 | ... L23: ='Full Historical Statements'!N44 -> 52149.767
B24: Tax Rate | C24: =C23/C22 -> 0.13826615 | D24: =D23/D22 -> 0.13113383 | E24: =E23/E22 -> 0.18978625 | F24: =F23/F22 -> 0.18231327 | G24: =G23/G22 -> 0.17629644 | H24: ='Full Historical Statements'!J44/'Full Historical Statements'!J43 -> 0.18279865 | I24: ='Full Historical Statements'!K44/'Full Historical Statements'!K43 -> 0.18046945 | J24: ='Full Historical Statements'!L44/'Full Historical Statements'!L43 -> 0.17985485 | K24: ='Full Historical Statements'!M44/'Full Historical Statements'!M43 -> 0.18104098 | L24: ='Full Historical Statements'!N44/'Full Historical Statements'!N43 -> 0.1804551
B25: Net income | C25: ='Full Historical Statements'!E45 -> 61271 | D25: ='Full Historical Statements'!F45 -> 72738 | E25: ='Full Historical Statements'!G45 -> 72361 | F25: ='Full Historical Statements'!H45 -> 88136 | G25: ='Full Historical Statements'!I45 -> 101832 | H25: ='Full Historical Statements'!J45 -> 125575.2 | I25: ='Full Historical Statements'!K45 -> 144200.19 | J25: ='Full Historical Statements'!L45 -> 166671.45 | ... L25: ='Full Historical Statements'!N45 -> 236840.5
B26: Net Margin | C26: =C25/C8 -> 0.3645174 | D26: =D25/D8 -> 0.36686337 | E26: =E25/E8 -> 0.34146238 | F26: =F25/F8 -> 0.35955973 | G26: =G25/G8 -> 0.36146015 | H26: ='Full Historical Statements'!J45/'Full Historical Statements'!J33 -> 0.3875986 | I26: ='Full Historical Statements'!K45/'Full Historical Statements'!K33 -> 0.3870315 | J26: ='Full Historical Statements'!L45/'Full Historical Statements'!L33 -> 0.38899485 | K26: ='Full Historical Statements'!M45/'Full Historical Statements'!M33 -> 0.40096233 | L26: ='Full Historical Statements'!N45/'Full Historical Statements'!N33 -> 0.4179679
B27: Diluted EPS | C27: ='Full Historical Statements'!E47 -> 8.05 | D27: ='Full Historical Statements'!F47 -> 9.65 | E27: ='Full Historical Statements'!G47 -> 9.68 | F27: ='Full Historical Statements'!H47 -> 11.8 | G27: ='Full Historical Statements'!I47 -> 13.64 | H27: ='Full Historical Statements'!J47 -> 0 | I27: ='Full Historical Statements'!K47 -> 0 | J27: ='Full Historical Statements'!L47 -> 0 | ... L27: ='Full Historical Statements'!N47 -> 0
B28: Diluted weighted average shares | C28: ='Full Historical Statements'!E49 -> 7608 | D28: ='Full Historical Statements'!F49 -> 7540 | E28: ='Full Historical Statements'!G49 -> 7472 | F28: ='Full Historical Statements'!H49 -> 7469 | G28: ='Full Historical Statements'!I49 -> 7465 | H28: ='Full Historical Statements'!J49 -> 0 | I28: ='Full Historical Statements'!K49 -> 0 | J28: ='Full Historical Statements'!L49 -> 0 | ... L28: ='Full Historical Statements'!N49 -> 0
B31: Balance Sheet
B32: Cash and cash equivalents | C32: ='Full Historical Statements'!E53 -> 14224 | D32: ='Full Historical Statements'!F53 -> 13931 | E32: ='Full Historical Statements'!G53 -> 34704 | F32: ='Full Historical Statements'!H53 -> 18315 | G32: ='Full Historical Statements'!I53 -> 30242 | H32: ='Full Historical Statements'!J53 -> 43770.741 | I32: ='Full Historical Statements'!K53 -> 45015.378 | J32: ='Full Historical Statements'!L53 -> 49320.403 | ... L32: ='Full Historical Statements'!N53 -> 69204.761
B33: Short-term investments | C33: ='Full Historical Statements'!E54 -> 116110 | D33: ='Full Historical Statements'!F54 -> 90826 | E33: ='Full Historical Statements'!G54 -> 76558 | F33: ='Full Historical Statements'!H54 -> 57228 | G33: ='Full Historical Statements'!I54 -> 64323 | H33: ='Full Historical Statements'!J54 -> 94878 | I33: ='Full Historical Statements'!K54 -> 100865 | J33: ='Full Historical Statements'!L54 -> 105322 | ... L33: ='Full Historical Statements'!N54 -> 202629
B34: Accounts receivable | C34: ='Full Historical Statements'!E56 -> 38043 | D34: ='Full Historical Statements'!F56 -> 44261 | E34: ='Full Historical Statements'!G56 -> 48688 | F34: ='Full Historical Statements'!H56 -> 56924 | G34: ='Full Historical Statements'!I56 -> 69905 | H34: ='Full Historical Statements'!J56 -> 80773.744 | I34: ='Full Historical Statements'!K56 -> 91869.039 | J34: ='Full Historical Statements'!L56 -> 105649.39 | ... L34: ='Full Historical Statements'!N56 -> 139721.32
B35: Accounts receivable days | C35: =IFERROR(C34/C8*365,"") -> 82.609675 | D35: =IFERROR(D34/D8*365,"") -> 81.481137 | E35: =IFERROR(E34/E8*365,"") -> 83.859661 | F35: =IFERROR(F34/F8*365,"") -> 84.762934 | G35: =IFERROR(G34/G8*365,"") -> 90.568517 | H35: ='Full Historical Statements'!J20 -> 91 | I35: ='Full Historical Statements'!K20 -> 90 | J35: ='Full Historical Statements'!L20 -> 90 | K35: ='Full Historical Statements'!M20 -> 90 | L35: ='Full Historical Statements'!N20 -> 90
B36: Inventories | C36: ='Full Historical Statements'!E57 -> 2636 | D36: ='Full Historical Statements'!F57 -> 3742 | E36: ='Full Historical Statements'!G57 -> 2500 | F36: ='Full Historical Statements'!H57 -> 1246 | G36: ='Full Historical Statements'!I57 -> 938 | H36: ='Full Historical Statements'!J57 -> 825.48991 | I36: ='Full Historical Statements'!K57 -> 653.29094 | J36: ='Full Historical Statements'!L57 -> 774.76223 | ... L36: ='Full Historical Statements'!N57 -> 931.47549
B37: Inventory days | C37: =IFERROR(C36/C10*365,"") -> 18.420509 | D37: =IFERROR(D36/D10*365,"") -> 21.800958 | E37: =IFERROR(E36/E10*365,"") -> 13.854516 | F37: =IFERROR(F36/F10*365,"") -> 6.1363575 | G37: =IFERROR(G36/G10*365,"") -> 3.8980542 | H37: ='Full Historical Statements'!J21 -> 3 | I37: ='Full Historical Statements'!K21 -> 2 | J37: ='Full Historical Statements'!L21 -> 2 | K37: ='Full Historical Statements'!M21 -> 2 | L37: ='Full Historical Statements'!N21 -> 2
B38: Other current assets | C38: ='Full Historical Statements'!E58 -> 13393 | D38: ='Full Historical Statements'!F58 -> 16924 | E38: ='Full Historical Statements'!G58 -> 21807 | F38: ='Full Historical Statements'!H58 -> 26021 | G38: ='Full Historical Statements'!I58 -> 25723 | H38: ='Full Historical Statements'!J58 -> 24517 | I38: ='Full Historical Statements'!K58 -> 25420.333 | J38: ='Full Historical Statements'!L58 -> 25220.111 | ... L38: ='Full Historical Statements'!N58 -> 25230.975
B39: Total current assets | C39: ='Full Historical Statements'!E59 -> 184406 | D39: ='Full Historical Statements'!F59 -> 169684 | E39: ='Full Historical Statements'!G59 -> 184257 | F39: ='Full Historical Statements'!H59 -> 159734 | G39: ='Full Historical Statements'!I59 -> 191131 | H39: ='Full Historical Statements'!J59 -> 244764.98 | I39: ='Full Historical Statements'!K59 -> 263823.04 | J39: ='Full Historical Statements'!L59 -> 286286.67 | ... L39: ='Full Historical Statements'!N59 -> 437717.54
B40: Property and equipment, net | C40: ='Full Historical Statements'!E60 -> 59715 | D40: ='Full Historical Statements'!F60 -> 74398 | E40: ='Full Historical Statements'!G60 -> 95641 | F40: ='Full Historical Statements'!H60 -> 135591 | G40: ='Full Historical Statements'!I60 -> 204966 | H40: ='Full Historical Statements'!J60 -> 216913.52 | I40: ='Full Historical Statements'!K60 -> 323530.82 | J40: ='Full Historical Statements'!L60 -> 387501.07 | ... L40: ='Full Historical Statements'!N60 -> 426928.08
B41: Operating lease ROU assets | C41: ='Full Historical Statements'!E61 -> 11088 | D41: ='Full Historical Statements'!F61 -> 13148 | E41: ='Full Historical Statements'!G61 -> 14346 | F41: ='Full Historical Statements'!H61 -> 18961 | G41: ='Full Historical Statements'!I61 -> 24823 | H41: ='Full Historical Statements'!J61 -> 26064.15 | I41: ='Full Historical Statements'!K61 -> 27367.358 | J41: ='Full Historical Statements'!L61 -> 28735.725 | ... L41: ='Full Historical Statements'!N61 -> 31681.137
B42: Equity and other investments | C42: ='Full Historical Statements'!E62 -> 5984 | D42: ='Full Historical Statements'!F62 -> 6891 | E42: ='Full Historical Statements'!G62 -> 9879 | F42: ='Full Historical Statements'!H62 -> 14600 | G42: ='Full Historical Statements'!I62 -> 15405 | H42: ='Full Historical Statements'!J62 -> 25000 | I42: ='Full Historical Statements'!K62 -> 30000 | J42: ='Full Historical Statements'!L62 -> 30000 | ... L42: ='Full Historical Statements'!N62 -> 80000
B43: Goodwill | C43: ='Full Historical Statements'!E63 -> 49711 | D43: ='Full Historical Statements'!F63 -> 67524 | E43: ='Full Historical Statements'!G63 -> 67886 | F43: ='Full Historical Statements'!H63 -> 119220 | G43: ='Full Historical Statements'!I63 -> 119509 | H43: ='Full Historical Statements'!J63 -> 150000 | I43: ='Full Historical Statements'!K63 -> 150000 | J43: ='Full Historical Statements'!L63 -> 200000 | ... L43: ='Full Historical Statements'!N63 -> 290000
B44: Intangible assets, net | C44: ='Full Historical Statements'!E64 -> 7800 | D44: ='Full Historical Statements'!F64 -> 11298 | E44: ='Full Historical Statements'!G64 -> 9366 | F44: ='Full Historical Statements'!H64 -> 27597 | G44: ='Full Historical Statements'!I64 -> 22604 | H44: ='Full Historical Statements'!J64 -> 19855.667 | I44: ='Full Historical Statements'!K64 -> 23352.222 | J44: ='Full Historical Statements'!L64 -> 21937.296 | ... L44: ='Full Historical Statements'!N64 -> 22334.86
B45: Other long-term assets | C45: ='Full Historical Statements'!E65 -> 15075 | D45: ='Full Historical Statements'!F65 -> 21897 | E45: ='Full Historical Statements'!G65 -> 30601 | F45: ='Full Historical Statements'!H65 -> 36460 | G45: ='Full Historical Statements'!I65 -> 40565 | H45: ='Full Historical Statements'!J65 -> 46649.75 | I45: ='Full Historical Statements'!K65 -> 53647.212 | J45: ='Full Historical Statements'!L65 -> 61694.294 | ... L45: ='Full Historical Statements'!N65 -> 81590.704
...

Sheet Ratios
D2: 2021 | E2: 2022 | F2: 2023 | G2: 2024 | H2: 2025
B3: OPERATIONAL EFFICIENCY
B4: Gross Profit | D4: =('Full Historical Statements'!E33-'Full Historical Statements'!E36)/'Full Historical Statements'!E33 -> 0.68925801 | E4: =('Full Historical Statements'!F33-'Full Historical Statements'!F36)/'Full Historical Statements'!F33 -> 0.68401674 | F4: =('Full Historical Statements'!G33-'Full Historical Statements'!G36)/'Full Historical Statements'!G33 -> 0.68920086 | G4: =('Full Historical Statements'!H33-'Full Historical Statements'!H36)/'Full Historical Statements'!H33 -> 0.69764444 | H4: =('Full Historical Statements'!I33-'Full Historical Statements'!I36)/'Full Historical Statements'!I33 -> 0.68823742
B5: Operating Profit Margin | D5: ='Full Historical Statements'!E41/'Full Historical Statements'!E33 -> 0.41594879 | E5: ='Full Historical Statements'!F41/'Full Historical Statements'!F33 -> 0.42055278 | F5: ='Full Historical Statements'!G41/'Full Historical Statements'!G33 -> 0.41772881 | G5: ='Full Historical Statements'!H41/'Full Historical Statements'!H33 -> 0.446443 | H5: ='Full Historical Statements'!I41/'Full Historical Statements'!I33 -> 0.45621956
B6: Net Profit Margin | D6: ='Full Historical Statements'!E45/'Full Historical Statements'!E33 -> 0.3645174 | E6: ='Full Historical Statements'!F45/'Full Historical Statements'!F33 -> 0.36686337 | F6: ='Full Historical Statements'!G45/'Full Historical Statements'!G33 -> 0.34146238 | G6: ='Full Historical Statements'!H45/'Full Historical Statements'!H33 -> 0.35955973 | H6: ='Full Historical Statements'!I45/'Full Historical Statements'!I33 -> 0.36146015
B8: LEVERED FREE CASH FLOW
B9: Operating Cash Flow | D9: ='Full Historical Statements'!E106 -> 76740 | E9: ='Full Historical Statements'!F41 -> 83383 | F9: ='Full Historical Statements'!G41 -> 88523 | G9: ='Full Historical Statements'!H41 -> 109433 | H9: ='Full Historical Statements'!I41 -> 128528
B10: Less: CAPEX | D10: =-'Full Historical Statements'!E118 -> 20622 | E10: =-'Full Historical Statements'!F118 -> 23886 | F10: =-'Full Historical Statements'!G118 -> 28107 | G10: =-'Full Historical Statements'!H118 -> 44477 | H10: =-'Full Historical Statements'!I118 -> 64551
B11: FCF | D11: =D9-D10 -> 56118 | E11: =E9-E10 -> 59497 | F11: =F9-F10 -> 60416 | G11: =G9-G10 -> 64956 | H11: =H9-H10 -> 63977
B12: (Growth Rate) | E12: =E11/D11-1 -> 0.06021241 | F12: =F11/E11-1 -> 0.015446157 | G12: =G11/F11-1 -> 0.075145657 | H12: =H11/G11-1 -> -0.015071741
B14: RETURN ON INVESTOR CAPITAL
B15: EBIT | D15: ='Full Historical Statements'!E41 -> 69916 | E15: ='Full Historical Statements'!F41 -> 83383 | F15: ='Full Historical Statements'!G41 -> 88523 | G15: ='Full Historical Statements'!H41 -> 109433 | H15: ='Full Historical Statements'!I41 -> 128528
B16: Tax Rate | D16: =1-'Full Historical Statements'!E17 -> 0.86173385 | E16: =1-'Full Historical Statements'!F17 -> 0.86886617 | F16: =1-'Full Historical Statements'!G17 -> 0.81021375 | G16: =1-'Full Historical Statements'!H17 -> 0.81768673 | H16: =1-'Full Historical Statements'!I17 -> 0.82370356
B17: NOPAT | D17: =D15*D16 -> 60248.984 | E17: =E15*E16 -> 72448.668 | F17: =F15*F16 -> 71722.552 | G17: =G15*G16 -> 89481.912 | H17: =H15*H16 -> 105868.97
B18: Total Debt | D18: =('Simplified Model'!G49+'Simplified Model'!G50+'Simplified Model'!G56) -> 43151 | E18: =('Simplified Model'!H49+'Simplified Model'!H50+'Simplified Model'!H56) -> 47152 | F18: =('Simplified Model'!I49+'Simplified Model'!I50+'Simplified Model'!I56) -> 61151 | G18: =('Simplified Model'!J49+'Simplified Model'!J50+'Simplified Model'!J56) -> 57151 | H18: =('Simplified Model'!K49+'Simplified Model'!K50+'Simplified Model'!K56) -> 37151
B19: Total Equity | D19: ='Full Historical Statements'!E86 -> 141988 | E19: ='Full Historical Statements'!F86 -> 166542 | F19: ='Full Historical Statements'!G86 -> 206223 | G19: ='Full Historical Statements'!H86 -> 268477 | H19: ='Full Historical Statements'!I86 -> 343479
B20: Excess Cash | D20: ='Full Historical Statements'!E128 -> 14224 | E20: ='Full Historical Statements'!F128 -> 13931 | F20: ='Full Historical Statements'!G128 -> 34704 | G20: ='Full Historical Statements'!H128 -> 18315 | H20: ='Full Historical Statements'!I128 -> 30242
B21: Invested Capital | D21: =D18+D19-D20 -> 170915 | E21: =E18+E19-E20 -> 199763 | F21: =F18+F19-F20 -> 232670 | G21: =G18+G19-G20 -> 307313 | H21: =H18+H19-H20 -> 350388
B22: ROIC | D22: =D17/D21 -> 0.35250846 | E22: =E17/E21 -> 0.36267311 | F22: =F17/F21 -> 0.3082587 | G22: =G17/G21 -> 0.29117516 | H22: =H17/H21 -> 0.30214782
B24: RETURN ON EQUITY (ROE)
B25: Net Income | D25: ='Full Historical Statements'!E45 -> 61271 | E25: ='Full Historical Statements'!F45 -> 72738 | F25: ='Full Historical Statements'!G45 -> 72361 | G25: ='Full Historical Statements'!H45 -> 88136 | H25: ='Full Historical Statements'!I45 -> 101832
B26: Shareholders Equity | D26: ='Full Historical Statements'!E86 -> 141988 | E26: ='Full Historical Statements'!F86 -> 166542 | F26: ='Full Historical Statements'!G86 -> 206223 | G26: ='Full Historical Statements'!H86 -> 268477 | H26: ='Full Historical Statements'!I86 -> 343479
B27: ROE | D27: =D25/D26 -> 0.43152238 | E27: =E25/E26 -> 0.43675469 | F27: =F25/F26 -> 0.35088715 | G27: =G25/G26 -> 0.32828138 | H27: =H25/H26 -> 0.29647227
B29: RATIOS
B30: D/E Ratio | D30: =D18/D19 -> 0.30390596 | E30: =E18/E19 -> 0.28312378 | F30: =F18/F19 -> 0.29652852 | G30: =G18/G19 -> 0.21287112 | H30: =H18/H19 -> 0.10816091
B31: EV / Revenue | D31: =D40/'Full Historical Statements'!E33 -> 12.976388 | E31: =E40/'Full Historical Statements'!F33 -> 10.688048 | F31: =F40/'Full Historical Statements'!G33 -> 11.902568 | G31: =G40/'Full Historical Statements'!H33 -> 12.839225 | H31: =H40/'Full Historical Statements'!I33 -> 10.410869
B32: P/E Ratio | D32: =393.82/'Full Historical Statements'!E47 -> 48.921739 | E32: =393.82/'Full Historical Statements'!F47 -> 40.810363 | F32: =393.82/'Full Historical Statements'!G47 -> 40.683884 | G32: =393.82/'Full Historical Statements'!H47 -> 33.374576 | H32: =393.82/'Full Historical Statements'!I47 -> 28.872434
B34: EV / EBITDA
B35: Shares Outstanding | D35: 7430 | E35: 7430 | F35: 7430 | G35: 7430 | H35: 7430
B36: Share Price | D36: 289.67 | E36: 280.74 | F36: 335.92 | G36: 418.35 | H36: 393.82
B37: Equity Value | D37: =D35*D36 -> 2152248.1 | E37: =E35*E36 -> 2085898.2 | F37: =F35*F36 -> 2495885.6 | G37: =G35*G36 -> 3108340.5 | H37: =H35*H36 -> 2926082.6
B38: Total Debt | D38: =D18 -> 43151 | E38: =E18 -> 47152 | F38: =F18 -> 61151 | G38: =G18 -> 57151 | H38: =H18 -> 37151
B39: Cash and Cash equivalents | D39: =D20 -> 14224 | E39: =E20 -> 13931 | F39: =F20 -> 34704 | G39: =G20 -> 18315 | H39: =H20 -> 30242
B40: Enterprise Value | D40: =D37+D38-D39 -> 2181175.1 | E40: =E37+E38-E39 -> 2119119.2 | F40: =F37+F38-F39 -> 2522332.6 | G40: =G37+G38-G39 -> 3147176.5 | H40: =H37+H38-H39 -> 2932991.6

Sheet Valuation
B2: Company Name | C2: Forward P/E | D2: EV/EBITDA | E2: Expected Revenue Growth | F2: PEG Ratio
B3: Microsoft | C3: 20.28 | D3: 14.6 | E3: 0.155 | F3: 1.21
B4: Alphabet | C4: 24.51 | D4: 19.16 | E4: 0.169 | F4: 1.36
B5: Amazon | C5: 29.15 | D5: 14.47 | E5: 0.134 | F5: 1.3
B6: Apple | C6: 34.97 | D6: 30.74 | E6: 0.1579 | F6: 2.69
B7: Peer Average | C7: =AVERAGE(C3:C6) -> 27.2275 | D7: =AVERAGE(D3:D6) -> 19.7425 | E7: =AVERAGE(E3:E6) -> 0.153975 | F7: =AVERAGE(F3:F6) -> 1.64

Sheet DCF
F3: Year -2 | G3: Year -2 | H3: Year 0 | I3: Year 1 | J3: Year 2 | K3: Year 3 | L3: Year 4 | M3: Year 5 | N3: Term
B5: Revenue Growth | G5: =G11/F11-1 -> 0.15669962 | H5: =H11/G11-1 -> 0.14932156 | I5: =I11/H11-1 -> 0.15 | J5: =J11/I11-1 -> 0.15 | K5: =K11/J11-1 -> 0.15 | L5: =L11/K11-1 -> 0.15 | M5: =M11/L11-1 -> 0.15 | N5: 0.17
B6: COGS | C6: (% of Revenue) | F6: =-F12/F11 -> 0.31079914 | G6: =-G12/G11 -> 0.30235556 | H6: =-H12/H11 -> 0.31176258 | I6: =-I12/I11 -> 0.31 | J6: =-J12/J11 -> 0.32 | K6: =-K12/K11 -> 0.33 | L6: =-L12/L11 -> 0.32 | M6: =-M12/M11 -> 0.3 | N6: 0.005
B7: SG&A | C7: (% of Revenue) | F7: =F15/F11 -> 0.27147205 | G7: =G15/G11 -> 0.25120144 | H7: =H15/H11 -> 0.23201786 | I7: =I15/I11 -> 0.225 | J7: =J15/J11 -> 0.217 | K7: =K15/K11 -> 0.205 | L7: =L15/L11 -> 0.2 | M7: =M15/M11 -> 0.2 | N7: 0.2
B9: Depreciation Growth | G9: =G18/F18-1 -> 0.60789265 | H9: =H18/G18-1 -> 0.532418 | I9: =I18/H18-1 -> -0.26570199 | J9: =J18/I18-1 -> 0.72987773 | K9: =K18/J18-1 -> 0.7525358 | L9: =L18/K18-1 -> 0.32514299 | M9: =M18/L18-1 -> 0.090048736 | N9: 0.14
B11: Revenue | F11: ='Simplified Model'!E8 -> 211915 | G11: ='Simplified Model'!F8 -> 245122 | H11: ='Simplified Model'!G8 -> 281724 | I11: ='Simplified Model'!H8 -> 323982.6 | J11: ='Simplified Model'!I8 -> 372579.99 | K11: ='Simplified Model'!J8 -> 428466.99 | L11: ='Simplified Model'!K8 -> 492737.04 | M11: ='Simplified Model'!L8 -> 566647.59 | N11: =M11*(1+N5) -> 662977.68
B12: COGS | F12: =-'Simplified Model'!E10 -> -65863 | G12: =-'Simplified Model'!F10 -> -74114 | H12: =-'Simplified Model'!G10 -> -87831 | I12: =-'Simplified Model'!H10 -> -100434.61 | J12: =-'Simplified Model'!I10 -> -119225.6 | K12: =-'Simplified Model'!J10 -> -141394.11 | L12: =-'Simplified Model'!K10 -> -157675.85 | M12: =-'Simplified Model'!L10 -> -169994.28 | N12: =M12*(1+N6) -> -170844.25
B13: Gross Profit | F13: =F11+F12 -> 146052 | G13: =G11+G12 -> 171008 | H13: =H11+H12 -> 193893 | I13: =I11+I12 -> 223547.99 | J13: =J11+J12 -> 253354.39 | K13: =K11+K12 -> 287072.88 | L13: =L11+L12 -> 335061.19 | M13: =M11+M12 -> 396653.31 | N13: =N11+N12 -> 492133.43
B15: Operating Income | F15: ='Simplified Model'!E13+'Simplified Model'!E15+'Simplified Model'!E17 -> 57529 | G15: ='Simplified Model'!F13+'Simplified Model'!F15+'Simplified Model'!F17 -> 61575 | H15: ='Simplified Model'!G13+'Simplified Model'!G15+'Simplified Model'!G17 -> 65365 | I15: ='Simplified Model'!H13+'Simplified Model'!H15+'Simplified Model'!H17 -> 72896.085 | J15: ='Simplified Model'!I13+'Simplified Model'!I15+'Simplified Model'!I17 -> 80849.858 | K15: ='Simplified Model'!J13+'Simplified Model'!J15+'Simplified Model'!J17 -> 87835.733 | L15: ='Simplified Model'!K13+'Simplified Model'!K15+'Simplified Model'!K17 -> 98547.407 | M15: ='Simplified Model'!L13+'Simplified Model'!L15+'Simplified Model'!L17 -> 113329.52 | N15: =N11*N7 -> 132595.54
B16: EBITDA | F16: =F19-F18 -> 102384 | G16: =G19-G18 -> 131720 | H16: =H19-H18 -> 162681 | I16: =I19-I18 -> 175730.39 | J16: =J19-J18 -> 215887.24 | K16: =K19-K18 -> 275266.89 | L16: =L19-L18 -> 337264.06 | M16: =M19-M18 -> 393146.51 | N16: =N19-N18 -> 484735.79
B18: Depreciation | F18: =-'Simplified Model'!E73 -> -13861 | G18: =-'Simplified Model'!F73 -> -22287 | H18: =-'Simplified Model'!G73 -> -34153 | I18: =-'Simplified Model'!H73 -> -25078.48 | J18: =-'Simplified Model'!I73 -> -43382.704 | K18: =-'Simplified Model'!J73 -> -76029.742 | L18: =-'Simplified Model'!K73 -> -100750.28 | M18: =-'Simplified Model'!L73 -> -109822.71 | N18: =M18*(1+N9) -> -125197.89
B19: Operating Profit | F19: =F13-F15 -> 88523 | G19: =G13-G15 -> 109433 | H19: =H13-H15 -> 128528 | I19: =I13-I15 -> 150651.91 | J19: =J13-J15 -> 172504.54 | K19: =K13-K15 -> 199237.15 | L19: =L13-L15 -> 236513.78 | M19: =M13-M15 -> 283323.8 | N19: =N13-N15 -> 359537.9
B21: Tax Rate | F21: ='Full Historical Statements'!G17 -> 0.18978625 | G21: ='Full Historical Statements'!H17 -> 0.18231327 | H21: ='Full Historical Statements'!I17 -> 0.17629644 | I21: ='Full Historical Statements'!J17 -> 0.18279865 | J21: ='Full Historical Statements'!K17 -> 0.18046945 | K21: ='Full Historical Statements'!L17 -> 0.17985485 | L21: ='Full Historical Statements'!M17 -> 0.18104098 | M21: ='Full Historical Statements'!N17 -> 0.1804551 | N21: 0.18
B22: Current Tax | F22: ='Simplified Model'!E23 -> 16950 | G22: ='Simplified Model'!F23 -> 19651 | H22: ='Simplified Model'!G23 -> 21795 | I22: ='Simplified Model'!H23 -> 28089.745 | J22: ='Simplified Model'!I23 -> 31754.435 | K22: ='Simplified Model'!J23 -> 36550.443 | L22: ='Simplified Model'!K23 -> 43675.061 | M22: ='Simplified Model'!L23 -> 52149.767 | N22: =N19*N21 -> 64716.822
B27: UNLEVERED FREE CASH FLOW
F30: Year -2 | G30: Year -2 | H30: Year 0 | I30: Year 1 | J30: Year 2 | K30: Year 3 | L30: Year 4 | M30: Year 5 | N30: Term
B31: Unlevered Free Cash Flow
B32: EBIT | F32: =F19 -> 88523 | G32: =G19 -> 109433 | H32: =H19 -> 128528 | I32: =I19 -> 150651.91 | J32: =J19 -> 172504.54 | K32: =K19 -> 199237.15 | L32: =L19 -> 236513.78 | M32: =M19 -> 283323.8 | N32: =N19 -> 359537.9
B33: Current Taxes | F33: =F22 -> 16950 | G33: =G22 -> 19651 | H33: =H22 -> 21795 | I33: =I22 -> 28089.745 | J33: =J22 -> 31754.435 | K33: =K22 -> 36550.443 | L33: =L22 -> 43675.061 | M33: =M22 -> 52149.767 | N33: =N22 -> 64716.822
B34: NOPAT | F34: =F32-F33 -> 71573 | G34: =G32-G33 -> 89782 | H34: =H32-H33 -> 106733 | I34: =I32-I33 -> 122562.16 | J34: =J32-J33 -> 140750.1 | K34: =K32-K33 -> 162686.71 | L34: =L32-L33 -> 192838.72 | M34: =M32-M33 -> 231174.03 | N34: =N32-N33 -> 294821.08
B35: D&A | F35: =-F18 -> 13861 | G35: =-G18 -> 22287 | H35: =-H18 -> 34153 | I35: =-I18 -> 25078.48 | J35: =-J18 -> 43382.704 | K35: =-K18 -> 76029.742 | L35: =-L18 -> 100750.28 | M35: =-M18 -> 109822.71 | N35: =-N18 -> 125197.89
B36: Capital Expenditure | F36: ='Simplified Model'!E82 -> -28107 | G36: ='Simplified Model'!F82 -> -44477 | H36: ='Simplified Model'!G82 -> -64551 | I36: ='Simplified Model'!H82 -> -110000 | J36: ='Simplified Model'!I82 -> -150000 | K36: ='Simplified Model'!J82 -> -140000 | L36: ='Simplified Model'!K82 -> -120000 | M36: ='Simplified Model'!L82 -> -130000 | N36: -120000
B37: Cash from Working Capital | F37: ='Simplified Model'!E39-'Simplified Model'!E55 -> 80108 | G37: ='Simplified Model'!F39-'Simplified Model'!F55 -> 34448 | H37: ='Simplified Model'!G39-'Simplified Model'!G55 -> 49913 | I37: ='Simplified Model'!H39-'Simplified Model'!H55 -> 92094.675 | J37: ='Simplified Model'!I39-'Simplified Model'!I55 -> 92511.678 | K37: ='Simplified Model'!J39-'Simplified Model'!J55 -> 94602.927 | L37: ='Simplified Model'!K39-'Simplified Model'!K55 -> 146030.09 | M37: ='Simplified Model'!L39-'Simplified Model'!L55 -> 222425.83 | N37: 200000
B38: Unlevered Free Cash Flow | F38: =SUM(F34:F37) -> 137435 | G38: =SUM(G34:G37) -> 102040 | H38: =SUM(H34:H37) -> 126248 | I38: =SUM(I34:I37) -> 129735.32 | J38: =SUM(J34:J37) -> 126644.48 | K38: =SUM(K34:K37) -> 193319.38 | L38: =SUM(L34:L37) -> 319619.08 | M38: =SUM(M34:M37) -> 433422.57 | N38: =SUM(N34:N37) -> 500018.97
B42: DISCOUNTED CASH FLOW SCHEDULE
I44: Year 1 | J44: Year 2 | K44: Year 3 | L44: Year 4 | M44: Year 5 | N44: Term
B46: Unlevered Free Cash Flow | I46: =I38 -> 129735.32 | J46: =J38 -> 126644.48 | K46: =K38 -> 193319.38 | L46: =L38 -> 319619.08 | M46: =M38 -> 433422.57 | N46: =N38 -> 500018.97
B47: EBITDA | N47: =N16 -> 484735.79
B50: UNDISCOUNTED CASH FLOW
B51: Discrete Forecast | I51: =I46 -> 129735.32 | J51: =J46 -> 126644.48 | K51: =K46 -> 193319.38 | L51: =L46 -> 319619.08 | M51: =M46 -> 433422.57 | N51: =N46 -> 500018.97
B52: Terminal Value | I52: 0 | J52: 0 | K52: 0 | L52: 0 | M52: 0 | N52: =(N51*(1+D60))/(D61-D60) -> 7285308.3
B53: Total Cash Flow | I53: =SUM(I51:I52) -> 129735.32 | J53: =SUM(J51:J52) -> 126644.48 | K53: =SUM(K51:K52) -> 193319.38 | L53: =SUM(L51:L52) -> 319619.08 | M53: =SUM(M51:M52) -> 433422.57 | N53: =SUM(N51:N52) -> 7785327.3
B57: ASSUMPTIONS | G57: ENTERPRISE VALUE | K57: EQUITY VALUE PER SHARE
B58: First Year of Forecast | D58: 2026 | G58: PV of Discrete | I58: =NPV(D61,I51,J51,K51,L51,M51) -> 853399.94 | K58: Equity Value | N58: =I74 -> 5349873.9
B59: Terminal Multiple | D59: =Valuation!D3 -> 14.6 | G59: PV of Terminal | I59: =NPV(D61,0,0,0,0,N52) -> 4509383 | K59: Shares Outstanding | N59: =D79 -> 7465
B60: Growth Rate | D60: 0.03 | G60: Enterprise Value | I60: =I58+I59 -> 5362782.9 | K60: Instrinsic Value per Share | N60: =N58/N59 -> 716.66094
B61: Discount Rate | D61: =(D81*D68)+(D87*D74) -> 0.1006929
B64: COST OF EQUITY | G64: NET DEBT
B65: Risk-free rate (US 10y) | D65: 0.0462 | G65: Short-term debt | I65: ='Simplified Model'!G49 -> 0
B66: Beta | D66: 1.13 | G66: Long-term debt | I66: ='Simplified Model'!G50+'Simplified Model'!G56 -> 43151
...

Sheet Source Notes
A1: Microsoft Corporation Historical Model - Source Notes
A2: Units | B2: USD millions unless otherwise stated
A3: Company | B3: Microsoft Corporation
A4: Ticker | B4: MSFT
A6: Fiscal year | B6: Filing used | C6: Uploaded PDF filename | D6: SEC archive URL
A7: 2021A | B7: FY2021 Form 10-K | C7: 0001564590-21-039151.pdf | D7: https://www.sec.gov/Archives/edgar/data/789019/000156459021039151/
A8: 2022A | B8: FY2023 Form 10-K comparative statements / FY2022 Form 10-K cross-check | C8: 0000950170-23-035122.pdf / 0001564590-22-026876.pdf | D8: https://www.sec.gov/Archives/edgar/data/789019/000095017023035122/
A9: 2023A | B9: FY2025 Form 10-K comparative statements / FY2023 Form 10-K cross-check | C9: 0000950170-25-100235.pdf / 0000950170-23-035122.pdf | D9: https://www.sec.gov/Archives/edgar/data/789019/000095017025100235/
A10: 2024A | B10: FY2025 Form 10-K comparative statements | C10: 0000950170-25-100235.pdf | D10: https://www.sec.gov/Archives/edgar/data/789019/000095017025100235/
A11: 2025A | B11: FY2025 Form 10-K | C11: 0000950170-25-100235.pdf | D11: https://www.sec.gov/Archives/edgar/data/789019/000095017025100235/
A13: Scope | B13: Full historical statements plus linked simplified model. Forecast columns are intentionally left blank for user completion.
A14: Colour convention | B14: Blue font = hardcoded audited inputs; black font = formulas; green font = same-workbook links; yellow fill = forecast input area.
