Workbook

Sheet Full Historical Statements
A1: Crocs, Inc. — Full Historical Three-Statement Model
A2: USD $000s, except per share data; historical periods sourced from Crocs 10-Ks.
A4: Fiscal Year Ended Dec 31 | O4: Source / notes | BYS4: 4 | BYT4: 5 | BYU4: 6 | BYV4: 7 | BYW4: 8
A5: Key Assumptions | D5: 2021 | E5: 2022 | F5: 2023 | G5: 2024 | H5: 2025 | I5: 2026 | J5: 2027 | K5: 2028 | L5: 2029 | M5: 2030 | O5: 2021: Crocs FY2021 10-K; 2022-2023: Crocs FY2023 10-K; 2024-2025: Crocs FY2025 10-K.
A6: Revenue Growth (% Change) | E6: =E20/D20-1 -> 0.53668212 | F6: =F20/E20-1 -> 0.11458895 | G6: =G20/F20-1 -> 0.035272277 | H6: =H20/G20-1 -> -0.014982784 | I6: -0.006 | J6: 0.01 | K6: 0.02 | L6: 0.02 | M6: 0.03
A7: Cost of Goods Sold (% of Revenue) | D7: =D21/D20 -> 0.38609398 | E7: =E21/E20 -> 0.47671172 | F7: =F21/F20 -> 0.44224723 | G7: =G21/G20 -> 0.41243429 | H7: =H21/H20 -> 0.41666396 | I7: 0.42 | J7: 0.42 | K7: 0.43 | L7: 0.44 | M7: 0.45
A8: SGA (% of Revenue) | D8: =D23/D20 -> 0.31864394 | E8: =E23/E20 -> 0.28397476 | F8: =F23/F20 -> 0.29375014 | G8: =G23/G20 -> 0.33257657 | H8: =H23/H20 -> 0.36366082 | I8: 0.32 | J8: 0.33 | K8: 0.36 | L8: 0.36 | M8: 0.35 | O8: Key checks
A9: Depreciation & Amortization (% of PP&E) | D9: =D81/-D99 -> 0.57185779 | E9: =E81/-E99 -> 0.37651406 | F9: =F81/-F99 -> 0.46965622 | G9: =G81/-G99 -> 1.0071092 | H9: =H81/-H99 -> 1.5475396 | I9: 0.9 | J9: 0.9 | K9: 0.3 | L9: 0.3 | M9: 0.3 | O9: 2021 BS check | P9: =D76 -> 0
A10: Interest (% of Debt) | D10: 0.044864249 | E10: 0.10593586 | F10: 0.094207593 | G10: 0.090664773 | H10: 0.090272176 | I10: 0.02706513 | J10: 0.048305632 | K10: 0.057459948 | L10: 0.089442732 | M10: 0.021732428 | O10: 2022 BS check | P10: =E76 -> 0
A11: Tax Rate (% of Earnings Before Tax) | D11: =-D32/(D26+D27+D28) -> 0.090456473 | E11: =E32/E31 -> 0.24822131 | F11: =F32/F31 -> 0.095525134 | G11: =G32/-G31 -> 0.043363332 | H11: =H32/H31 -> 2.1126367 | I11: 0.25 | J11: 0.25 | K11: 0.25 | L11: 0.25 | M11: 0.25 | O11: 2023 BS check | P11: =F76 -> 0
A12: Accounts Receivable (Days) | D12: =D39/D20*D17 -> 28.814353 | E12: =E39/E20*E17 -> 30.349442 | F12: =F39/F20*F17 -> 28.164534 | G12: =G39/G20*G17 -> 22.92597 | H12: =H39/H20*H17 -> 25.129568 | I12: =AVERAGE(D12:H12) -> 27.076773 | J12: 27 | K12: 27 | L12: 27 | M12: 27 | O12: 2024 BS check | P12: =G76 -> 0
A13: Inventory (Days) | D13: =D40/D21*D17 -> 87.253861 | E13: =E40/E21*E17 -> 101.56123 | F13: =F40/F21*F17 -> 80.204156 | G13: =G40/G21*G17 -> 76.858297 | H13: =H40/H21*H17 -> 79.93074 | I13: =AVERAGE(D13:H13) -> 85.161656 | J13: 85 | K13: 85 | L13: 85 | M13: 85 | O13: 2025 BS check | P13: =H76 -> 0
A14: Accounts Payable (Days) | D14: =D55/D21*D17 -> 66.259729 | E14: =E55/E21*E17 -> 49.713528 | F14: =F55/F21*F17 -> 54.35996 | G14: =G55/G21*G17 -> 57.149786 | H14: =H55/H21*H17 -> 57.687878 | I14: =AVERAGE(D14:H14) -> 57.034176 | J14: 57 | K14: 57 | L14: 57 | M14: 57 | O14: 2021 cash tie | P14: =D116 -> 0
A15: Capital Expenditures ($000's) | E15: =(E45-D45)+E81 -> 112360 | F15: =(F45-E45)+F81 -> 111090 | G15: =(G45-F45)+G81 -> 75860 | H15: =(H45-G45)+H81 -> 73138 | I15: 20000 | J15: 20000 | K15: 100000 | L15: 120000 | M15: 100000 | O15: 2022 cash tie | P15: =E116 -> 0
A16: Equity Issued (Repaid) ($000's) | D16: =-(D108+D109) -> 1020119 | E16: =-(E108+E109) -> 11477 | F16: =-(F108+F109) -> 192105 | G16: =-(G108+G109) -> 560690 | H16: =-(H108+H109) -> 586565 | I16: 300000 | J16: 300000 | K16: 300000 | L16: 300000 | M16: 300000
A17: Days in Period | D17: 365 | E17: 365 | F17: 365 | G17: 365 | H17: 365 | I17: 365 | J17: 365 | K17: 365 | L17: 365 | M17: 365
A19: Income Statement | D19: 2021 | E19: 2022 | F19: 2023 | G19: 2024 | H19: 2025 | I19: 2026 | J19: 2027 | K19: 2028 | L19: 2029 | M19: 2030
A20: Revenues | D20: 2313416 | E20: 3554985 | F20: 3962347 | G20: 4102108 | H20: 4040647 | I20: =H20*(1+I6) -> 4016403.1 | J20: =I20*(1+J6) -> 4056567.1 | K20: =J20*(1+K6) -> 4137698.5 | L20: =K20*(1+L6) -> 4220452.5 | M20: =L20*(1+M6) -> 4347066
A21: Cost of sales | D21: 893196 | E21: 1694703 | F21: 1752337 | G21: 1691850 | H21: 1683592 | I21: =I20*I7 -> 1686889.3 | J21: =J20*J7 -> 1703758.2 | K21: =K20*K7 -> 1779210.4 | L21: =L20*L7 -> 1856999.1 | M21: =M20*M7 -> 1956179.7
A22: Gross profit | D22: =D20-D21 -> 1420220 | E22: =E20-E21 -> 1860282 | F22: =F20-F21 -> 2210010 | G22: =G20-G21 -> 2410258 | H22: =H20-H21 -> 2357055 | I22: =I20-I21 -> 2329513.8 | J22: =J20-J21 -> 2352808.9 | K22: =K20-K21 -> 2358488.1 | ... M22: =M20-M21 -> 2390886.3
A23: Selling, general and administrative expenses | D23: 737156 | E23: 1009526 | F23: 1163940 | G23: 1364265 | H23: 1469425 | I23: =I20*I8 -> 1285249 | J23: =J20*J8 -> 1338667.2 | K23: =K20*K8 -> 1489571.5 | L23: =L20*L8 -> 1519362.9 | M23: =M20*M8 -> 1521473.1
A24: Goodwill impairment | D24: 0 | E24: 0 | F24: 0 | G24: 0 | H24: 307000 | I24: 307000 | J24: 307000 | K24: 307000 | L24: 307000 | M24: 307000
A25: Asset impairments | D25: 0 | E25: 0 | F25: 9287 | G25: 24082 | H25: 431115 | I25: 290000 | J25: 102000 | K25: 60000 | L25: 15000 | M25: 7000
A26: Income from operations | D26: =D22-D23-D24-D25 -> 683064 | E26: =E22-E23-E24-E25 -> 850756 | F26: =F22-F23-F24-F25 -> 1036783 | G26: =G22-G23-G24-G25 -> 1021911 | H26: =H22-H23-H24-H25 -> 149515 | I26: =I22-I23-I24-I25 -> 447264.81 | J26: =J22-J23-J24-J25 -> 605141.79 | K26: =K22-K23-K24-K25 -> 501916.68 | ... M26: =M22-M23-M24-M25 -> 555413.21
A27: Foreign currency gains (losses), net | D27: -140 | E27: 3228 | F27: -1240 | G27: -6777 | H27: 9843 | I27: 9843 | J27: 9843 | K27: 9843 | L27: 9843 | M27: 9843
A28: Interest income | D28: 775 | E28: 1020 | F28: 2406 | G28: 3484 | H28: 1844 | I28: 1844 | J28: 1844 | K28: 1844 | L28: 1844 | M28: 1844
A29: Interest expense | D29: -21647 | E29: -136158 | F29: -161351 | G29: -109264 | H29: -88287 | I29: =-I144 -> -42453.443 | J29: =-J145 -> -16240 | K29: =-K146 -> -15225 | L29: =-L144 -> -49353.546 | M29: =-M144 -> -17941.553
A30: Other income (expense), net | D30: 1797 | E30: -338 | F30: -326 | G30: 1231 | H30: 63 | I30: =AVERAGE(D30:H30) -> 485.4 | J30: =AVERAGE(E30:I30) -> 223.08 | K30: =AVERAGE(F30:J30) -> 335.296 | L30: =AVERAGE(G30:K30) -> 467.5552 | M30: =AVERAGE(H30:L30) -> 314.86624
A31: Income before income taxes | D31: =D26+D27+D28+D29+D30 -> 663849 | E31: =E26+E27+E28+E29+E30 -> 718508 | F31: =F26+F27+F28+F29+F30 -> 876272 | G31: =G26+G27+G28+G29+G30 -> 910585 | H31: =H26+H27+H28+H29+H30 -> 72978 | I31: =I26+I27+I28+I29+I30 -> 416983.77 | J31: =J26+J27+J28+J29+J30 -> 600811.87 | K31: =K26+K27+K28+K29+K30 -> 498713.98 | ... M31: =M26+M27+M28+M29+M30 -> 549473.52
A32: Income tax expense (benefit) | D32: -61845 | E32: 178349 | F32: 83706 | G32: -39486 | H32: 154176 | I32: =I31*I11 -> 104245.94 | J32: =J31*J11 -> 150202.97 | K32: =K31*K11 -> 124678.49 | L32: =L31*L11 -> 121222.88 | M32: =M31*M11 -> 137368.38
A33: Net income (loss) | D33: =D31-D32 -> 725694 | E33: =E31-E32 -> 540159 | F33: =F31-F32 -> 792566 | G33: =G31-G32 -> 950071 | H33: =H31-H32 -> -81198 | I33: =I31-I32 -> 312737.83 | J33: =J31-J32 -> 450608.9 | K33: =K31-K32 -> 374035.48 | ... M33: =M31-M32 -> 412105.14
A36: Balance Sheet — Assets
A37: Cash and cash equivalents | D37: 213197 | E37: 191629 | F37: 149288 | G37: 180485 | H37: 130354 | I37: =I115 -> 361852.26 | J37: =J115 -> 389596.82 | K37: =K115 -> 231889.89 | L37: =L115 -> 87162.314 | M37: =M115 -> 55638.584
A38: Restricted cash — current | D38: 65 | E38: 2 | F38: 2 | G38: 0 | H38: 0 | I38: 0 | J38: 0 | K38: 0 | L38: 0 | M38: 0
A39: Accounts receivable, net | D39: 182629 | E39: 295594 | F39: 305747 | G39: 257657 | H39: 278191 | I39: =I20*I12/I17 -> 297948.59 | J39: =J20*J12/J17 -> 300074.83 | K39: =K20*K12/K17 -> 306076.33 | L39: =L20*L12/L17 -> 312197.85 | M39: =M20*M12/M17 -> 321563.79
A40: Inventories | D40: 213520 | E40: 471551 | F40: 385054 | G40: 356254 | H40: 368687 | I40: =I21*I13/I17 -> 393584.35 | J40: =J21*J13/J17 -> 396765.61 | K40: =K21*K13/K17 -> 414336.66 | L40: =L21*L13/L17 -> 432451.84 | M40: =M21*M13/M17 -> 455548.7
A41: Income taxes receivable | D41: 22301 | E41: 14752 | F41: 4413 | G41: 4046 | H41: 32782 | I41: =AVERAGE(F41:H41) -> 13747 | J41: =AVERAGE(G41:I41) -> 16858.333 | K41: =AVERAGE(H41:J41) -> 21129.111 | L41: =AVERAGE(I41:K41) -> 17244.815 | M41: =AVERAGE(J41:L41) -> 18410.753
A42: Other receivables | D42: 12252 | E42: 18842 | F42: 21071 | G42: 22204 | H42: 22082 | I42: =H42*(1+(H42/G42-1)) -> 21960.67 | J42: =I42*(1+(I42/H42-1)) -> 21840.007 | K42: =J42*(1+(J42/I42-1)) -> 21720.007 | L42: =K42*(1+(K42/J42-1)) -> 21600.667 | M42: =L42*(1+(L42/K42-1)) -> 21481.982
A43: Prepaid expenses and other assets | D43: 22605 | E43: 33605 | F43: 45129 | G43: 51623 | H43: 53787 | I43: =H43*(1+(H43/G43-1)) -> 56041.713 | J43: =I43*(1+(I43/H43-1)) -> 58390.943 | K43: =J43*(1+(J43/I43-1)) -> 60838.65 | L43: =K43*(1+(K43/J43-1)) -> 63388.964 | M43: =L43*(1+(L43/K43-1)) -> 66046.185
A44: Total current assets | D44: =SUM(D37:D43) -> 666569 | E44: =SUM(E37:E43) -> 1025975 | F44: =SUM(F37:F43) -> 910704 | G44: =SUM(G37:G43) -> 872269 | H44: =SUM(H37:H43) -> 885883 | I44: =SUM(I37:I43) -> 1145134.6 | J44: =SUM(J37:J43) -> 1183526.5 | K44: =SUM(K37:K43) -> 1055990.6 | ... M44: =SUM(M37:M43) -> 938689.99
...

Sheet Source Notes
A1: Source Notes
A2: Model sheet | B2: Source | C2: PDF section/page | D2: Purpose
A3: Full Historical Statements | B3: Crocs FY2021 10-K | C3: Consolidated Statements of Operations, Balance Sheets, Cash Flows / F-4, F-6, F-8 | D3: 2021 historical income statement, balance sheet and cash flow statement
A4: Full Historical Statements | B4: Crocs FY2023 10-K | C4: Consolidated Statements of Income, Balance Sheets, Cash Flows / F-4, F-6, F-8 | D4: 2022–2023 historical income statement, balance sheet and cash flow statement
A5: Full Historical Statements | B5: Crocs FY2025 10-K | C5: Consolidated Statements of Operations, Balance Sheets, Cash Flows / F-4, F-6, F-8 | D5: 2024–2025 historical income statement, balance sheet and cash flow statement

Sheet Simplified Model
A1: Crocs, Inc. — Simplified Three-Statement Model | O1: Model note
A2: USD $000s; historical and forecast data linked to Full Historical Statements. Forecast cash is used as a balancing line. | O2: Forecast cash is a balancing line
O3: This makes the balance sheet balance mechanically.
A4: Fiscal Year Ended Dec 31 | D4: 2021 | E4: 2022 | F4: 2023 | G4: 2024 | H4: 2025 | I4: 2026 | J4: 2027 | K4: 2028 | L4: 2029 | M4: 2030 | O4: Replace the balancing line with cash from the fully integrated cash flow statement once the schedules are final.
A6: Income Statement | O6: Check | P6: Target
A7: Revenue | D7: ='Full Historical Statements'!D20 -> 2313416 | E7: ='Full Historical Statements'!E20 -> 3554985 | F7: ='Full Historical Statements'!F20 -> 3962347 | G7: ='Full Historical Statements'!G20 -> 4102108 | H7: ='Full Historical Statements'!H20 -> 4040647 | I7: ='Full Historical Statements'!I20 -> 4016403.1 | J7: ='Full Historical Statements'!J20 -> 4056567.1 | K7: ='Full Historical Statements'!K20 -> 4137698.5 | ... M7: ='Full Historical Statements'!M20 -> 4347066 | O7: Balance sheet check | P7: 0
A8: Cost of sales | D8: ='Full Historical Statements'!D21 -> 893196 | E8: ='Full Historical Statements'!E21 -> 1694703 | F8: ='Full Historical Statements'!F21 -> 1752337 | G8: ='Full Historical Statements'!G21 -> 1691850 | H8: ='Full Historical Statements'!H21 -> 1683592 | I8: ='Full Historical Statements'!I21 -> 1686889.3 | J8: ='Full Historical Statements'!J21 -> 1703758.2 | K8: ='Full Historical Statements'!K21 -> 1779210.4 | ... M8: ='Full Historical Statements'!M21 -> 1956179.7 | O8: Cash flow reconciliation | P8: 0
A9: Gross profit | D9: ='Full Historical Statements'!D22 -> 1420220 | E9: ='Full Historical Statements'!E22 -> 1860282 | F9: ='Full Historical Statements'!F22 -> 2210010 | G9: ='Full Historical Statements'!G22 -> 2410258 | H9: ='Full Historical Statements'!H22 -> 2357055 | I9: ='Full Historical Statements'!I22 -> 2329513.8 | J9: ='Full Historical Statements'!J22 -> 2352808.9 | K9: ='Full Historical Statements'!K22 -> 2358488.1 | ... M9: ='Full Historical Statements'!M22 -> 2390886.3
A10: Selling, general and administrative expenses | D10: ='Full Historical Statements'!D23 -> 737156 | E10: ='Full Historical Statements'!E23 -> 1009526 | F10: ='Full Historical Statements'!F23 -> 1163940 | G10: ='Full Historical Statements'!G23 -> 1364265 | H10: ='Full Historical Statements'!H23 -> 1469425 | I10: ='Full Historical Statements'!I23 -> 1285249 | J10: ='Full Historical Statements'!J23 -> 1338667.2 | K10: ='Full Historical Statements'!K23 -> 1489571.5 | ... M10: ='Full Historical Statements'!M23 -> 1521473.1
A11: Asset impairments | D11: =SUM('Full Historical Statements'!D24:D25) -> 0 | E11: =SUM('Full Historical Statements'!E24:E25) -> 0 | F11: =SUM('Full Historical Statements'!F24:F25) -> 9287 | G11: =SUM('Full Historical Statements'!G24:G25) -> 24082 | H11: =SUM('Full Historical Statements'!H24:H25) -> 738115 | I11: =SUM('Full Historical Statements'!I24:I25) -> 597000 | J11: =SUM('Full Historical Statements'!J24:J25) -> 409000 | K11: =SUM('Full Historical Statements'!K24:K25) -> 367000 | ... M11: =SUM('Full Historical Statements'!M24:M25) -> 314000
A12: Income from operations | D12: ='Full Historical Statements'!D26 -> 683064 | E12: ='Full Historical Statements'!E26 -> 850756 | F12: ='Full Historical Statements'!F26 -> 1036783 | G12: ='Full Historical Statements'!G26 -> 1021911 | H12: ='Full Historical Statements'!H26 -> 149515 | I12: ='Full Historical Statements'!I26 -> 447264.81 | J12: ='Full Historical Statements'!J26 -> 605141.79 | K12: ='Full Historical Statements'!K26 -> 501916.68 | ... M12: ='Full Historical Statements'!M26 -> 555413.21
A13: Foreign currency gains (losses), net | D13: ='Full Historical Statements'!D27 -> -140 | E13: ='Full Historical Statements'!E27 -> 3228 | F13: ='Full Historical Statements'!F27 -> -1240 | G13: ='Full Historical Statements'!G27 -> -6777 | H13: ='Full Historical Statements'!H27 -> 9843 | I13: ='Full Historical Statements'!I27 -> 9843 | J13: ='Full Historical Statements'!J27 -> 9843 | K13: ='Full Historical Statements'!K27 -> 9843 | ... M13: ='Full Historical Statements'!M27 -> 9843
A14: Interest income | D14: ='Full Historical Statements'!D28 -> 775 | E14: ='Full Historical Statements'!E28 -> 1020 | F14: ='Full Historical Statements'!F28 -> 2406 | G14: ='Full Historical Statements'!G28 -> 3484 | H14: ='Full Historical Statements'!H28 -> 1844 | I14: ='Full Historical Statements'!I28 -> 1844 | J14: ='Full Historical Statements'!J28 -> 1844 | K14: ='Full Historical Statements'!K28 -> 1844 | ... M14: ='Full Historical Statements'!M28 -> 1844
A15: Interest expense | D15: ='Full Historical Statements'!D29 -> -21647 | E15: ='Full Historical Statements'!E29 -> -136158 | F15: ='Full Historical Statements'!F29 -> -161351 | G15: ='Full Historical Statements'!G29 -> -109264 | H15: ='Full Historical Statements'!H29 -> -88287 | I15: ='Full Historical Statements'!I29 -> -42453.443 | J15: ='Full Historical Statements'!J29 -> -16240 | K15: ='Full Historical Statements'!K29 -> -15225 | ... M15: ='Full Historical Statements'!M29 -> -17941.553
A16: Other income (expense), net | D16: ='Full Historical Statements'!D30 -> 1797 | E16: ='Full Historical Statements'!E30 -> -338 | F16: ='Full Historical Statements'!F30 -> -326 | G16: ='Full Historical Statements'!G30 -> 1231 | H16: ='Full Historical Statements'!H30 -> 63 | I16: ='Full Historical Statements'!I30 -> 485.4 | J16: ='Full Historical Statements'!J30 -> 223.08 | K16: ='Full Historical Statements'!K30 -> 335.296 | ... M16: ='Full Historical Statements'!M30 -> 314.86624
A17: Income before income taxes | D17: ='Full Historical Statements'!D31 -> 663849 | E17: ='Full Historical Statements'!E31 -> 718508 | F17: ='Full Historical Statements'!F31 -> 876272 | G17: ='Full Historical Statements'!G31 -> 910585 | H17: ='Full Historical Statements'!H31 -> 72978 | I17: ='Full Historical Statements'!I31 -> 416983.77 | J17: ='Full Historical Statements'!J31 -> 600811.87 | K17: ='Full Historical Statements'!K31 -> 498713.98 | ... M17: ='Full Historical Statements'!M31 -> 549473.52
A18: Income tax expense (benefit) | D18: ='Full Historical Statements'!D32 -> -61845 | E18: ='Full Historical Statements'!E32 -> 178349 | F18: ='Full Historical Statements'!F32 -> 83706 | G18: ='Full Historical Statements'!G32 -> -39486 | H18: ='Full Historical Statements'!H32 -> 154176 | I18: ='Full Historical Statements'!I32 -> 104245.94 | J18: =200157*28% -> 56043.96 | K18: ='Full Historical Statements'!K32 -> 124678.49 | L18: =341758*28% -> 95692.24 | M18: =446069*28% -> 124899.32
A19: Net income (loss) | D19: ='Full Historical Statements'!D33 -> 725694 | E19: ='Full Historical Statements'!E33 -> 540159 | F19: ='Full Historical Statements'!F33 -> 792566 | G19: ='Full Historical Statements'!G33 -> 950071 | H19: ='Full Historical Statements'!H33 -> -81198 | I19: ='Full Historical Statements'!I33 -> 312737.83 | J19: ='Full Historical Statements'!J33 -> 450608.9 | K19: ='Full Historical Statements'!K33 -> 374035.48 | ... M19: ='Full Historical Statements'!M33 -> 412105.14
A22: Balance Sheet — Assets
A23: Cash and cash equivalents | D23: ='Full Historical Statements'!D37 -> 213197 | E23: ='Full Historical Statements'!E37 -> 191629 | F23: ='Full Historical Statements'!F37 -> 149288 | G23: ='Full Historical Statements'!G37 -> 180485 | H23: ='Full Historical Statements'!H37 -> 130354 | I23: =I51-SUM(I24:I26,I28:I31) -> -8098.416 | J23: =J51-SUM(J24:J26,J28:J31) -> 534457.24 | K23: =K51-SUM(K24:K26,K28:K31) -> 1272941.7 | L23: =L51-SUM(L24:L26,L28:L31) -> 1409051 | M23: =M51-SUM(M24:M26,M28:M31) -> 1942365
A24: Accounts receivable, net | D24: ='Full Historical Statements'!D39 -> 182629 | E24: ='Full Historical Statements'!E39 -> 295594 | F24: ='Full Historical Statements'!F39 -> 305747 | G24: ='Full Historical Statements'!G39 -> 257657 | H24: ='Full Historical Statements'!H39 -> 278191 | I24: ='Full Historical Statements'!I39 -> 297948.59 | J24: ='Full Historical Statements'!J39 -> 300074.83 | K24: ='Full Historical Statements'!K39 -> 306076.33 | ... M24: ='Full Historical Statements'!M39 -> 321563.79
A25: Inventories | D25: ='Full Historical Statements'!D40 -> 213520 | E25: ='Full Historical Statements'!E40 -> 471551 | F25: ='Full Historical Statements'!F40 -> 385054 | G25: ='Full Historical Statements'!G40 -> 356254 | H25: ='Full Historical Statements'!H40 -> 368687 | I25: ='Full Historical Statements'!I40 -> 393584.35 | J25: ='Full Historical Statements'!J40 -> 396765.61 | K25: ='Full Historical Statements'!K40 -> 414336.66 | ... M25: ='Full Historical Statements'!M40 -> 455548.7
A26: Other current assets | D26: =SUM('Full Historical Statements'!D38,'Full Historical Statements'!D41:D43) -> 57223 | E26: =SUM('Full Historical Statements'!E38,'Full Historical Statements'!E41:E43) -> 67201 | F26: =SUM('Full Historical Statements'!F38,'Full Historical Statements'!F41:F43) -> 70615 | G26: =SUM('Full Historical Statements'!G38,'Full Historical Statements'!G41:G43) -> 77873 | H26: =SUM('Full Historical Statements'!H38,'Full Historical Statements'!H41:H43) -> 108651 | I26: =SUM('Full Historical Statements'!I38,'Full Historical Statements'!I41:I43) -> 91749.384 | J26: =SUM('Full Historical Statements'!J38,'Full Historical Statements'!J41:J43) -> 97089.283 | K26: =SUM('Full Historical Statements'!K38,'Full Historical Statements'!K41:K43) -> 103687.77 | ... M26: =SUM('Full Historical Statements'!M38,'Full Historical Statements'!M41:M43) -> 105938.92
A27: Total current assets | D27: =SUM(D23:D26) -> 666569 | E27: =SUM(E23:E26) -> 1025975 | F27: =SUM(F23:F26) -> 910704 | G27: =SUM(G23:G26) -> 872269 | H27: =SUM(H23:H26) -> 885883 | I27: =SUM(I23:I26) -> 775183.91 | J27: =SUM(J23:J26) -> 1328387 | K27: =SUM(K23:K26) -> 2097042.5 | ... M27: =SUM(M23:M26) -> 2825416.4
A28: Property and equipment, net | D28: ='Full Historical Statements'!D45 -> 108398 | E28: ='Full Historical Statements'!E45 -> 181529 | F28: ='Full Historical Statements'!F45 -> 238315 | G28: ='Full Historical Statements'!G45 -> 244335 | H28: ='Full Historical Statements'!H45 -> 238191 | I28: ='Full Historical Statements'!I45 -> 240280.33 | J28: ='Full Historical Statements'!J45 -> 240935.44 | K28: ='Full Historical Statements'!K45 -> 320000 | ... M28: ='Full Historical Statements'!M45 -> 360000
A29: Intangible assets, net | D29: ='Full Historical Statements'!D46 -> 28802 | E29: ='Full Historical Statements'!E46 -> 1800167 | F29: ='Full Historical Statements'!F46 -> 1792562 | G29: ='Full Historical Statements'!G46 -> 1777080 | H29: ='Full Historical Statements'!H46 -> 1324680 | I29: ='Full Historical Statements'!I46 -> 1631440.7 | J29: ='Full Historical Statements'!J46 -> 1577733.6 | K29: ='Full Historical Statements'!K46 -> 1511284.7 | ... M29: ='Full Historical Statements'!M46 -> 1554168.2
A30: Goodwill | D30: ='Full Historical Statements'!D47 -> 1600 | E30: ='Full Historical Statements'!E47 -> 714814 | F30: ='Full Historical Statements'!F47 -> 711588 | G30: ='Full Historical Statements'!G47 -> 711491 | H30: ='Full Historical Statements'!H47 -> 404689 | I30: ='Full Historical Statements'!I47 -> 609256 | J30: ='Full Historical Statements'!J47 -> 575145.33 | K30: ='Full Historical Statements'!K47 -> 529696.78 | ... M30: ='Full Historical Statements'!M47 -> 558736.05
A31: Other non-current assets | D31: =SUM('Full Historical Statements'!D48:D51) -> 739699 | E31: =SUM('Full Historical Statements'!E48:E51) -> 779312 | F31: =SUM('Full Historical Statements'!F48:F51) -> 990665 | G31: =SUM('Full Historical Statements'!G48:G51) -> 1206978 | H31: =SUM('Full Historical Statements'!H48:H51) -> 1321307 | I31: =SUM('Full Historical Statements'!I48:I51) -> 1172983.3 | J31: =SUM('Full Historical Statements'!J48:J51) -> 1233756.1 | K31: =SUM('Full Historical Statements'!K48:K51) -> 1419754 | ... M31: =SUM('Full Historical Statements'!M48:M51) -> 1461099.9
A32: Total assets | D32: =D27+SUM(D28:D31) -> 1545068 | E32: =E27+SUM(E28:E31) -> 4501797 | F32: =F27+SUM(F28:F31) -> 4643834 | G32: =G27+SUM(G28:G31) -> 4812153 | H32: =H27+SUM(H28:H31) -> 4174750 | I32: =I27+SUM(I28:I31) -> 4429144.2 | J32: =J27+SUM(J28:J31) -> 4955957.4 | K32: =K27+SUM(K28:K31) -> 5877778 | ... M32: =M27+SUM(M28:M31) -> 6759420.6
A35: Balance Sheet — Liabilities
A36: Accounts payable | D36: ='Full Historical Statements'!D55 -> 162145 | E36: ='Full Historical Statements'!E55 -> 230821 | F36: ='Full Historical Statements'!F55 -> 260978 | G36: ='Full Historical Statements'!G55 -> 264901 | H36: ='Full Historical Statements'!H55 -> 266090 | I36: ='Full Historical Statements'!I55 -> 263589.98 | J36: ='Full Historical Statements'!J55 -> 266066.35 | K36: ='Full Historical Statements'!K55 -> 277849.29 | ... M36: ='Full Historical Statements'!M55 -> 305485.6
A37: Other current liabilities | D37: =SUM('Full Historical Statements'!D56:D59) -> 226098 | E37: =SUM('Full Historical Statements'!E56:E59) -> 410453 | F37: =SUM('Full Historical Statements'!F56:F59) -> 437318 | G37: =SUM('Full Historical Statements'!G56:G59) -> 475307 | H37: =SUM('Full Historical Statements'!H56:H59) -> 434039 | I37: =SUM('Full Historical Statements'!I56:I59) -> 450057.37 | J37: =SUM('Full Historical Statements'!J56:J59) -> 458991.5 | K37: =SUM('Full Historical Statements'!K56:K59) -> 453609.81 | ... M37: =SUM('Full Historical Statements'!M56:M59) -> 463626.49
A38: Total current liabilities | D38: =SUM(D36:D37) -> 388243 | E38: =SUM(E36:E37) -> 641274 | F38: =SUM(F36:F37) -> 698296 | G38: =SUM(G36:G37) -> 740208 | H38: =SUM(H36:H37) -> 700129 | I38: =SUM(I36:I37) -> 713647.35 | J38: =SUM(J36:J37) -> 725057.85 | K38: =SUM(K36:K37) -> 731459.1 | ... M38: =SUM(M36:M37) -> 769112.09
A39: Long-term borrowings | D39: ='Full Historical Statements'!D63 -> 771390 | E39: ='Full Historical Statements'!E63 -> 2298027 | F39: ='Full Historical Statements'!F63 -> 1640996 | G39: ='Full Historical Statements'!G63 -> 1349339 | H39: ='Full Historical Statements'!H63 -> 1230885 | I39: ='Full Historical Statements'!I63 -> 950566 | J39: ='Full Historical Statements'!J63 -> 750566 | K39: ='Full Historical Statements'!K63 -> 900566 | ... M39: ='Full Historical Statements'!M63 -> 400566
A40: Other non-current liabilities | D40: =SUM('Full Historical Statements'!D61:D62,'Full Historical Statements'!D64:D65) -> 371353 | E40: =SUM('Full Historical Statements'!E61:E62,'Full Historical Statements'!E64:E65) -> 744565 | F40: =SUM('Full Historical Statements'!F61:F62,'Full Historical Statements'!F64:F65) -> 850619 | G40: =SUM('Full Historical Statements'!G61:G62,'Full Historical Statements'!G64:G65) -> 886874 | H40: =SUM('Full Historical Statements'!H61:H62,'Full Historical Statements'!H64:H65) -> 950453 | I40: =SUM('Full Historical Statements'!I61:I62,'Full Historical Statements'!I64:I65) -> 1023003.4 | J40: =SUM('Full Historical Statements'!J61:J62,'Full Historical Statements'!J64:J65) -> 1101872.3 | K40: =SUM('Full Historical Statements'!K61:K62,'Full Historical Statements'!K64:K65) -> 1294081.6 | ... M40: =SUM('Full Historical Statements'!M61:M62,'Full Historical Statements'!M64:M65) -> 1502372.3
A41: Total liabilities | D41: =D38+SUM(D39:D40) -> 1530986 | E41: =E38+SUM(E39:E40) -> 3683866 | F41: =F38+SUM(F39:F40) -> 3189911 | G41: =G38+SUM(G39:G40) -> 2976421 | H41: =H38+SUM(H39:H40) -> 2881467 | I41: =I38+SUM(I39:I40) -> 2687216.8 | J41: =J38+SUM(J39:J40) -> 2577496.1 | K41: =K38+SUM(K39:K40) -> 2926106.7 | ... M41: =M38+SUM(M39:M40) -> 2672050.4
A44: Balance Sheet — Stockholders' Equity
A45: Common stock | D45: ='Full Historical Statements'!D69 -> 106 | E45: ='Full Historical Statements'!E69 -> 110 | F45: ='Full Historical Statements'!F69 -> 110 | G45: ='Full Historical Statements'!G69 -> 110 | H45: ='Full Historical Statements'!H69 -> 111 | I45: ='Full Historical Statements'!I69 -> 110 | J45: ='Full Historical Statements'!J69 -> 110 | K45: ='Full Historical Statements'!K69 -> 110 | ... M45: ='Full Historical Statements'!M69 -> 110
A46: Treasury stock, at cost | D46: ='Full Historical Statements'!D70 -> -1684262 | E46: ='Full Historical Statements'!E70 -> -1695501 | F46: ='Full Historical Statements'!F70 -> -1888869 | G46: ='Full Historical Statements'!G70 -> -2453473 | H46: ='Full Historical Statements'!H70 -> -3040416 | I46: ='Full Historical Statements'!I70 -> -2890416 | J46: ='Full Historical Statements'!J70 -> -2740416 | K46: ='Full Historical Statements'!K70 -> -2590416 | ... M46: ='Full Historical Statements'!M70 -> -2290416
A47: Additional paid-in capital | D47: ='Full Historical Statements'!D71 -> 496036 | E47: ='Full Historical Statements'!E71 -> 797614 | F47: ='Full Historical Statements'!F71 -> 826685 | G47: ='Full Historical Statements'!G71 -> 859904 | H47: ='Full Historical Statements'!H71 -> 896605 | I47: ='Full Historical Statements'!I71 -> 929547 | J47: ='Full Historical Statements'!J71 -> 963779 | K47: ='Full Historical Statements'!K71 -> 998404 | ... M47: ='Full Historical Statements'!M71 -> 1066600.3
...

Sheet DCF
B2: Revenue Growth | F2: =F8/E8-1 -> 0.035272277 | G2: =G8/F8-1 -> -0.014982784 | H2: =H8/G8-1 -> -0.006 | I2: 0.06 | J2: 0.06 | K2: 0.06 | L2: 0.07 | M2: 0.08
B3: COGS | C3: (% of Revenue) | E3: =-E9/E8 -> 0.44224723 | F3: =-F9/F8 -> 0.41243429 | G3: =-G9/G8 -> 0.41666396 | H3: =-H9/H8 -> 0.42 | I3: =-I9/I8 -> 0.42 | J3: =-J9/J8 -> 0.43 | K3: =-K9/K8 -> 0.44 | L3: =-L9/L8 -> 0.45 | M3: 0.4
B4: SG&A | C4: (% of Revenue) | E4: =E12/E8 -> 0.29375014 | F4: =F12/F8 -> 0.33257657 | G4: =G12/G8 -> 0.36366082 | H4: =H12/H8 -> 0.32 | I4: =I12/I8 -> 0.33 | J4: =J12/J8 -> 0.36 | K4: =K12/K8 -> 0.36 | L4: =L12/L8 -> 0.35 | M4: 0.3
B6: Depreciation | F6: =F15/E15-1 -> 0.28609311 | G6: =G15/F15-1 -> 0.13519473 | H6: =H15/G15-1 -> 1.1972592 | I6: =I15/H15-1 -> -0.79667233 | J6: =J15/I15-1 -> -0.79727233 | K6: =K15/J15-1 -> 0.53557581 | L6: =L15/K15-1 -> 2.9648697 | M6: 0.049
B8: Revenue | E8: ='Simplified Model'!F7 -> 3962347 | F8: ='Simplified Model'!G7 -> 4102108 | G8: ='Simplified Model'!H7 -> 4040647 | H8: ='Simplified Model'!I7 -> 4016403.1 | I8: ='Simplified Model'!J7 -> 4056567.1 | J8: ='Simplified Model'!K7 -> 4137698.5 | K8: ='Simplified Model'!L7 -> 4220452.5 | L8: ='Simplified Model'!M7 -> 4347066 | M8: =L8*(1+M2) -> 4694831.3
B9: COGS | E9: =-'Simplified Model'!F8 -> -1752337 | F9: =-'Simplified Model'!G8 -> -1691850 | G9: =-'Simplified Model'!H8 -> -1683592 | H9: =-'Simplified Model'!I8 -> -1686889.3 | I9: =-'Simplified Model'!J8 -> -1703758.2 | J9: =-'Simplified Model'!K8 -> -1779210.4 | K9: =-'Simplified Model'!L8 -> -1856999.1 | L9: =-'Simplified Model'!M8 -> -1956179.7 | M9: =L9*(1+M3) -> -2738651.6
B10: Gross Profit | E10: =E8+E9 -> 2210010 | F10: =F8+F9 -> 2410258 | G10: =G8+G9 -> 2357055 | H10: =H8+H9 -> 2329513.8 | I10: =I8+I9 -> 2352808.9 | J10: =J8+J9 -> 2358488.1 | K10: =K8+K9 -> 2363453.4 | L10: =L8+L9 -> 2390886.3 | M10: =M8+M9 -> 1956179.7
B12: SG&A | E12: ='Simplified Model'!F10 -> 1163940 | F12: ='Simplified Model'!G10 -> 1364265 | G12: ='Simplified Model'!H10 -> 1469425 | H12: ='Simplified Model'!I10 -> 1285249 | I12: ='Simplified Model'!J10 -> 1338667.2 | J12: ='Simplified Model'!K10 -> 1489571.5 | K12: ='Simplified Model'!L10 -> 1519362.9 | L12: ='Simplified Model'!M10 -> 1521473.1 | M12: =L12*(1+M4) -> 1977915
B13: EBITDA | E13: =E10-E12-E15 -> 1100374 | F13: =F10-F12-F15 -> 1115833 | G13: =G10-G12-G15 -> 966912 | H13: =H10-H12-H15 -> 1218467.9 | I13: =I10-I12-I15 -> 1049562.1 | J13: =J10-J12-J15 -> 876097.36 | K13: =K10-K12-K15 -> 855116.97 | L13: =L10-L12-L15 -> 913131.74 | M13: =M10-M12-M15 -> 24125.41
B15: Tax Depreciation | E15: =-'Simplified Model'!F57 -> -54304 | F15: =-'Simplified Model'!G57 -> -69840 | G15: =-'Simplified Model'!H57 -> -79282 | H15: =-'Simplified Model'!I57 -> -174203.1 | I15: =-'Simplified Model'!J57 -> -35420.31 | J15: =-'Simplified Model'!K57 -> -7180.677 | K15: =-'Simplified Model'!L57 -> -11026.474 | L15: =-'Simplified Model'!M57 -> -43718.532 | M15: =L15*(1+M6) -> -45860.74
B16: Operating Profit | E16: =E10-E12 -> 1046070 | F16: =F10-F12 -> 1045993 | G16: =G10-G12 -> 887630 | H16: =H10-H12 -> 1044264.8 | I16: =I10-I12 -> 1014141.8 | J16: =J10-J12 -> 868916.68 | K16: =K10-K12 -> 844090.49 | L16: =L10-L12 -> 869413.21 | M16: =M10-M12 -> -21735.33
B18: Tax Rate | E18: ='Full Historical Statements'!F11 -> 0.095525134 | F18: ='Full Historical Statements'!G11 -> 0.043363332 | G18: ='Full Historical Statements'!H11 -> 2.1126367 | H18: ='Full Historical Statements'!I11 -> 0.25 | I18: ='Full Historical Statements'!J11 -> 0.25 | J18: ='Full Historical Statements'!K11 -> 0.25 | K18: ='Full Historical Statements'!L11 -> 0.25 | L18: ='Full Historical Statements'!M11 -> 0.25 | M18: 0.28
B19: Current Tax | E19: =-'Simplified Model'!F18 -> -83706 | F19: =-'Simplified Model'!G18 -> 39486 | G19: =-'Simplified Model'!H18 -> -154176 | H19: =-'Simplified Model'!I18 -> -104245.94 | I19: =-'Simplified Model'!J18 -> -56043.96 | J19: =-'Simplified Model'!K18 -> -124678.49 | K19: =-'Simplified Model'!L18 -> -95692.24 | L19: =-'Simplified Model'!M18 -> -124899.32 | M19: =M16*M18 -> -6085.8925
B24: Unlevered Free Cash Flow Schedule
E27: Year -2 | F27: Year - 1 | G27: Year 0 | H27: Year 1 | I27: Year 2 | J27: Year 3 | K27: Year 4 | L27: Year 5 | M27: Term
B28: Unlevered Free Cash Flow
B29: EBIT | E29: =E16 -> 1046070 | F29: =F16 -> 1045993 | G29: =G16 -> 887630 | H29: =H16 -> 1044264.8 | I29: =I16 -> 1014141.8 | J29: =J16 -> 868916.68 | K29: =K16 -> 844090.49 | L29: =L16 -> 869413.21 | M29: =M16 -> -21735.33
B30: Current Taxes | E30: =E19 -> -83706 | F30: =F19 -> 39486 | G30: =G19 -> -154176 | H30: =H19 -> -104245.94 | I30: =I19 -> -56043.96 | J30: =J19 -> -124678.49 | K30: =K19 -> -95692.24 | L30: =L19 -> -124899.32 | M30: =M19 -> -6085.8925
B31: NOPAT | E31: =SUM(E29:E30) -> 962364 | F31: =SUM(F29:F30) -> 1085479 | G31: =SUM(G29:G30) -> 733454 | H31: =SUM(H29:H30) -> 940018.87 | I31: =SUM(I29:I30) -> 958097.83 | J31: =SUM(J29:J30) -> 744238.19 | K31: =SUM(K29:K30) -> 748398.25 | L31: =SUM(L29:L30) -> 744513.89 | M31: =SUM(M29:M30) -> -27821.223
B32: D&A | E32: =-E15 -> 54304 | F32: =-F15 -> 69840 | G32: =-G15 -> 79282 | H32: =-H15 -> 174203.1 | I32: =-I15 -> 35420.31 | J32: =-J15 -> 7180.677 | K32: =-K15 -> 11026.474 | L32: =-L15 -> 43718.532 | M32: =-M15 -> 45860.74
B33: Capital Expenditure | E33: ='Simplified Model'!F61 -> -115625 | F33: ='Simplified Model'!G61 -> -69347 | G33: ='Simplified Model'!H61 -> -51231 | H33: =-'Simplified Model'!I61 -> -20000 | I33: =-'Simplified Model'!J61 -> -20000 | J33: =-'Simplified Model'!K61 -> -20000 | K33: =-'Simplified Model'!L61 -> -120000 | L33: =-'Simplified Model'!M61 -> -100000 | M33: -70000
B34: Cash from Working Capital | E34: ='Full Historical Statements'!F125 -> -106501 | F34: ='Full Historical Statements'!G125 -> -80813 | G34: ='Full Historical Statements'!H125 -> 31778 | H34: ='Full Historical Statements'!I125 -> 47154.964 | I34: ='Full Historical Statements'!J125 -> 2831.1253 | J34: ='Full Historical Statements'!K125 -> 11789.607 | K34: ='Full Historical Statements'!L125 -> 12088.881 | L34: ='Full Historical Statements'!M125 -> 16974.313 | M34: 46000
B35: Unlevered Free Cash Flow | E35: =SUM(E31:E34) -> 794542 | F35: =SUM(F31:F34) -> 1005159 | G35: =SUM(G31:G34) -> 793283 | H35: =SUM(H31:H34) -> 1141376.9 | I35: =SUM(I31:I34) -> 976349.26 | J35: =SUM(J31:J34) -> 743208.47 | K35: =SUM(K31:K34) -> 651513.61 | L35: =SUM(L31:L34) -> 705206.73 | M35: =SUM(M31:M34) -> -5960.4828
B38: Discounted Cash Flow Schedule
H40: Year 1 | I40: Year 2 | J40: Year 3 | K40: Year 4 | L40: Year 5 | M40: Term
B42: Unlevered Free Cash Flow | H42: 794542 | I42: =I35 -> 976349.26 | J42: =J35 -> 743208.47 | K42: =K35 -> 651513.61 | L42: =L35 -> 705206.73 | M42: =M35 -> -5960.4828
B43: EBITDA | M43: =M13 -> 24125.41
B46: UNDISCOUNTED CASH FLOW
B47: Discrete Forecast | H47: =H42 -> 794542 | I47: =I42 -> 976349.26 | J47: =J42 -> 743208.47 | K47: =K42 -> 651513.61 | L47: =L42 -> 705206.73 | M47: =M42 -> -5960.4828
B48: Terminal Value | H48: 0 | I48: 0 | J48: 0 | K48: 0 | L48: 0 | M48: =M43*C54 -> 1930.0328
B49: Total Cash Flow | H49: =SUM(H47:H48) -> 794542 | I49: =SUM(I47:I48) -> 976349.26 | J49: =SUM(J47:J48) -> 743208.47 | K49: =SUM(K47:K48) -> 651513.61 | L49: =SUM(L47:L48) -> 705206.73 | M49: =SUM(M47:M48) -> -4030.4501
C51: 8
B52: ASSUMPTIONS | F52: ENTERPRISE VALUE | J52: EQUITY VALUE PER SHARE
B53: First Year of Forecast | C53: 2026 | F53: PV of Discrete | H53: =NPV(C55,H47,I47,J47,K47,L47) -> 2862298.8 | J53: Equity Value | M53: =H61 -> 2021526.2
B54: Terminal Multiple | C54: 0.08 | F54: PV of Terminal | H54: =NPV(C55,H48:M48) -> 1002.4352 | J54: Shares Outstanding | L54: (000s) | M54: 54200
B55: Discount Rate | C55: =(C75*C62)+(C81*C68) -> 0.1153677 | F55: Enterprise Value | H55: =H53+H54 -> 2863301.2 | J55: Equity Value | L55: (USD) | M55: =M53/M54 -> 37.297532
B58: COST OF EQUITY | F58: EQUITY VALUE
B59: Risk-free rate (US 10y) | C59: 0.0462 | F59: Enterprise Value | H59: =H55 -> 2863301.2
B60: Beta | C60: 1.55 | F60: Less: Net Debt | H60: =-(1542341-700566) -> -841775
B61: Market risk premium | C61: 0.05 | F61: Equity Value | H61: =SUM(H59:H60) -> 2021526.2
...
