Workbook

Sheet Historical
B1: J Sainsbury plc – Historical Three-Statement Model
B2: FY2022A–FY2026A | £m except per-share data | 2025A uses the latest restated comparative disclosed in FY2026 where available
H3: Live Case | I3: 1 | K3: Share Price | L3: =DCF!N61 -> 3.3806943
D5: 2022A | E5: 2023A | F5: 2024A | G5: 2025A* | H5: 2026A | I5: 2027E | J5: 2028E | K5: 2029E | L5: 2030E | M5: 2031E
B6: Income Statement
B7: Revenue | D7: 29895 | E7: 31491 | F7: 32238 | G7: 32772 | H7: 33647 | I7: =H7*(1+Assumptions!F45+DCF!$W75) -> 29609.36 | J7: =I7*(1+Assumptions!G45+DCF!$W75) -> 29964.672 | K7: =J7*(1+Assumptions!H45+DCF!$W75) -> 30324.248 | L7: =K7*(1+Assumptions!I45+DCF!$W75) -> 30688.139 | M7: =L7*(1+Assumptions!J45+DCF!$W75) -> 31117.773
B8: Revenue growth | E8: =E7/D7-1 -> 0.053386854 | F8: =F7/E7-1 -> 0.023721063 | G8: =G7/F7-1 -> 0.016564303 | H8: =H7/G7-1 -> 0.026699622 | I8: =I7/H7-1 -> -0.12 | J8: =J7/I7-1 -> 0.012 | K8: =K7/J7-1 -> 0.012 | L8: =L7/K7-1 -> 0.012 | M8: =M7/L7-1 -> 0.014
B9: Cost of sales | D9: -27514 | E9: -29409 | F9: -30148 | G9: -30589 | H9: -31441 | I9: =-I7*Assumptions!F46 -> -27655.142 | J9: =-J7*Assumptions!G46 -> -27942.057 | K9: =-K7*Assumptions!H46 -> -28231.875 | L9: =-L7*Assumptions!I46 -> -28539.97 | M9: =-M7*Assumptions!J46 -> -28877.294
B10: Impairment loss on financial assets | D10: -15 | E10: -78 | F10: 0 | G10: 0 | H10: 0 | I10: 0 | J10: 0 | K10: 0 | L10: 0 | M10: 0
B11: Gross profit | D11: =D7+D9+D10 -> 2366 | E11: =E7+E9+E10 -> 2004 | F11: =F7+F9+F10 -> 2090 | G11: =G7+G9+G10 -> 2183 | H11: =H7+H9+H10 -> 2206 | I11: =I7+I9+I10 -> 1954.2178 | J11: =J7+J9+J10 -> 2022.6154 | K11: =K7+K9+K10 -> 2092.3731 | ... M11: =M7+M9+M10 -> 2240.4797
B12: Gross margin | D12: =D11/D7 -> 0.07914367 | E12: =E11/E7 -> 0.06363723 | F12: =F11/F7 -> 0.064830324 | G12: =G11/G7 -> 0.066611742 | H12: =H11/H7 -> 0.065563052 | I12: =I11/I7 -> 0.066 | J12: =J11/J7 -> 0.0675 | K12: =K11/K7 -> 0.069 | ... M12: =M11/M7 -> 0.072
B13: Administrative expenses | D13: -1430 | E13: -1515 | F13: -1404 | G13: -1401 | H13: -1391 | I13: =H13*(1+Assumptions!F47+DCF!$Z75) -> -1365.962 | J13: =I13*(1+Assumptions!G47+DCF!$Z75) -> -1341.3747 | K13: =J13*(1+Assumptions!H47+DCF!$Z75) -> -1317.2299 | L13: =K13*(1+Assumptions!I47+DCF!$Z75) -> -1297.4715 | M13: =L13*(1+Assumptions!J47+DCF!$Z75) -> -1278.0094
B14: Other income | D14: 220 | E14: 73 | F14: 58 | G14: 108 | H14: 82 | I14: =AVERAGE(F14:H14) -> 82.666667 | J14: =AVERAGE(G14:I14) -> 90.888889 | K14: =AVERAGE(H14:J14) -> 85.185185 | L14: =AVERAGE(I14:K14) -> 86.246914 | M14: =AVERAGE(J14:L14) -> 87.440329
B15: Operating profit | D15: =D11+D13+D14 -> 1156 | E15: =E11+E13+E14 -> 562 | F15: =F11+F13+F14 -> 744 | G15: =G11+G13+G14 -> 890 | H15: =H11+H13+H14 -> 897 | I15: =I11+I13+I14 -> 670.92243 | J15: =J11+J13+J14 -> 772.12959 | K15: =K11+K13+K14 -> 860.32838 | ... M15: =M11+M13+M14 -> 1049.9106
B16: Operating margin | D16: =D15/D7 -> 0.038668674 | E16: =E15/E7 -> 0.017846369 | F16: =F15/F7 -> 0.023078355 | G16: =G15/G7 -> 0.027157329 | H16: =H15/H7 -> 0.026659138 | I16: =I15/I7 -> 0.022659133 | J16: =J15/J7 -> 0.025767997 | K16: =K15/K7 -> 0.028370971 | ... M16: =M15/M7 -> 0.033739901
B17: Finance income | D17: 20 | E17: 74 | F17: 81 | G17: 67 | H17: 64 | I17: =AVERAGE(F17:H17) -> 70.666667 | J17: =AVERAGE(G17:I17) -> 67.222222 | K17: =AVERAGE(H17:J17) -> 67.296296 | L17: =AVERAGE(I17:K17) -> 68.395062 | M17: =AVERAGE(J17:L17) -> 67.63786
B18: Finance costs | D18: -322 | E18: -309 | F18: -336 | G18: -350 | H18: -342 | I18: =I90 -> -260.9735 | J18: =J90 -> -256.74318 | K18: =K90 -> -239.6947 | L18: =L90 -> -235.0361 | M18: =M90 -> -228.01614
B19: Profit before tax – continuing operations | D19: =D15+D17+D18 -> 854 | E19: =E15+E17+E18 -> 327 | F19: =F15+F17+F18 -> 489 | G19: =G15+G17+G18 -> 607 | H19: =H15+H17+H18 -> 619 | I19: =I15+I17+I18 -> 480.61559 | J19: =J15+J17+J18 -> 582.60863 | K19: =K15+K17+K18 -> 687.92998 | ... M19: =M15+M17+M18 -> 889.53231
B20: Income tax expense | D20: -177 | E20: -120 | F20: -181 | G20: -186 | H20: -205 | I20: =-I19*I22+I91 -> -204.35515 | J20: =-J19*J22+J91 -> -236.43476 | K20: =-K19*K22+K91 -> -270.13759 | L20: =-L19*L22+L91 -> -296.49733 | M20: =-M19*M22+M91 -> -334.65034
B21: Profit after tax – continuing operations | D21: =D19+D20 -> 677 | E21: =E19+E20 -> 207 | F21: =F19+F20 -> 308 | G21: =G19+G20 -> 421 | H21: =H19+H20 -> 414 | I21: =I19+I20 -> 276.26045 | J21: =J19+J20 -> 346.17387 | K21: =K19+K20 -> 417.79239 | ... M21: =M19+M20 -> 554.88197
B22: Effective tax rate | D22: =IFERROR(-D20/D19,"") -> 0.20725995 | E22: =IFERROR(-E20/E19,"") -> 0.36697248 | F22: =IFERROR(-F20/F19,"") -> 0.37014315 | G22: =IFERROR(-G20/G19,"") -> 0.30642504 | H22: =IFERROR(-H20/H19,"") -> 0.33117932 | I22: =Assumptions!F55 -> 0.32 | J22: =Assumptions!G55 -> 0.32 | K22: =Assumptions!H55 -> 0.32 | L22: =Assumptions!I55 -> 0.32 | M22: =Assumptions!J55 -> 0.32
B23: Profit after tax – discontinued operations | D23: 0 | E23: 0 | F23: -171 | G23: -168 | H23: -21 | I23: -700 | J23: 0 | K23: 0 | L23: 0 | M23: 0
B24: Profit for the financial period | D24: =D21+D23 -> 677 | E24: =E21+E23 -> 207 | F24: =F21+F23 -> 137 | G24: =G21+G23 -> 253 | H24: =H21+H23 -> 393 | I24: =I21+I23 -> -423.73955 | J24: =J21+J23 -> 346.17387 | K24: =K21+K23 -> 417.79239 | ... M24: =M21+M23 -> 554.88197
B25: Net margin | D25: =D24/D7 -> 0.022645927 | E25: =E24/E7 -> 0.0065733067 | F25: =F24/F7 -> 0.0042496433 | G25: =G24/G7 -> 0.0077200049 | H25: =H24/H7 -> 0.01168009 | I25: =I24/I7 -> -0.014311 | J25: =J24/J7 -> 0.011552733 | K25: =K24/K7 -> 0.013777502 | ... M25: =M24/M7 -> 0.017831673
B26: Basic EPS – total (p) | D26: 29.8 | E26: 9 | F26: 5.9 | G26: 10.9 | H26: 17.3
B27: Diluted EPS – total (p) | D27: 28.8 | E27: 8.8 | F27: 5.7 | G27: 10.7 | H27: 16.9
B30: Balance Sheet
B31: Property, plant and equipment | D31: 8402 | E31: 8201 | F31: 9282 | G31: 9358 | H31: 9386 | I31: ='Supporting Schedules'!H76 -> 9042.75 | J31: ='Supporting Schedules'!I76 -> 8851.5 | K31: ='Supporting Schedules'!J76 -> 8660.25 | L31: ='Supporting Schedules'!K76 -> 8469 | M31: ='Supporting Schedules'!L76 -> 8277.75
B32: Right-of-use assets | D32: 5560 | E32: 5345 | F32: 4296 | G32: 4455 | H32: 4486 | I32: ='Supporting Schedules'!H60 -> 4167.68 | J32: ='Supporting Schedules'!I60 -> 3887.5584 | K32: ='Supporting Schedules'!J60 -> 3641.0514 | L32: ='Supporting Schedules'!K60 -> 3424.1252 | M32: ='Supporting Schedules'!L60 -> 3233.2302
B33: Intangible assets | D33: 1006 | E33: 1024 | F33: 806 | G33: 807 | H33: 838 | I33: ='Supporting Schedules'!H93 -> 848 | J33: ='Supporting Schedules'!I93 -> 839 | K33: ='Supporting Schedules'!J93 -> 807.2 | L33: ='Supporting Schedules'!K93 -> 748.04 | M33: ='Supporting Schedules'!L93 -> 656.048
B34: Investments in joint ventures and associates | D34: 3 | E34: 2 | F34: 2 | G34: 2 | H34: 2 | I34: 2 | J34: 2 | K34: 2 | L34: 2 | M34: 2
B35: Other financial assets / FVOCI – non-current | D35: 604 | E35: 515 | F35: 761 | G35: 769 | H35: 129 | I35: =H35 -> 129 | J35: =I35 -> 129 | K35: =J35 -> 129 | L35: =K35 -> 129 | M35: =L35 -> 129
B36: Trade and other receivables – non-current | D36: 65 | E36: 56 | F36: 108 | G36: 42 | H36: 22 | I36: =H36 -> 22 | J36: =I36 -> 22 | K36: =J36 -> 22 | L36: =K36 -> 22 | M36: =L36 -> 22
B37: Financial Services receivables – non-current | D37: 2026 | E37: 1908 | F37: 1467 | G37: 0 | H37: 0 | I37: 0 | J37: 0 | K37: 0 | L37: 0 | M37: 0
B38: Derivative financial assets – non-current | D38: 213 | E38: 217 | F38: 68 | G38: 35 | H38: 18 | I38: =H38 -> 18 | J38: =I38 -> 18 | K38: =J38 -> 18 | L38: =K38 -> 18 | M38: =L38 -> 18
B39: Net retirement benefit surplus | D39: 2283 | E39: 989 | F39: 690 | G39: 754 | H39: 548 | I39: =H39 -> 548 | J39: =I39 -> 548 | K39: =J39 -> 548 | L39: =K39 -> 548 | M39: =L39 -> 548
B40: Total non-current assets | D40: =SUM(D31:D39) -> 20162 | E40: =SUM(E31:E39) -> 18257 | F40: =SUM(F31:F39) -> 17480 | G40: =SUM(G31:G39) -> 16222 | H40: =SUM(H31:H39) -> 15429 | I40: =SUM(I31:I39) -> 14777.43 | J40: =SUM(J31:J39) -> 14297.058 | K40: =SUM(K31:K39) -> 13827.501 | ... M40: =SUM(M31:M39) -> 12886.028
B41: Inventories | D41: 1797 | E41: 1899 | F41: 1927 | G41: 1946 | H41: 1987 | I41: ='Supporting Schedules'!H64 -> 1515.3503 | J41: ='Supporting Schedules'!I64 -> 1377.9645 | K41: ='Supporting Schedules'!J64 -> 1237.5617 | L41: ='Supporting Schedules'!K64 -> 1211.9713 | M41: ='Supporting Schedules'!L64 -> 1186.7381
B42: Trade and other receivables – current | D42: 683 | E42: 627 | F42: 582 | G42: 572 | H42: 431 | I42: ='Supporting Schedules'!H65 -> 405.60767 | J42: ='Supporting Schedules'!I65 -> 410.47496 | K42: ='Supporting Schedules'!J65 -> 415.40066 | L42: ='Supporting Schedules'!K65 -> 420.38547 | M42: ='Supporting Schedules'!L65 -> 426.27087
B43: Financial Services receivables – current | D43: 3163 | E43: 3484 | F43: 3050 | G43: 0 | H43: 0 | I43: 0 | J43: 0 | K43: 0 | L43: 0 | M43: 0
...

Sheet Assumptions
E1: Assumptions | F1: 2027 | G1: 2028 | H1: 2029 | I1: 2030 | J1: 2031
E2: Base Case
B3: Cases | E3: Revenue | F3: -0.12 | G3: 0.012 | H3: 0.012 | I3: 0.012 | J3: 0.014
C4: 1 | E4: Cost of Sales | F4: 0.934 | G4: 0.9325 | H4: 0.931 | I4: 0.93 | J4: 0.928
C5: 2 | E5: Admin Expenses | F5: -0.018 | G5: -0.018 | H5: -0.018 | I5: -0.015 | J5: -0.015
C6: 3 | E6: Inventory | F6: 20 | G6: 18 | H6: 16 | I6: 15.5 | J6: 15
E7: Trade and other receivables | F7: 5 | G7: 5 | H7: 5 | I7: 5 | J7: 5
E8: Trade and other payables | F8: 64 | G8: 64 | H8: 64 | I8: 64 | J8: 64
E9: Operating provisions | F9: -130 | G9: -120 | H9: -110 | I9: -110 | J9: -110
E10: Depreciation & Amortisation | F10: 1200 | G10: 1200 | H10: 1200 | I10: 1200 | J10: 1200
E11: CapEx | F11: 825 | G11: 825 | H11: 825 | I11: 825 | J11: 825
E12: Dividend paid | F12: 600 | G12: 600 | H12: 600 | I12: 680 | J12: 730
E13: Tax Rate | F13: 0.32 | G13: 0.32 | H13: 0.32 | I13: 0.32 | J13: 0.32
E14: D&A | F14: 1200 | G14: 1200 | H14: 1200 | I14: 1200 | J14: 1200
E16: Downside Case
E17: Revenue | F17: -0.135 | G17: 0.003 | H17: 0.005 | I17: 0.007 | J17: 0.008
E18: Cost of Sales | F18: 0.94 | G18: 0.94 | H18: 0.939 | I18: 0.938 | J18: 0.937
E19: Admin Expenses | F19: 0 | G19: -0.005 | H19: -0.005 | I19: -0.01 | J19: -0.01
E20: Inventory | F20: 22 | G20: 21 | H20: 20 | I20: 19 | J20: 18
E21: Trade and other receivables | F21: 6 | G21: 6 | H21: 6 | I21: 6 | J21: 6
E22: Trade and other payables | F22: 60 | G22: 60 | H22: 60 | I22: 60 | J22: 60
E23: Operating provisions | F23: -180 | G23: -170 | H23: -150 | I23: -130 | J23: -120
E24: Depreciation & Amortisation | F24: 1200 | G24: 1200 | H24: 1200 | I24: 1200 | J24: 1200
E25: CapEx | F25: 900 | G25: 900 | H25: 875 | I25: 875 | J25: 850
E26: Dividend paid | F26: 450 | G26: 500 | H26: 525 | I26: 550 | J26: 575
E27: Tax Rate | F27: 0.32 | G27: 0.32 | H27: 0.32 | I27: 0.32 | J27: 0.32
E29: Upside Case
E30: Revenue | F30: -0.105 | G30: 0.02 | H30: 0.022 | I30: 0.023 | J30: 0.025
E31: Cost of Sales | F31: 0.93 | G31: 0.927 | H31: 0.925 | I31: 0.923 | J31: 0.921
E32: Admin Expenses | F32: -0.03 | G32: -0.03 | H32: -0.025 | I32: -0.025 | J32: -0.02
E33: Inventory | F33: 18 | G33: 16 | H33: 15 | I33: 14.5 | J33: 14
E34: Trade and other receivables | F34: 4.5 | G34: 4.5 | H34: 4.5 | I34: 4.5 | J34: 4.5
E35: Trade and other payables | F35: 65 | G35: 65 | H35: 65 | I35: 65 | J35: 65
E36: Operating provisions | F36: -100 | G36: -90 | H36: -80 | I36: -80 | J36: -80
E37: Depreciation & Amortisation | F37: 1200 | G37: 1200 | H37: 1200 | I37: 1200 | J37: 1200
E38: CapEx | F38: 800 | G38: 800 | H38: 800 | I38: 800 | J38: 800
E39: Dividend paid | F39: 650 | G39: 650 | H39: 700 | I39: 750 | J39: 800
E40: Tax Rate | F40: 0.32 | G40: 0.32 | H40: 0.32 | I40: 0.32 | J40: 0.32
E44: Live Case | K44: Rationale
E45: Revenue | F45: =CHOOSE(Historical!$I$3,Assumptions!F3,Assumptions!F17,Assumptions!F30) -> -0.12 | G45: =CHOOSE(Historical!$I$3,Assumptions!G3,Assumptions!G17,Assumptions!G30) -> 0.012 | H45: =CHOOSE(Historical!$I$3,Assumptions!H3,Assumptions!H17,Assumptions!H30) -> 0.012 | I45: =CHOOSE(Historical!$I$3,Assumptions!I3,Assumptions!I17,Assumptions!I30) -> 0.012 | J45: =CHOOSE(Historical!$I$3,Assumptions!J3,Assumptions!J17,Assumptions!J30) -> 0.014 | K45: "Next Level Sainsbury's" blueprint aims to priortise volume increases ahead of price inflation (2.6%). Aim to grow revenue by winning big weekly shops (£80+ baskets) from competitors through aggressive value scheme like Nectar Prices and the Aldi Price Match, which will force internal price deflation. Rapid home delivery serves as a major growth vector for digital sales. Sainsbury's commerce divison expanded by 69% in 2026. Argos sales have fell 0.5% due to cautious consumer spending, and is expected to reamin a heavy drag on total revenue. Argos sale expected to finalise in 2027. We can expect to see a signficant drop in revenue as the retail brought in roughly 4bn to the top-line revenue
...

Sheet DCF
F3: Year -2 | G3: Year -1 | H3: Year 0 | I3: Year 1 | J3: Year 2 | K3: Year 3 | L3: Year 4 | M3: Year 5 | N3: Term
B5: Revenue Growth | G5: =G11/F11-1 -> 0.016564303 | H5: =H11/G11-1 -> 0.026699622 | I5: =I11/H11-1 -> -0.12 | J5: =J11/I11-1 -> 0.012 | K5: =K11/J11-1 -> 0.012 | L5: =L11/K11-1 -> 0.012 | M5: =M11/L11-1 -> 0.014 | N5: 0.02
B6: COGS | C6: (% of Revenue) | F6: =-F12/F11 -> 0.93516968 | G6: =-G12/G11 -> 0.93338826 | H6: =-H12/H11 -> 0.93443695 | I6: =-I12/I11 -> 0.934 | J6: =-J12/J11 -> 0.9325 | K6: =-K12/K11 -> 0.931 | L6: =-L12/L11 -> 0.93 | M6: =-M12/M11 -> 0.928 | N6: 0.928
B7: Expenses | C7: (% of Revenue) | F7: =F15/F11 -> 0.04175197 | G7: =G15/G11 -> 0.039454412 | H7: =H15/H11 -> 0.038903914 | I7: =I15/I11 -> 0.043340867 | J7: =J15/J11 -> 0.041732003 | K7: =K15/K11 -> 0.040629029 | L7: =L15/L11 -> 0.039468818 | M7: =M15/M11 -> 0.038260099 | N7: 0.035
B9: Depreciation Growth | G9: =G18/F18-1 -> 0.045546559 | H9: =H18/G18-1 -> 0.0058083253 | I9: =I18/H18-1 -> -0.018286814 | J9: =J18/I18-1 -> 0 | K9: =K18/J18-1 -> 0 | L9: =L18/K18-1 -> 0 | M9: =M18/L18-1 -> 0 | N9: 0
B11: Revenue | F11: =Historical!F7 -> 32238 | G11: =Historical!G7 -> 32772 | H11: =Historical!H7 -> 33647 | I11: =Historical!I7 -> 29609.36 | J11: =Historical!J7 -> 29964.672 | K11: =Historical!K7 -> 30324.248 | L11: =Historical!L7 -> 30688.139 | M11: =Historical!M7 -> 31117.773 | N11: =M11*(1+N5) -> 31740.129
B12: COGS | F12: =Historical!F9 -> -30148 | G12: =Historical!G9 -> -30589 | H12: =Historical!H9 -> -31441 | I12: =Historical!I9 -> -27655.142 | J12: =Historical!J9 -> -27942.057 | K12: =Historical!K9 -> -28231.875 | L12: =Historical!L9 -> -28539.97 | M12: =Historical!M9 -> -28877.294 | N12: =-N11*N6 -> -29454.84
B13: Gross Profit | F13: =F11+F12 -> 2090 | G13: =G11+G12 -> 2183 | H13: =H11+H12 -> 2206 | I13: =I11+I12 -> 1954.2178 | J13: =J11+J12 -> 2022.6154 | K13: =K11+K12 -> 2092.3731 | L13: =L11+L12 -> 2148.1698 | M13: =M11+M12 -> 2240.4797 | N13: =N11+N12 -> 2285.2893
B15: Expenses | F15: =-SUM(Historical!F13:F14) -> 1346 | G15: =-SUM(Historical!G13:G14) -> 1293 | H15: =-SUM(Historical!H13:H14) -> 1309 | I15: =-SUM(Historical!I13:I14) -> 1283.2953 | J15: =-SUM(Historical!J13:J14) -> 1250.4858 | K15: =-SUM(Historical!K13:K14) -> 1232.0448 | L15: =-SUM(Historical!L13:L14) -> 1211.2246 | M15: =-SUM(Historical!M13:M14) -> 1190.5691 | N15: =N11*N7 -> 1110.9045
B16: EBIT | F16: =F13-F15 -> 744 | G16: =G13-G15 -> 890 | H16: =H13-H15 -> 897 | I16: =I13-I15 -> 670.92243 | J16: =J13-J15 -> 772.12959 | K16: =K13-K15 -> 860.32838 | L16: =L13-L15 -> 936.94518 | M16: =M13-M15 -> 1049.9106 | N16: =N13-N15 -> 1174.3848
B18: Depreciation | F18: ='Supporting Schedules'!E75 -> 988 | G18: ='Supporting Schedules'!F75 -> 1033 | H18: ='Supporting Schedules'!G75 -> 1039 | I18: ='Supporting Schedules'!H75 -> 1020 | J18: ='Supporting Schedules'!I75 -> 1020 | K18: ='Supporting Schedules'!J75 -> 1020 | L18: ='Supporting Schedules'!K75 -> 1020 | M18: ='Supporting Schedules'!L75 -> 1020 | N18: =M18*(1+N9) -> 1020
B19: EBITDA | F19: =F16+F18 -> 1732 | G19: =G16+G18 -> 1923 | H19: =H16+H18 -> 1936 | I19: =I16+I18 -> 1690.9224 | J19: =J16+J18 -> 1792.1296 | K19: =K16+K18 -> 1880.3284 | L19: =L16+L18 -> 1956.9452 | M19: =M16+M18 -> 2069.9106 | N19: =N16+N18 -> 2194.3848
B21: Tax Rate | F21: =Historical!F22 -> 0.37014315 | G21: =Historical!G22 -> 0.30642504 | H21: =Historical!H22 -> 0.33117932 | I21: =Historical!I22 -> 0.32 | J21: =Historical!J22 -> 0.32 | K21: =Historical!K22 -> 0.32 | L21: =Historical!L22 -> 0.32 | M21: =Historical!M22 -> 0.32 | N21: 0.32
B22: Current Tax | F22: =-Historical!F20 -> 181 | G22: =-Historical!G20 -> 186 | H22: =-Historical!H20 -> 205 | I22: =-Historical!I20 -> 204.35515 | J22: =-Historical!J20 -> 236.43476 | K22: =-Historical!K20 -> 270.13759 | L22: =-Historical!L20 -> 296.49733 | M22: =-Historical!M20 -> 334.65034 | N22: =N16*N21 -> 375.80312
B27: UNLEVERED FREE CASH FLOW
F30: Year -2 | G30: Year -1 | H30: Year 0 | I30: Year 1 | J30: Year 2 | K30: Year 3 | L30: Year 4 | M30: Year 5 | N30: Term
B31: Unlevered Free Cash Flow
B32: EBIT | F32: =F16 -> 744 | G32: =G16 -> 890 | H32: =H16 -> 897 | I32: =I16 -> 670.92243 | J32: =J16 -> 772.12959 | K32: =K16 -> 860.32838 | L32: =L16 -> 936.94518 | M32: =M16 -> 1049.9106 | N32: =N16 -> 1174.3848
B33: Tax Rate | F33: =F21 -> 0.37014315 | G33: =G21 -> 0.30642504 | H33: =H21 -> 0.33117932 | I33: =I21 -> 0.32 | J33: =J21 -> 0.32 | K33: =K21 -> 0.32 | L33: =L21 -> 0.32 | M33: =M21 -> 0.32 | N33: 0.32
B34: NOPAT | F34: =F32*(1-F33) -> 468.6135 | G34: =G32*(1-G21) -> 617.28171 | H34: =H32*(1-H21) -> 599.93215 | I34: =I32*(1-I21) -> 456.22725 | J34: =J32*(1-J21) -> 525.04812 | K34: =K32*(1-K21) -> 585.0233 | L34: =L32*(1-L21) -> 637.12272 | M34: =M32*(1-M21) -> 713.9392 | N34: =N32*(1-N33) -> 798.58164
B35: D&A | F35: =Historical!F86 -> 1160 | G35: =Historical!G86 -> 1215 | H35: =Historical!H86 -> 1238 | I35: =Historical!I86 -> 1200 | J35: =Historical!J86 -> 1200 | K35: =Historical!K86 -> 1200 | L35: =Historical!L86 -> 1200 | M35: =Historical!M86 -> 1200 | N35: 1200
B36: Capital Expenditure | F36: =-'Supporting Schedules'!E74 -> -1559 | G36: =-'Supporting Schedules'!F74 -> -825 | H36: =-'Supporting Schedules'!G74 -> -843 | I36: =-'Supporting Schedules'!H74 -> -828.75 | J36: =-'Supporting Schedules'!I74 -> -828.75 | K36: =-'Supporting Schedules'!J74 -> -828.75 | L36: =-'Supporting Schedules'!K74 -> -828.75 | M36: =-'Supporting Schedules'!L74 -> -828.75 | N36: -825
B37: Change in Working Capital | F37: ='Supporting Schedules'!E69 -> -244 | G37: ='Supporting Schedules'!F69 -> -506 | H37: ='Supporting Schedules'!G69 -> -86 | I37: ='Supporting Schedules'!H69 -> 228.8371 | J37: ='Supporting Schedules'!I69 -> -172.82685 | K37: ='Supporting Schedules'!J69 -> -176.29455 | L37: ='Supporting Schedules'!K69 -> -74.62756 | M37: ='Supporting Schedules'!L69 -> -78.495048 | N37: -85
B38: Lease liability repayments | F38: =Historical!F106 -> -507 | G38: =Historical!G106 -> -487 | H38: =Historical!H106 -> -504 | I38: =Historical!I106 -> -490.4 | J38: =Historical!J106 -> -492.832 | K38: =Historical!K106 -> -495.45856 | L38: =Historical!L106 -> -498.29524 | M38: =Historical!M106 -> -501.35886 | N38: -610
B39: Unlevered Free Cash Flow | F39: =F34+F35+F36-F37+F38 -> -193.3865 | G39: =G34+G35+G36-G37+G38 -> 1026.2817 | H39: =H34+H35+H36-H37+H38 -> 576.93215 | I39: =I34+I35+I36-I37+I38 -> 108.24015 | J39: =J34+J35+J36-J37+J38 -> 576.29297 | K39: =K34+K35+K36-K37+K38 -> 637.1093 | L39: =L34+L35+L36-L37+L38 -> 584.70504 | M39: =M34+M35+M36-M37+M38 -> 662.32538 | N39: =N34+N35+N36-N37+N38 -> 648.58164
B43: DISCOUNTED CASH FLOW SCHEDULE
I45: Year 1 | J45: Year 2 | K45: Year 3 | L45: Year 4 | M45: Year 5 | N45: Term
B47: Unlevered Free Cash Flow | I47: =I39 -> 108.24015 | J47: =J39 -> 576.29297 | K47: =K39 -> 637.1093 | L47: =L39 -> 584.70504 | M47: =M39 -> 662.32538 | N47: =N39 -> 648.58164
B48: EBITDA | N48: =N19 -> 2194.3848
B51: UNDISCOUNTED CASH FLOW
B52: Discrete Forecast | I52: =I47 -> 108.24015 | J52: =J47 -> 576.29297 | K52: =K47 -> 637.1093 | L52: =L47 -> 584.70504 | M52: =M47 -> 662.32538 | N52: =N47 -> 648.58164
B53: Terminal Value | I53: 0 | J53: 0 | K53: 0 | L53: 0 | M53: 0 | N53: =(N52*(1+D61))/(D62-D61) -> 8682.387
B54: Total Cash Flow | I54: =SUM(I52:I53) -> 108.24015 | J54: =SUM(J52:J53) -> 576.29297 | K54: =SUM(K52:K53) -> 637.1093 | L54: =SUM(L52:L53) -> 584.70504 | M54: =SUM(M52:M53) -> 662.32538 | N54: =SUM(N52:N53) -> 9330.9687
B58: ASSUMPTIONS | G58: ENTERPRISE VALUE | K58: EQUITY VALUE PER SHARE
B59: First Year of Forecast | D59: 2026 | G59: PV of Discrete | I59: =NPV(D62,I52,J52,K52,L52,M52) -> 1885.3757 | K59: Equity Value | N59: =I75 -> 7376.675
B60: Terminal Multiple | G60: PV of Terminal | I60: =NPV(D62,0,0,0,0,N53) -> 5485.2993 | K60: Shares Outstanding | N60: =D80 -> 2182
B61: Growth Rate | D61: =2%+Q75 -> 0.02 | G61: Enterprise Value | I61: =I59+I60 -> 7370.675 | K61: Instrinsic Value per Share | N61: =N59/N60 -> 3.3806943
B62: Discount Rate | D62: =(D82*D69)+(D88*D75)+T75 -> 0.096194861
R63: Share Price Sensitivity
T64: Growth Rate
...

Sheet Supporting Schedules
B1: J Sainsbury plc – Supporting Schedules
C3: 2022A | D3: 2023A | E3: 2024A | F3: 2025A* | G3: 2026A | H3: 2027E | I3: 2028E | J3: 2029E | K3: 2030E | L3: 2031E
B5: Borrowings Schedule
B6: Opening borrowings | C6: 1104 | D6: =C10 -> 761 | E6: =D10 -> 656 | F6: =E10 -> 1195 | G6: =F10 -> 1114 | H6: =G10 -> 1061 | I6: =H10 -> 983.8 | J6: =I10 -> 781.6 | K6: =J10 -> 704.4 | L6: =K10 -> 627.2
B7: New borrowings | C7: =Historical!D101 -> 0 | D7: =Historical!E101 -> 0 | E7: =Historical!F101 -> 575 | F7: =Historical!G101 -> 544 | G7: =Historical!H101 -> 0 | H7: =SUM(H15,H19,H22,H25,H29,H33) -> 0 | I7: =SUM(I15,I19,I22,I25,I29,I33) -> 0 | J7: =SUM(J15,J19,J22,J25,J29,J33) -> 0 | K7: =SUM(K15,K19,K22,K25,K29,K33) -> 250 | L7: =SUM(L15,L19,L22,L25,L29,L33) -> 0
B8: Repayments | C8: =Historical!D102 -> -248 | D8: =Historical!E102 -> -95 | E8: =Historical!F102 -> -41 | F8: =Historical!G102 -> -623 | G8: =Historical!H102 -> -59 | H8: =SUM(H16,H20,H23,H26,H30,H34) -> -77.2 | I8: =SUM(I16,I20,I23,I26,I30,I34) -> -202.2 | J8: =SUM(J16,J20,J23,J26,J30,J34) -> -77.2 | K8: =SUM(K16,K20,K23,K26,K30,K34) -> -327.2 | L8: =SUM(L16,L20,L23,L26,L30,L34) -> -77.2
B9: Other / classification changes | C9: =C10-SUM(C6:C8) -> -95 | D9: =D10-SUM(D6:D8) -> -10 | E9: =E10-SUM(E6:E8) -> 5 | F9: =F10-SUM(F6:F8) -> -2 | G9: =G10-SUM(G6:G8) -> 6 | H9: 0 | I9: 0 | J9: 0 | K9: 0 | L9: 0
B10: Closing borrowings | C10: =Historical!D132 -> 761 | D10: =Historical!E132 -> 656 | E10: =Historical!F132 -> 1195 | F10: =Historical!G132 -> 1114 | G10: =Historical!H132 -> 1061 | H10: =SUM(H6:H9) -> 983.8 | I10: =SUM(I6:I9) -> 781.6 | J10: =SUM(J6:J9) -> 704.4 | K10: =SUM(K6:K9) -> 627.2 | L10: =SUM(L6:L9) -> 550
B11: Interest Expense | G11: 50 | H11: =SUM(H17,H27,H31,H35) -> 51.3735 | I11: =SUM(I17,I27,I31,I35) -> 49.57518 | J11: =SUM(J17,J27,J31,J35) -> 35.15326 | K11: =SUM(K17,K27,K31,K35) -> 33.33134 | L11: =SUM(L17,L27,L31,L35) -> 29.375
B13: Debt
B14: Loan (due in 2031 at a 2.36% rate (principal and interst rae uplifted annually by RPI subject to a cap at 5% and floor at 0%))
B15: New Borrowings | C15: 0 | D15: 0 | E15: 0 | F15: 0 | G15: 0 | H15: 0 | I15: 0 | J15: 0 | K15: 0 | L15: 0
B16: Repayments | C16: -45 | D16: -48 | E16: -41 | F16: -52 | G16: -59 | H16: =-386/5 -> -77.2 | I16: =-(386+H16)/4 -> -77.2 | J16: =-(386+I16)/4 -> -77.2 | K16: =-(386+J16)/4 -> -77.2 | L16: =-(386+K16)/4 -> -77.2
B17: Interest | H17: =385*2.36% -> 9.086 | I17: =(386+I16)*2.36% -> 7.28768 | J17: =(386+J16+I16)*2.36% -> 5.46576 | K17: =(386+K16+J16+I16)*2.36% -> 3.64384
B18: Revolving Credit (Facility A due in 2029: 500m)
B19: New Borrowings | C19: 0 | D19: 0 | E19: 0 | F19: 0 | G19: 0 | H19: 0 | I19: 0 | J19: 0
B20: Repayments | C20: 0 | D20: 0 | E20: 0 | F20: 0 | G20: 0 | H20: 0 | I20: 0 | J20: 0
B21: Revolving Credit (Facility B due in 2028: 500m)
B22: New Borrowings | C22: 0 | D22: 0 | E22: 0 | F22: 0 | G22: 0 | H22: 0 | I22: 0
B23: Repayments | C23: 0 | D23: 0 | E23: 0 | F23: 0 | G23: 0 | H23: 0 | I23: 0
B24: Unsecured Bond (£250m 5-year due in 2030 5.125%)
B25: New Borrowings | C25: 0 | D25: 0 | E25: 0 | F25: 250 | G25: 0 | H25: 0 | I25: 0 | J25: 0 | K25: 250
B26: Repayments | C26: 0 | D26: 0 | E26: 0 | F26: 0 | G26: 0 | H26: 0 | I26: 0 | J26: 0 | K26: -250
B27: Interest | G27: =250*5.125% -> 12.8125 | H27: =250*5.125% -> 12.8125 | I27: =250*5.125% -> 12.8125 | J27: =250*5.125% -> 12.8125 | K27: =250*5.125% -> 12.8125 | L27: =250*5% -> 12.5
B28: Unsecured Bond (£300m 10-year due in 2035 5.625%)
B29: New Borrowings | C29: 0 | D29: 0 | E29: 0 | F29: 300 | G29: 0 | H29: 0 | I29: 0 | J29: 0 | K29: 0 | L29: 0
B30: Repayments | C30: 0 | D30: 0 | E30: 0 | F30: 0 | G30: 0 | H30: 0 | I30: 0 | J30: 0 | K30: 0 | L30: 0
B31: Interest | G31: =300*5.625% -> 16.875 | H31: =300*5.625% -> 16.875 | I31: =300*5.625% -> 16.875 | J31: =300*5.625% -> 16.875 | K31: =300*5.625% -> 16.875 | L31: =300*5.625% -> 16.875
B32: Bank Tier 2 Capital (£120m 10.5% due in 2028)
B33: New Borrowings | C33: 0 | D33: 120 | E33: 0 | F33: 0 | G33: 0 | H33: 0 | I33: 0
B34: Repayments | C34: 0 | D34: -175 | E34: 0 | F34: 0 | G34: 0 | H34: 0 | I34: -125
B35: Interest | E35: =120*10.5% -> 12.6 | F35: =120*10.5% -> 12.6 | G35: =120*10.5% -> 12.6 | H35: =120*10.5% -> 12.6 | I35: =120*10.5% -> 12.6
B37: Current liabilities | H37: =386+H16 -> 308.8 | I37: =H37+I16 -> 231.6 | J37: =I37+J16 -> 154.4 | K37: =J37+K16 -> 77.2 | L37: =K37+L16 -> 0
B38: Non-current liabilities | H38: =F25+F29+D33+H37 -> 978.8 | I38: =F25+F29+I37 -> 781.6 | J38: =F25+F29+J37 -> 704.4 | K38: =F29+K25+K37 -> 627.2 | L38: =F29+K25 -> 550
B41: Lease Liability Schedule
B42: Opening lease liabilities | C42: 5834 | D42: =C45 -> 6621 | E42: =D45 -> 6489 | F42: =E45 -> 5354 | G42: =F45 -> 5494 | H42: =G45-300 -> 5240 | I42: =H45 -> 5179.2 | J42: =I45 -> 5113.536 | K42: =J45 -> 5042.6189 | L42: =K45 -> 4966.0284
B43: Principal repayments | C43: =-(C47-C48) -> -493 | D43: =-(D47-D48) -> -514 | E43: =-(E47-E48) -> -507 | F43: =-(F47-F48) -> -487 | G43: =-(G47-G48) -> -504 | H43: =-(H47-H48) -> -490.4 | I43: =-(I47-I48) -> -492.832 | J43: =-(J47-J48) -> -495.45856 | ... L43: =-(L47-L48) -> -501.35886
B44: New leases / interest / remeasurements / other | C44: =C45-SUM(C42:C43) -> 1280 | D44: =D45-SUM(D42:D43) -> 382 | E44: =E45-SUM(E42:E43) -> -628 | F44: =F45-SUM(F42:F43) -> 627 | G44: =G45-SUM(G42:G43) -> 550 | H44: =220+H48 -> 429.6 | I44: =220+I48 -> 427.168 | J44: =220+J48 -> 424.54144 | K44: =220+K48 -> 421.70476 | L44: =220+L48 -> 418.64114
B45: Closing lease liabilities | C45: =Historical!D133 -> 6621 | D45: =Historical!E133 -> 6489 | E45: =Historical!F133 -> 5354 | F45: =Historical!G133 -> 5494 | G45: =Historical!H133 -> 5540 | H45: =SUM(H42:H44) -> 5179.2 | I45: =SUM(I42:I44) -> 5113.536 | J45: =SUM(J42:J44) -> 5042.6189 | K45: =SUM(K42:K44) -> 4966.0284 | L45: =SUM(L42:L44) -> 4883.3107
B46: Lease liabilities / EBITDA | C46: =IFERROR(C45/Historical!D126,"") -> 2.7866162 | D46: =IFERROR(D45/Historical!E126,"") -> 3.6661017 | E46: =IFERROR(E45/Historical!F126,"") -> 2.8119748 | F46: =IFERROR(F45/Historical!G126,"") -> 2.6099762 | G46: =IFERROR(G45/Historical!H126,"") -> 2.5948478 | H46: =IFERROR(H45/Historical!I126,"") -> 2.7682602 | I46: =IFERROR(I45/Historical!J126,"") -> 2.5929006 | J46: =IFERROR(J45/Historical!K126,"") -> 2.4474831 | ... L46: =IFERROR(L45/Historical!M126,"") -> 2.1704465
...

Sheet Source Notes
A1: Fiscal year(s) | B1: Source | C1: Use in model | D1: Restatement / modelling note | E1: URL
A2: FY2022 | B2: J Sainsbury plc Annual Report and Financial Statements 2023 / 2022 | C2: FY2022 income statement, balance sheet, cash flow and opening schedule balances | D2: FY2022 balance-sheet presentation follows the latest comparative presentation in the FY2023 report. | E2: https://www.about.sainsburys.co.uk/~/media/Files/S/Sainsburys/documents/reports-and-presentations/2023/annual-report-2023/annual-report-and-financial-statements-2023.pdf
A3: FY2023 | B3: J Sainsbury plc Annual Report and Financial Statements 2023 | C3: FY2023 consolidated income statement, balance sheet and cash flow statement | E3: https://www.about.sainsburys.co.uk/~/media/Files/S/Sainsburys/documents/reports-and-presentations/2023/annual-report-2023/annual-report-and-financial-statements-2023.pdf
A4: FY2024 | B4: J Sainsbury plc Annual Report and Financial Statements 2025 | C4: FY2024 comparative income statement, balance sheet and cash flow statement | D4: Comparatives are re-presented for discontinued operations where disclosed. | E4: https://corporate.sainsburys.co.uk/media/e1lfnybd/sainsbury-annual-report-and-financial-statements-2025.pdf
A5: FY2025 | B5: J Sainsbury plc Annual Report and Financial Statements 2026 | C5: Latest restated FY2025 comparative figures, particularly discontinued Financial Services and deferred-tax presentation | D5: These values can differ from the originally filed FY2025 annual report. | E5: https://corporate.sainsburys.co.uk/media/z01g231u/j-sainsbury-plc-annual-report-and-financial-statements-2026.pdf
A6: FY2026 | B6: J Sainsbury plc Annual Report and Financial Statements 2026 | C6: FY2026 consolidated statements and latest operating metrics | D6: Financial Services core banking exit materially reduces consolidated FS receivables/deposits versus prior years. | E6: https://corporate.sainsburys.co.uk/media/z01g231u/j-sainsbury-plc-annual-report-and-financial-statements-2026.pdf
A9: Additional official results sources used for Operating Metrics
A10: FY2022 | B10: Preliminary Results 2021/22 | C10: Underlying PBT, Retail FCF, net debt, ROCE, underlying EPS | E10: https://corporate.sainsburys.co.uk/news/press-releases/preliminary-results-for-the-52-weeks-ended-5-march-2022/
A11: FY2025–FY2026 | B11: Annual Report 2026 / Preliminary Results 2025/26 | C11: Latest underlying PBT, Retail FCF, net debt, ROCE and EPS | E11: https://corporate.sainsburys.co.uk/investors/annual-report-2026/
A12: FY2023–FY2024 | B12: Annual reports / preliminary results | C12: Underlying PBT, Retail FCF, net debt and ROCE | E12: https://corporate.sainsburys.co.uk/investors/results-reports-and-presentations/
